[2016-11-09 15:07:55] DEBUG [django.db.backends:90] (0.004) 
            SELECT name, type FROM sqlite_master
            WHERE type in ('table', 'view') AND NOT name='sqlite_sequence'
            ORDER BY name; args=None
[2016-11-09 15:07:55] DEBUG [django.db.backends:90] (0.001) SELECT "django_migrations"."app", "django_migrations"."name" FROM "django_migrations"; args=()
[2016-11-09 15:08:21] DEBUG [django.db.backends:90] (0.001) 
            SELECT name, type FROM sqlite_master
            WHERE type in ('table', 'view') AND NOT name='sqlite_sequence'
            ORDER BY name; args=None
[2016-11-09 15:08:21] DEBUG [django.db.backends:90] (0.000) SELECT "django_migrations"."app", "django_migrations"."name" FROM "django_migrations"; args=()
[2016-11-09 15:08:21] DEBUG [django.db.backends:90] (0.000) 
            SELECT name, type FROM sqlite_master
            WHERE type in ('table', 'view') AND NOT name='sqlite_sequence'
            ORDER BY name; args=None
[2016-11-09 15:08:21] DEBUG [django.db.backends:90] (0.000) SELECT "django_migrations"."app", "django_migrations"."name" FROM "django_migrations"; args=()
[2016-11-09 15:08:21] DEBUG [django.db.backends:90] (0.000) PRAGMA foreign_keys; args=None
[2016-11-09 15:08:21] DEBUG [django.db.backends:90] (0.000) PRAGMA foreign_keys = 0; args=None
[2016-11-09 15:08:21] DEBUG [django.db.backends:90] (0.000) BEGIN; args=None
[2016-11-09 15:08:21] DEBUG [django.db.backends.schema:103] CREATE TABLE "catalogo_distribuidor" ("id" char(32) NOT NULL PRIMARY KEY, "nombre" varchar(20) NOT NULL, "ruc" integer NOT NULL UNIQUE, "telefono" integer NOT NULL, "direccion" varchar(60) NOT NULL); (params None)
[2016-11-09 15:08:21] DEBUG [django.db.backends:90] (0.002) CREATE TABLE "catalogo_distribuidor" ("id" char(32) NOT NULL PRIMARY KEY, "nombre" varchar(20) NOT NULL, "ruc" integer NOT NULL UNIQUE, "telefono" integer NOT NULL, "direccion" varchar(60) NOT NULL); args=None
[2016-11-09 15:08:21] DEBUG [django.db.backends:90] (0.000) PRAGMA foreign_keys = 0; args=None
[2016-11-09 15:08:21] DEBUG [django.db.backends:90] (0.000) 
            SELECT name, type FROM sqlite_master
            WHERE type in ('table', 'view') AND NOT name='sqlite_sequence'
            ORDER BY name; args=None
[2016-11-09 15:08:21] DEBUG [django.db.backends:90] (0.000) BEGIN; args=None
[2016-11-09 15:08:21] DEBUG [django.db.backends:90] (0.002) INSERT INTO "django_migrations" ("app", "name", "applied") VALUES ('catalogo', '0002_distribuidor', '2016-11-09 20:08:21.677301'); args=['catalogo', '0002_distribuidor', '2016-11-09 20:08:21.677301']
[2016-11-09 15:08:21] DEBUG [django.db.backends:90] (0.001) 
            SELECT name, type FROM sqlite_master
            WHERE type in ('table', 'view') AND NOT name='sqlite_sequence'
            ORDER BY name; args=None
[2016-11-09 15:08:21] DEBUG [django.db.backends:90] (0.002) SELECT "django_migrations"."app", "django_migrations"."name" FROM "django_migrations"; args=()
[2016-11-09 15:08:21] DEBUG [django.db.backends:90] (0.001) SELECT "django_content_type"."id", "django_content_type"."app_label", "django_content_type"."model" FROM "django_content_type" WHERE ("django_content_type"."app_label" = 'admin' AND "django_content_type"."model" = 'logentry'); args=('admin', 'logentry')
[2016-11-09 15:08:21] DEBUG [django.db.backends:90] (0.000) SELECT "auth_permission"."content_type_id", "auth_permission"."codename" FROM "auth_permission" INNER JOIN "django_content_type" ON ("auth_permission"."content_type_id" = "django_content_type"."id") WHERE "auth_permission"."content_type_id" IN (1) ORDER BY "django_content_type"."app_label" ASC, "django_content_type"."model" ASC, "auth_permission"."codename" ASC; args=(1,)
[2016-11-09 15:08:21] DEBUG [django.db.backends:90] (0.001) SELECT "django_content_type"."id", "django_content_type"."app_label", "django_content_type"."model" FROM "django_content_type" WHERE "django_content_type"."app_label" = 'admin'; args=('admin',)
[2016-11-09 15:08:21] DEBUG [django.db.backends:90] (0.001) SELECT "django_content_type"."id", "django_content_type"."app_label", "django_content_type"."model" FROM "django_content_type" WHERE ("django_content_type"."app_label" = 'auth' AND "django_content_type"."model" = 'permission'); args=('auth', 'permission')
[2016-11-09 15:08:21] DEBUG [django.db.backends:90] (0.000) SELECT "django_content_type"."id", "django_content_type"."app_label", "django_content_type"."model" FROM "django_content_type" WHERE ("django_content_type"."app_label" = 'auth' AND "django_content_type"."model" = 'group'); args=('auth', 'group')
[2016-11-09 15:08:21] DEBUG [django.db.backends:90] (0.001) SELECT "auth_permission"."content_type_id", "auth_permission"."codename" FROM "auth_permission" INNER JOIN "django_content_type" ON ("auth_permission"."content_type_id" = "django_content_type"."id") WHERE "auth_permission"."content_type_id" IN (2, 3) ORDER BY "django_content_type"."app_label" ASC, "django_content_type"."model" ASC, "auth_permission"."codename" ASC; args=(2, 3)
[2016-11-09 15:08:21] DEBUG [django.db.backends:90] (0.000) SELECT "django_content_type"."id", "django_content_type"."app_label", "django_content_type"."model" FROM "django_content_type" WHERE "django_content_type"."app_label" = 'auth'; args=('auth',)
[2016-11-09 15:08:21] DEBUG [django.db.backends:90] (0.000) SELECT "django_content_type"."id", "django_content_type"."app_label", "django_content_type"."model" FROM "django_content_type" WHERE ("django_content_type"."app_label" = 'contenttypes' AND "django_content_type"."model" = 'contenttype'); args=('contenttypes', 'contenttype')
[2016-11-09 15:08:21] DEBUG [django.db.backends:90] (0.000) SELECT "auth_permission"."content_type_id", "auth_permission"."codename" FROM "auth_permission" INNER JOIN "django_content_type" ON ("auth_permission"."content_type_id" = "django_content_type"."id") WHERE "auth_permission"."content_type_id" IN (4) ORDER BY "django_content_type"."app_label" ASC, "django_content_type"."model" ASC, "auth_permission"."codename" ASC; args=(4,)
[2016-11-09 15:08:21] DEBUG [django.db.backends:90] (0.000) SELECT "django_content_type"."id", "django_content_type"."app_label", "django_content_type"."model" FROM "django_content_type" WHERE "django_content_type"."app_label" = 'contenttypes'; args=('contenttypes',)
[2016-11-09 15:08:21] DEBUG [django.db.backends:90] (0.000) SELECT "django_content_type"."id", "django_content_type"."app_label", "django_content_type"."model" FROM "django_content_type" WHERE ("django_content_type"."app_label" = 'sessions' AND "django_content_type"."model" = 'session'); args=('sessions', 'session')
[2016-11-09 15:08:21] DEBUG [django.db.backends:90] (0.000) SELECT "auth_permission"."content_type_id", "auth_permission"."codename" FROM "auth_permission" INNER JOIN "django_content_type" ON ("auth_permission"."content_type_id" = "django_content_type"."id") WHERE "auth_permission"."content_type_id" IN (5) ORDER BY "django_content_type"."app_label" ASC, "django_content_type"."model" ASC, "auth_permission"."codename" ASC; args=(5,)
[2016-11-09 15:08:21] DEBUG [django.db.backends:90] (0.000) SELECT "django_content_type"."id", "django_content_type"."app_label", "django_content_type"."model" FROM "django_content_type" WHERE "django_content_type"."app_label" = 'sessions'; args=('sessions',)
[2016-11-09 15:08:21] DEBUG [django.db.backends:90] (0.000) SELECT "django_content_type"."id", "django_content_type"."app_label", "django_content_type"."model" FROM "django_content_type" WHERE ("django_content_type"."app_label" = 'corsheaders' AND "django_content_type"."model" = 'corsmodel'); args=('corsheaders', 'corsmodel')
[2016-11-09 15:08:21] DEBUG [django.db.backends:90] (0.000) SELECT "auth_permission"."content_type_id", "auth_permission"."codename" FROM "auth_permission" INNER JOIN "django_content_type" ON ("auth_permission"."content_type_id" = "django_content_type"."id") WHERE "auth_permission"."content_type_id" IN (6) ORDER BY "django_content_type"."app_label" ASC, "django_content_type"."model" ASC, "auth_permission"."codename" ASC; args=(6,)
[2016-11-09 15:08:21] DEBUG [django.db.backends:90] (0.000) SELECT "django_content_type"."id", "django_content_type"."app_label", "django_content_type"."model" FROM "django_content_type" WHERE "django_content_type"."app_label" = 'corsheaders'; args=('corsheaders',)
[2016-11-09 15:08:21] DEBUG [django.db.backends:90] (0.000) SELECT "django_content_type"."id", "django_content_type"."app_label", "django_content_type"."model" FROM "django_content_type" WHERE ("django_content_type"."app_label" = 'oauth2_provider' AND "django_content_type"."model" = 'application'); args=('oauth2_provider', 'application')
[2016-11-09 15:08:21] DEBUG [django.db.backends:90] (0.000) SELECT "django_content_type"."id", "django_content_type"."app_label", "django_content_type"."model" FROM "django_content_type" WHERE ("django_content_type"."app_label" = 'oauth2_provider' AND "django_content_type"."model" = 'accesstoken'); args=('oauth2_provider', 'accesstoken')
[2016-11-09 15:08:21] DEBUG [django.db.backends:90] (0.000) SELECT "django_content_type"."id", "django_content_type"."app_label", "django_content_type"."model" FROM "django_content_type" WHERE ("django_content_type"."app_label" = 'oauth2_provider' AND "django_content_type"."model" = 'refreshtoken'); args=('oauth2_provider', 'refreshtoken')
[2016-11-09 15:08:21] DEBUG [django.db.backends:90] (0.000) SELECT "django_content_type"."id", "django_content_type"."app_label", "django_content_type"."model" FROM "django_content_type" WHERE ("django_content_type"."app_label" = 'oauth2_provider' AND "django_content_type"."model" = 'grant'); args=('oauth2_provider', 'grant')
[2016-11-09 15:08:21] DEBUG [django.db.backends:90] (0.001) SELECT "auth_permission"."content_type_id", "auth_permission"."codename" FROM "auth_permission" INNER JOIN "django_content_type" ON ("auth_permission"."content_type_id" = "django_content_type"."id") WHERE "auth_permission"."content_type_id" IN (8, 9, 10, 7) ORDER BY "django_content_type"."app_label" ASC, "django_content_type"."model" ASC, "auth_permission"."codename" ASC; args=(8, 9, 10, 7)
[2016-11-09 15:08:21] DEBUG [django.db.backends:90] (0.000) SELECT "django_content_type"."id", "django_content_type"."app_label", "django_content_type"."model" FROM "django_content_type" WHERE "django_content_type"."app_label" = 'oauth2_provider'; args=('oauth2_provider',)
[2016-11-09 15:08:21] DEBUG [django.db.backends:90] (0.000) SELECT "django_content_type"."id", "django_content_type"."app_label", "django_content_type"."model" FROM "django_content_type" WHERE ("django_content_type"."app_label" = 'auths' AND "django_content_type"."model" = 'hierarchytype'); args=('auths', 'hierarchytype')
[2016-11-09 15:08:21] DEBUG [django.db.backends:90] (0.000) SELECT "django_content_type"."id", "django_content_type"."app_label", "django_content_type"."model" FROM "django_content_type" WHERE ("django_content_type"."app_label" = 'auths' AND "django_content_type"."model" = 'user'); args=('auths', 'user')
[2016-11-09 15:08:21] DEBUG [django.db.backends:90] (0.000) SELECT "django_content_type"."id", "django_content_type"."app_label", "django_content_type"."model" FROM "django_content_type" WHERE ("django_content_type"."app_label" = 'auths' AND "django_content_type"."model" = 'menu'); args=('auths', 'menu')
[2016-11-09 15:08:21] DEBUG [django.db.backends:90] (0.001) SELECT "django_content_type"."id", "django_content_type"."app_label", "django_content_type"."model" FROM "django_content_type" WHERE ("django_content_type"."app_label" = 'auths' AND "django_content_type"."model" = 'hierarchy'); args=('auths', 'hierarchy')
[2016-11-09 15:08:21] DEBUG [django.db.backends:90] (0.000) SELECT "django_content_type"."id", "django_content_type"."app_label", "django_content_type"."model" FROM "django_content_type" WHERE ("django_content_type"."app_label" = 'auths' AND "django_content_type"."model" = 'person'); args=('auths', 'person')
[2016-11-09 15:08:21] DEBUG [django.db.backends:90] (0.000) SELECT "django_content_type"."id", "django_content_type"."app_label", "django_content_type"."model" FROM "django_content_type" WHERE ("django_content_type"."app_label" = 'auths' AND "django_content_type"."model" = 'userhierarchygroup'); args=('auths', 'userhierarchygroup')
[2016-11-09 15:08:21] DEBUG [django.db.backends:90] (0.000) SELECT "django_content_type"."id", "django_content_type"."app_label", "django_content_type"."model" FROM "django_content_type" WHERE ("django_content_type"."app_label" = 'auths' AND "django_content_type"."model" = 'userhierarchypermission'); args=('auths', 'userhierarchypermission')
[2016-11-09 15:08:21] DEBUG [django.db.backends:90] (0.001) SELECT "auth_permission"."content_type_id", "auth_permission"."codename" FROM "auth_permission" INNER JOIN "django_content_type" ON ("auth_permission"."content_type_id" = "django_content_type"."id") WHERE "auth_permission"."content_type_id" IN (11, 12, 13, 14, 15, 16, 17) ORDER BY "django_content_type"."app_label" ASC, "django_content_type"."model" ASC, "auth_permission"."codename" ASC; args=(11, 12, 13, 14, 15, 16, 17)
[2016-11-09 15:08:21] DEBUG [django.db.backends:90] (0.000) SELECT "django_content_type"."id", "django_content_type"."app_label", "django_content_type"."model" FROM "django_content_type" WHERE "django_content_type"."app_label" = 'auths'; args=('auths',)
[2016-11-09 15:08:21] DEBUG [django.db.backends:90] (0.000) SELECT "django_content_type"."id", "django_content_type"."app_label", "django_content_type"."model" FROM "django_content_type" WHERE ("django_content_type"."app_label" = 'catalogo' AND "django_content_type"."model" = 'producto'); args=('catalogo', 'producto')
[2016-11-09 15:08:21] DEBUG [django.db.backends:90] (0.000) SELECT "django_content_type"."id", "django_content_type"."app_label", "django_content_type"."model" FROM "django_content_type" WHERE ("django_content_type"."app_label" = 'catalogo' AND "django_content_type"."model" = 'cliente'); args=('catalogo', 'cliente')
[2016-11-09 15:08:21] DEBUG [django.db.backends:90] (0.000) SELECT "django_content_type"."id", "django_content_type"."app_label", "django_content_type"."model" FROM "django_content_type" WHERE ("django_content_type"."app_label" = 'catalogo' AND "django_content_type"."model" = 'distribuidor'); args=('catalogo', 'distribuidor')
[2016-11-09 15:08:21] DEBUG [django.db.backends:90] (0.001) SELECT "django_content_type"."id", "django_content_type"."app_label", "django_content_type"."model" FROM "django_content_type" WHERE ("django_content_type"."app_label" = 'catalogo' AND "django_content_type"."model" = 'distribuidor'); args=('catalogo', 'distribuidor')
[2016-11-09 15:08:21] DEBUG [django.db.backends:90] (0.000) BEGIN; args=None
[2016-11-09 15:08:21] DEBUG [django.db.backends:90] (0.001) INSERT INTO "django_content_type" ("app_label", "model") VALUES ('catalogo', 'distribuidor'); args=['catalogo', 'distribuidor']
[2016-11-09 15:08:21] DEBUG [django.db.backends:90] (0.000) SELECT "auth_permission"."content_type_id", "auth_permission"."codename" FROM "auth_permission" INNER JOIN "django_content_type" ON ("auth_permission"."content_type_id" = "django_content_type"."id") WHERE "auth_permission"."content_type_id" IN (18, 19, 20) ORDER BY "django_content_type"."app_label" ASC, "django_content_type"."model" ASC, "auth_permission"."codename" ASC; args=(18, 19, 20)
[2016-11-09 15:08:21] DEBUG [django.db.backends:90] (0.000) BEGIN; args=None
[2016-11-09 15:08:21] DEBUG [django.db.backends:90] (0.001) INSERT INTO "auth_permission" ("name", "content_type_id", "codename") SELECT 'Can add distribuidor', 20, 'add_distribuidor' UNION ALL SELECT 'Can change distribuidor', 20, 'change_distribuidor' UNION ALL SELECT 'Can delete distribuidor', 20, 'delete_distribuidor'; args=('Can add distribuidor', 20, 'add_distribuidor', 'Can change distribuidor', 20, 'change_distribuidor', 'Can delete distribuidor', 20, 'delete_distribuidor')
[2016-11-09 15:08:22] DEBUG [django.db.backends:90] (0.001) SELECT "django_content_type"."id", "django_content_type"."app_label", "django_content_type"."model" FROM "django_content_type" WHERE "django_content_type"."app_label" = 'catalogo'; args=('catalogo',)
[2016-11-09 15:08:47] DEBUG [django.db.backends:90] (0.002) 
            SELECT name, type FROM sqlite_master
            WHERE type in ('table', 'view') AND NOT name='sqlite_sequence'
            ORDER BY name; args=None
[2016-11-09 15:08:47] DEBUG [django.db.backends:90] (0.000) SELECT "django_migrations"."app", "django_migrations"."name" FROM "django_migrations"; args=()
[2016-11-09 15:10:18] DEBUG [django.template:929] Exception while resolving variable 'name' in template 'unknown'.
Traceback (most recent call last):
  File "D:\pydev\lp\marketsoft\ve_market\lib\site-packages\django\core\handlers\exception.py", line 39, in inner
    response = get_response(request)
  File "D:\pydev\lp\marketsoft\ve_market\lib\site-packages\django\core\handlers\base.py", line 249, in _legacy_get_response
    response = self._get_response(request)
  File "D:\pydev\lp\marketsoft\ve_market\lib\site-packages\django\core\handlers\base.py", line 172, in _get_response
    resolver_match = resolver.resolve(request.path_info)
  File "D:\pydev\lp\marketsoft\ve_market\lib\site-packages\django\urls\resolvers.py", line 300, in resolve
    raise Resolver404({'tried': tried, 'path': new_path})
django.urls.exceptions.Resolver404: {'tried': [[<RegexURLResolver <RegexURLPattern list> (admin:admin) ^admin/>], [<RegexURLResolver <module 'django.contrib.admindocs.urls' from 'D:\\pydev\\lp\\marketsoft\\ve_market\\lib\\site-packages\\django\\contrib\\admindocs\\urls.py'> (None:None) ^admin/doc/>], [<RegexURLResolver <module 'rest_framework.urls' from 'D:\\pydev\\lp\\marketsoft\\ve_market\\lib\\site-packages\\rest_framework\\urls.py'> (rest_framework:rest_framework) ^api-auth/>], [<RegexURLResolver <module 'oauth2_provider.urls' from 'D:\\pydev\\lp\\marketsoft\\ve_market\\lib\\site-packages\\oauth2_provider\\urls.py'> (None:oauth2_provider) ^o/>], [<RegexURLResolver <module 'market_service_apps.auths_api.urls' from 'D:\\pydev\\lp\\marketsoft\\market_serve\\market_service_apps\\auths_api\\urls.py'> (None:None) ^api/auths/>], [<RegexURLResolver <module 'market_service_apps.catalogo_api.urls' from 'D:\\pydev\\lp\\marketsoft\\market_serve\\market_service_apps\\catalogo_api\\urls.py'> (None:None) ^api/catalogo/>]], 'path': ''}

During handling of the above exception, another exception occurred:

Traceback (most recent call last):
  File "D:\pydev\lp\marketsoft\ve_market\lib\site-packages\django\template\base.py", line 885, in _resolve_lookup
    current = current[bit]
TypeError: 'RegexURLResolver' object is not subscriptable

During handling of the above exception, another exception occurred:

Traceback (most recent call last):
  File "D:\pydev\lp\marketsoft\ve_market\lib\site-packages\django\template\base.py", line 893, in _resolve_lookup
    current = getattr(current, bit)
AttributeError: 'RegexURLResolver' object has no attribute 'name'

During handling of the above exception, another exception occurred:

Traceback (most recent call last):
  File "D:\pydev\lp\marketsoft\ve_market\lib\site-packages\django\template\base.py", line 900, in _resolve_lookup
    current = current[int(bit)]
ValueError: invalid literal for int() with base 10: 'name'

During handling of the above exception, another exception occurred:

Traceback (most recent call last):
  File "D:\pydev\lp\marketsoft\ve_market\lib\site-packages\django\template\base.py", line 907, in _resolve_lookup
    (bit, current))  # missing attribute
django.template.base.VariableDoesNotExist: Failed lookup for key [name] in '<RegexURLResolver <RegexURLPattern list> (admin:admin) ^admin/>'
[2016-11-09 15:10:18] DEBUG [django.template:929] Exception while resolving variable 'name' in template 'unknown'.
Traceback (most recent call last):
  File "D:\pydev\lp\marketsoft\ve_market\lib\site-packages\django\core\handlers\exception.py", line 39, in inner
    response = get_response(request)
  File "D:\pydev\lp\marketsoft\ve_market\lib\site-packages\django\core\handlers\base.py", line 249, in _legacy_get_response
    response = self._get_response(request)
  File "D:\pydev\lp\marketsoft\ve_market\lib\site-packages\django\core\handlers\base.py", line 172, in _get_response
    resolver_match = resolver.resolve(request.path_info)
  File "D:\pydev\lp\marketsoft\ve_market\lib\site-packages\django\urls\resolvers.py", line 300, in resolve
    raise Resolver404({'tried': tried, 'path': new_path})
django.urls.exceptions.Resolver404: {'tried': [[<RegexURLResolver <RegexURLPattern list> (admin:admin) ^admin/>], [<RegexURLResolver <module 'django.contrib.admindocs.urls' from 'D:\\pydev\\lp\\marketsoft\\ve_market\\lib\\site-packages\\django\\contrib\\admindocs\\urls.py'> (None:None) ^admin/doc/>], [<RegexURLResolver <module 'rest_framework.urls' from 'D:\\pydev\\lp\\marketsoft\\ve_market\\lib\\site-packages\\rest_framework\\urls.py'> (rest_framework:rest_framework) ^api-auth/>], [<RegexURLResolver <module 'oauth2_provider.urls' from 'D:\\pydev\\lp\\marketsoft\\ve_market\\lib\\site-packages\\oauth2_provider\\urls.py'> (None:oauth2_provider) ^o/>], [<RegexURLResolver <module 'market_service_apps.auths_api.urls' from 'D:\\pydev\\lp\\marketsoft\\market_serve\\market_service_apps\\auths_api\\urls.py'> (None:None) ^api/auths/>], [<RegexURLResolver <module 'market_service_apps.catalogo_api.urls' from 'D:\\pydev\\lp\\marketsoft\\market_serve\\market_service_apps\\catalogo_api\\urls.py'> (None:None) ^api/catalogo/>]], 'path': ''}

During handling of the above exception, another exception occurred:

Traceback (most recent call last):
  File "D:\pydev\lp\marketsoft\ve_market\lib\site-packages\django\template\base.py", line 885, in _resolve_lookup
    current = current[bit]
TypeError: 'RegexURLResolver' object is not subscriptable

During handling of the above exception, another exception occurred:

Traceback (most recent call last):
  File "D:\pydev\lp\marketsoft\ve_market\lib\site-packages\django\template\base.py", line 893, in _resolve_lookup
    current = getattr(current, bit)
AttributeError: 'RegexURLResolver' object has no attribute 'name'

During handling of the above exception, another exception occurred:

Traceback (most recent call last):
  File "D:\pydev\lp\marketsoft\ve_market\lib\site-packages\django\template\base.py", line 900, in _resolve_lookup
    current = current[int(bit)]
ValueError: invalid literal for int() with base 10: 'name'

During handling of the above exception, another exception occurred:

Traceback (most recent call last):
  File "D:\pydev\lp\marketsoft\ve_market\lib\site-packages\django\template\base.py", line 907, in _resolve_lookup
    (bit, current))  # missing attribute
django.template.base.VariableDoesNotExist: Failed lookup for key [name] in "<RegexURLResolver <module 'django.contrib.admindocs.urls' from 'D:\\\\pydev\\\\lp\\\\marketsoft\\\\ve_market\\\\lib\\\\site-packages\\\\django\\\\contrib\\\\admindocs\\\\urls.py'> (None:None) ^admin/doc/>"
[2016-11-09 15:10:18] DEBUG [django.template:929] Exception while resolving variable 'name' in template 'unknown'.
Traceback (most recent call last):
  File "D:\pydev\lp\marketsoft\ve_market\lib\site-packages\django\core\handlers\exception.py", line 39, in inner
    response = get_response(request)
  File "D:\pydev\lp\marketsoft\ve_market\lib\site-packages\django\core\handlers\base.py", line 249, in _legacy_get_response
    response = self._get_response(request)
  File "D:\pydev\lp\marketsoft\ve_market\lib\site-packages\django\core\handlers\base.py", line 172, in _get_response
    resolver_match = resolver.resolve(request.path_info)
  File "D:\pydev\lp\marketsoft\ve_market\lib\site-packages\django\urls\resolvers.py", line 300, in resolve
    raise Resolver404({'tried': tried, 'path': new_path})
django.urls.exceptions.Resolver404: {'tried': [[<RegexURLResolver <RegexURLPattern list> (admin:admin) ^admin/>], [<RegexURLResolver <module 'django.contrib.admindocs.urls' from 'D:\\pydev\\lp\\marketsoft\\ve_market\\lib\\site-packages\\django\\contrib\\admindocs\\urls.py'> (None:None) ^admin/doc/>], [<RegexURLResolver <module 'rest_framework.urls' from 'D:\\pydev\\lp\\marketsoft\\ve_market\\lib\\site-packages\\rest_framework\\urls.py'> (rest_framework:rest_framework) ^api-auth/>], [<RegexURLResolver <module 'oauth2_provider.urls' from 'D:\\pydev\\lp\\marketsoft\\ve_market\\lib\\site-packages\\oauth2_provider\\urls.py'> (None:oauth2_provider) ^o/>], [<RegexURLResolver <module 'market_service_apps.auths_api.urls' from 'D:\\pydev\\lp\\marketsoft\\market_serve\\market_service_apps\\auths_api\\urls.py'> (None:None) ^api/auths/>], [<RegexURLResolver <module 'market_service_apps.catalogo_api.urls' from 'D:\\pydev\\lp\\marketsoft\\market_serve\\market_service_apps\\catalogo_api\\urls.py'> (None:None) ^api/catalogo/>]], 'path': ''}

During handling of the above exception, another exception occurred:

Traceback (most recent call last):
  File "D:\pydev\lp\marketsoft\ve_market\lib\site-packages\django\template\base.py", line 885, in _resolve_lookup
    current = current[bit]
TypeError: 'RegexURLResolver' object is not subscriptable

During handling of the above exception, another exception occurred:

Traceback (most recent call last):
  File "D:\pydev\lp\marketsoft\ve_market\lib\site-packages\django\template\base.py", line 893, in _resolve_lookup
    current = getattr(current, bit)
AttributeError: 'RegexURLResolver' object has no attribute 'name'

During handling of the above exception, another exception occurred:

Traceback (most recent call last):
  File "D:\pydev\lp\marketsoft\ve_market\lib\site-packages\django\template\base.py", line 900, in _resolve_lookup
    current = current[int(bit)]
ValueError: invalid literal for int() with base 10: 'name'

During handling of the above exception, another exception occurred:

Traceback (most recent call last):
  File "D:\pydev\lp\marketsoft\ve_market\lib\site-packages\django\template\base.py", line 907, in _resolve_lookup
    (bit, current))  # missing attribute
django.template.base.VariableDoesNotExist: Failed lookup for key [name] in "<RegexURLResolver <module 'rest_framework.urls' from 'D:\\\\pydev\\\\lp\\\\marketsoft\\\\ve_market\\\\lib\\\\site-packages\\\\rest_framework\\\\urls.py'> (rest_framework:rest_framework) ^api-auth/>"
[2016-11-09 15:10:18] DEBUG [django.template:929] Exception while resolving variable 'name' in template 'unknown'.
Traceback (most recent call last):
  File "D:\pydev\lp\marketsoft\ve_market\lib\site-packages\django\core\handlers\exception.py", line 39, in inner
    response = get_response(request)
  File "D:\pydev\lp\marketsoft\ve_market\lib\site-packages\django\core\handlers\base.py", line 249, in _legacy_get_response
    response = self._get_response(request)
  File "D:\pydev\lp\marketsoft\ve_market\lib\site-packages\django\core\handlers\base.py", line 172, in _get_response
    resolver_match = resolver.resolve(request.path_info)
  File "D:\pydev\lp\marketsoft\ve_market\lib\site-packages\django\urls\resolvers.py", line 300, in resolve
    raise Resolver404({'tried': tried, 'path': new_path})
django.urls.exceptions.Resolver404: {'tried': [[<RegexURLResolver <RegexURLPattern list> (admin:admin) ^admin/>], [<RegexURLResolver <module 'django.contrib.admindocs.urls' from 'D:\\pydev\\lp\\marketsoft\\ve_market\\lib\\site-packages\\django\\contrib\\admindocs\\urls.py'> (None:None) ^admin/doc/>], [<RegexURLResolver <module 'rest_framework.urls' from 'D:\\pydev\\lp\\marketsoft\\ve_market\\lib\\site-packages\\rest_framework\\urls.py'> (rest_framework:rest_framework) ^api-auth/>], [<RegexURLResolver <module 'oauth2_provider.urls' from 'D:\\pydev\\lp\\marketsoft\\ve_market\\lib\\site-packages\\oauth2_provider\\urls.py'> (None:oauth2_provider) ^o/>], [<RegexURLResolver <module 'market_service_apps.auths_api.urls' from 'D:\\pydev\\lp\\marketsoft\\market_serve\\market_service_apps\\auths_api\\urls.py'> (None:None) ^api/auths/>], [<RegexURLResolver <module 'market_service_apps.catalogo_api.urls' from 'D:\\pydev\\lp\\marketsoft\\market_serve\\market_service_apps\\catalogo_api\\urls.py'> (None:None) ^api/catalogo/>]], 'path': ''}

During handling of the above exception, another exception occurred:

Traceback (most recent call last):
  File "D:\pydev\lp\marketsoft\ve_market\lib\site-packages\django\template\base.py", line 885, in _resolve_lookup
    current = current[bit]
TypeError: 'RegexURLResolver' object is not subscriptable

During handling of the above exception, another exception occurred:

Traceback (most recent call last):
  File "D:\pydev\lp\marketsoft\ve_market\lib\site-packages\django\template\base.py", line 893, in _resolve_lookup
    current = getattr(current, bit)
AttributeError: 'RegexURLResolver' object has no attribute 'name'

During handling of the above exception, another exception occurred:

Traceback (most recent call last):
  File "D:\pydev\lp\marketsoft\ve_market\lib\site-packages\django\template\base.py", line 900, in _resolve_lookup
    current = current[int(bit)]
ValueError: invalid literal for int() with base 10: 'name'

During handling of the above exception, another exception occurred:

Traceback (most recent call last):
  File "D:\pydev\lp\marketsoft\ve_market\lib\site-packages\django\template\base.py", line 907, in _resolve_lookup
    (bit, current))  # missing attribute
django.template.base.VariableDoesNotExist: Failed lookup for key [name] in "<RegexURLResolver <module 'oauth2_provider.urls' from 'D:\\\\pydev\\\\lp\\\\marketsoft\\\\ve_market\\\\lib\\\\site-packages\\\\oauth2_provider\\\\urls.py'> (None:oauth2_provider) ^o/>"
[2016-11-09 15:10:18] DEBUG [django.template:929] Exception while resolving variable 'name' in template 'unknown'.
Traceback (most recent call last):
  File "D:\pydev\lp\marketsoft\ve_market\lib\site-packages\django\core\handlers\exception.py", line 39, in inner
    response = get_response(request)
  File "D:\pydev\lp\marketsoft\ve_market\lib\site-packages\django\core\handlers\base.py", line 249, in _legacy_get_response
    response = self._get_response(request)
  File "D:\pydev\lp\marketsoft\ve_market\lib\site-packages\django\core\handlers\base.py", line 172, in _get_response
    resolver_match = resolver.resolve(request.path_info)
  File "D:\pydev\lp\marketsoft\ve_market\lib\site-packages\django\urls\resolvers.py", line 300, in resolve
    raise Resolver404({'tried': tried, 'path': new_path})
django.urls.exceptions.Resolver404: {'tried': [[<RegexURLResolver <RegexURLPattern list> (admin:admin) ^admin/>], [<RegexURLResolver <module 'django.contrib.admindocs.urls' from 'D:\\pydev\\lp\\marketsoft\\ve_market\\lib\\site-packages\\django\\contrib\\admindocs\\urls.py'> (None:None) ^admin/doc/>], [<RegexURLResolver <module 'rest_framework.urls' from 'D:\\pydev\\lp\\marketsoft\\ve_market\\lib\\site-packages\\rest_framework\\urls.py'> (rest_framework:rest_framework) ^api-auth/>], [<RegexURLResolver <module 'oauth2_provider.urls' from 'D:\\pydev\\lp\\marketsoft\\ve_market\\lib\\site-packages\\oauth2_provider\\urls.py'> (None:oauth2_provider) ^o/>], [<RegexURLResolver <module 'market_service_apps.auths_api.urls' from 'D:\\pydev\\lp\\marketsoft\\market_serve\\market_service_apps\\auths_api\\urls.py'> (None:None) ^api/auths/>], [<RegexURLResolver <module 'market_service_apps.catalogo_api.urls' from 'D:\\pydev\\lp\\marketsoft\\market_serve\\market_service_apps\\catalogo_api\\urls.py'> (None:None) ^api/catalogo/>]], 'path': ''}

During handling of the above exception, another exception occurred:

Traceback (most recent call last):
  File "D:\pydev\lp\marketsoft\ve_market\lib\site-packages\django\template\base.py", line 885, in _resolve_lookup
    current = current[bit]
TypeError: 'RegexURLResolver' object is not subscriptable

During handling of the above exception, another exception occurred:

Traceback (most recent call last):
  File "D:\pydev\lp\marketsoft\ve_market\lib\site-packages\django\template\base.py", line 893, in _resolve_lookup
    current = getattr(current, bit)
AttributeError: 'RegexURLResolver' object has no attribute 'name'

During handling of the above exception, another exception occurred:

Traceback (most recent call last):
  File "D:\pydev\lp\marketsoft\ve_market\lib\site-packages\django\template\base.py", line 900, in _resolve_lookup
    current = current[int(bit)]
ValueError: invalid literal for int() with base 10: 'name'

During handling of the above exception, another exception occurred:

Traceback (most recent call last):
  File "D:\pydev\lp\marketsoft\ve_market\lib\site-packages\django\template\base.py", line 907, in _resolve_lookup
    (bit, current))  # missing attribute
django.template.base.VariableDoesNotExist: Failed lookup for key [name] in "<RegexURLResolver <module 'market_service_apps.auths_api.urls' from 'D:\\\\pydev\\\\lp\\\\marketsoft\\\\market_serve\\\\market_service_apps\\\\auths_api\\\\urls.py'> (None:None) ^api/auths/>"
[2016-11-09 15:10:18] DEBUG [django.template:929] Exception while resolving variable 'name' in template 'unknown'.
Traceback (most recent call last):
  File "D:\pydev\lp\marketsoft\ve_market\lib\site-packages\django\core\handlers\exception.py", line 39, in inner
    response = get_response(request)
  File "D:\pydev\lp\marketsoft\ve_market\lib\site-packages\django\core\handlers\base.py", line 249, in _legacy_get_response
    response = self._get_response(request)
  File "D:\pydev\lp\marketsoft\ve_market\lib\site-packages\django\core\handlers\base.py", line 172, in _get_response
    resolver_match = resolver.resolve(request.path_info)
  File "D:\pydev\lp\marketsoft\ve_market\lib\site-packages\django\urls\resolvers.py", line 300, in resolve
    raise Resolver404({'tried': tried, 'path': new_path})
django.urls.exceptions.Resolver404: {'tried': [[<RegexURLResolver <RegexURLPattern list> (admin:admin) ^admin/>], [<RegexURLResolver <module 'django.contrib.admindocs.urls' from 'D:\\pydev\\lp\\marketsoft\\ve_market\\lib\\site-packages\\django\\contrib\\admindocs\\urls.py'> (None:None) ^admin/doc/>], [<RegexURLResolver <module 'rest_framework.urls' from 'D:\\pydev\\lp\\marketsoft\\ve_market\\lib\\site-packages\\rest_framework\\urls.py'> (rest_framework:rest_framework) ^api-auth/>], [<RegexURLResolver <module 'oauth2_provider.urls' from 'D:\\pydev\\lp\\marketsoft\\ve_market\\lib\\site-packages\\oauth2_provider\\urls.py'> (None:oauth2_provider) ^o/>], [<RegexURLResolver <module 'market_service_apps.auths_api.urls' from 'D:\\pydev\\lp\\marketsoft\\market_serve\\market_service_apps\\auths_api\\urls.py'> (None:None) ^api/auths/>], [<RegexURLResolver <module 'market_service_apps.catalogo_api.urls' from 'D:\\pydev\\lp\\marketsoft\\market_serve\\market_service_apps\\catalogo_api\\urls.py'> (None:None) ^api/catalogo/>]], 'path': ''}

During handling of the above exception, another exception occurred:

Traceback (most recent call last):
  File "D:\pydev\lp\marketsoft\ve_market\lib\site-packages\django\template\base.py", line 885, in _resolve_lookup
    current = current[bit]
TypeError: 'RegexURLResolver' object is not subscriptable

During handling of the above exception, another exception occurred:

Traceback (most recent call last):
  File "D:\pydev\lp\marketsoft\ve_market\lib\site-packages\django\template\base.py", line 893, in _resolve_lookup
    current = getattr(current, bit)
AttributeError: 'RegexURLResolver' object has no attribute 'name'

During handling of the above exception, another exception occurred:

Traceback (most recent call last):
  File "D:\pydev\lp\marketsoft\ve_market\lib\site-packages\django\template\base.py", line 900, in _resolve_lookup
    current = current[int(bit)]
ValueError: invalid literal for int() with base 10: 'name'

During handling of the above exception, another exception occurred:

Traceback (most recent call last):
  File "D:\pydev\lp\marketsoft\ve_market\lib\site-packages\django\template\base.py", line 907, in _resolve_lookup
    (bit, current))  # missing attribute
django.template.base.VariableDoesNotExist: Failed lookup for key [name] in "<RegexURLResolver <module 'market_service_apps.catalogo_api.urls' from 'D:\\\\pydev\\\\lp\\\\marketsoft\\\\market_serve\\\\market_service_apps\\\\catalogo_api\\\\urls.py'> (None:None) ^api/catalogo/>"
[2016-11-09 15:10:18] WARNING [django.request:152] Not Found: /
[2016-11-09 15:10:18] WARNING [django.server:131] "GET / HTTP/1.1" 404 2457
[2016-11-09 15:10:19] DEBUG [django.template:929] Exception while resolving variable 'name' in template 'unknown'.
Traceback (most recent call last):
  File "D:\pydev\lp\marketsoft\ve_market\lib\site-packages\django\core\handlers\exception.py", line 39, in inner
    response = get_response(request)
  File "D:\pydev\lp\marketsoft\ve_market\lib\site-packages\django\core\handlers\base.py", line 249, in _legacy_get_response
    response = self._get_response(request)
  File "D:\pydev\lp\marketsoft\ve_market\lib\site-packages\django\core\handlers\base.py", line 172, in _get_response
    resolver_match = resolver.resolve(request.path_info)
  File "D:\pydev\lp\marketsoft\ve_market\lib\site-packages\django\urls\resolvers.py", line 300, in resolve
    raise Resolver404({'tried': tried, 'path': new_path})
django.urls.exceptions.Resolver404: {'tried': [[<RegexURLResolver <RegexURLPattern list> (admin:admin) ^admin/>], [<RegexURLResolver <module 'django.contrib.admindocs.urls' from 'D:\\pydev\\lp\\marketsoft\\ve_market\\lib\\site-packages\\django\\contrib\\admindocs\\urls.py'> (None:None) ^admin/doc/>], [<RegexURLResolver <module 'rest_framework.urls' from 'D:\\pydev\\lp\\marketsoft\\ve_market\\lib\\site-packages\\rest_framework\\urls.py'> (rest_framework:rest_framework) ^api-auth/>], [<RegexURLResolver <module 'oauth2_provider.urls' from 'D:\\pydev\\lp\\marketsoft\\ve_market\\lib\\site-packages\\oauth2_provider\\urls.py'> (None:oauth2_provider) ^o/>], [<RegexURLResolver <module 'market_service_apps.auths_api.urls' from 'D:\\pydev\\lp\\marketsoft\\market_serve\\market_service_apps\\auths_api\\urls.py'> (None:None) ^api/auths/>], [<RegexURLResolver <module 'market_service_apps.catalogo_api.urls' from 'D:\\pydev\\lp\\marketsoft\\market_serve\\market_service_apps\\catalogo_api\\urls.py'> (None:None) ^api/catalogo/>]], 'path': 'favicon.ico'}

During handling of the above exception, another exception occurred:

Traceback (most recent call last):
  File "D:\pydev\lp\marketsoft\ve_market\lib\site-packages\django\template\base.py", line 885, in _resolve_lookup
    current = current[bit]
TypeError: 'RegexURLResolver' object is not subscriptable

During handling of the above exception, another exception occurred:

Traceback (most recent call last):
  File "D:\pydev\lp\marketsoft\ve_market\lib\site-packages\django\template\base.py", line 893, in _resolve_lookup
    current = getattr(current, bit)
AttributeError: 'RegexURLResolver' object has no attribute 'name'

During handling of the above exception, another exception occurred:

Traceback (most recent call last):
  File "D:\pydev\lp\marketsoft\ve_market\lib\site-packages\django\template\base.py", line 900, in _resolve_lookup
    current = current[int(bit)]
ValueError: invalid literal for int() with base 10: 'name'

During handling of the above exception, another exception occurred:

Traceback (most recent call last):
  File "D:\pydev\lp\marketsoft\ve_market\lib\site-packages\django\template\base.py", line 907, in _resolve_lookup
    (bit, current))  # missing attribute
django.template.base.VariableDoesNotExist: Failed lookup for key [name] in '<RegexURLResolver <RegexURLPattern list> (admin:admin) ^admin/>'
[2016-11-09 15:10:19] DEBUG [django.template:929] Exception while resolving variable 'name' in template 'unknown'.
Traceback (most recent call last):
  File "D:\pydev\lp\marketsoft\ve_market\lib\site-packages\django\core\handlers\exception.py", line 39, in inner
    response = get_response(request)
  File "D:\pydev\lp\marketsoft\ve_market\lib\site-packages\django\core\handlers\base.py", line 249, in _legacy_get_response
    response = self._get_response(request)
  File "D:\pydev\lp\marketsoft\ve_market\lib\site-packages\django\core\handlers\base.py", line 172, in _get_response
    resolver_match = resolver.resolve(request.path_info)
  File "D:\pydev\lp\marketsoft\ve_market\lib\site-packages\django\urls\resolvers.py", line 300, in resolve
    raise Resolver404({'tried': tried, 'path': new_path})
django.urls.exceptions.Resolver404: {'tried': [[<RegexURLResolver <RegexURLPattern list> (admin:admin) ^admin/>], [<RegexURLResolver <module 'django.contrib.admindocs.urls' from 'D:\\pydev\\lp\\marketsoft\\ve_market\\lib\\site-packages\\django\\contrib\\admindocs\\urls.py'> (None:None) ^admin/doc/>], [<RegexURLResolver <module 'rest_framework.urls' from 'D:\\pydev\\lp\\marketsoft\\ve_market\\lib\\site-packages\\rest_framework\\urls.py'> (rest_framework:rest_framework) ^api-auth/>], [<RegexURLResolver <module 'oauth2_provider.urls' from 'D:\\pydev\\lp\\marketsoft\\ve_market\\lib\\site-packages\\oauth2_provider\\urls.py'> (None:oauth2_provider) ^o/>], [<RegexURLResolver <module 'market_service_apps.auths_api.urls' from 'D:\\pydev\\lp\\marketsoft\\market_serve\\market_service_apps\\auths_api\\urls.py'> (None:None) ^api/auths/>], [<RegexURLResolver <module 'market_service_apps.catalogo_api.urls' from 'D:\\pydev\\lp\\marketsoft\\market_serve\\market_service_apps\\catalogo_api\\urls.py'> (None:None) ^api/catalogo/>]], 'path': 'favicon.ico'}

During handling of the above exception, another exception occurred:

Traceback (most recent call last):
  File "D:\pydev\lp\marketsoft\ve_market\lib\site-packages\django\template\base.py", line 885, in _resolve_lookup
    current = current[bit]
TypeError: 'RegexURLResolver' object is not subscriptable

During handling of the above exception, another exception occurred:

Traceback (most recent call last):
  File "D:\pydev\lp\marketsoft\ve_market\lib\site-packages\django\template\base.py", line 893, in _resolve_lookup
    current = getattr(current, bit)
AttributeError: 'RegexURLResolver' object has no attribute 'name'

During handling of the above exception, another exception occurred:

Traceback (most recent call last):
  File "D:\pydev\lp\marketsoft\ve_market\lib\site-packages\django\template\base.py", line 900, in _resolve_lookup
    current = current[int(bit)]
ValueError: invalid literal for int() with base 10: 'name'

During handling of the above exception, another exception occurred:

Traceback (most recent call last):
  File "D:\pydev\lp\marketsoft\ve_market\lib\site-packages\django\template\base.py", line 907, in _resolve_lookup
    (bit, current))  # missing attribute
django.template.base.VariableDoesNotExist: Failed lookup for key [name] in "<RegexURLResolver <module 'django.contrib.admindocs.urls' from 'D:\\\\pydev\\\\lp\\\\marketsoft\\\\ve_market\\\\lib\\\\site-packages\\\\django\\\\contrib\\\\admindocs\\\\urls.py'> (None:None) ^admin/doc/>"
[2016-11-09 15:10:19] DEBUG [django.template:929] Exception while resolving variable 'name' in template 'unknown'.
Traceback (most recent call last):
  File "D:\pydev\lp\marketsoft\ve_market\lib\site-packages\django\core\handlers\exception.py", line 39, in inner
    response = get_response(request)
  File "D:\pydev\lp\marketsoft\ve_market\lib\site-packages\django\core\handlers\base.py", line 249, in _legacy_get_response
    response = self._get_response(request)
  File "D:\pydev\lp\marketsoft\ve_market\lib\site-packages\django\core\handlers\base.py", line 172, in _get_response
    resolver_match = resolver.resolve(request.path_info)
  File "D:\pydev\lp\marketsoft\ve_market\lib\site-packages\django\urls\resolvers.py", line 300, in resolve
    raise Resolver404({'tried': tried, 'path': new_path})
django.urls.exceptions.Resolver404: {'tried': [[<RegexURLResolver <RegexURLPattern list> (admin:admin) ^admin/>], [<RegexURLResolver <module 'django.contrib.admindocs.urls' from 'D:\\pydev\\lp\\marketsoft\\ve_market\\lib\\site-packages\\django\\contrib\\admindocs\\urls.py'> (None:None) ^admin/doc/>], [<RegexURLResolver <module 'rest_framework.urls' from 'D:\\pydev\\lp\\marketsoft\\ve_market\\lib\\site-packages\\rest_framework\\urls.py'> (rest_framework:rest_framework) ^api-auth/>], [<RegexURLResolver <module 'oauth2_provider.urls' from 'D:\\pydev\\lp\\marketsoft\\ve_market\\lib\\site-packages\\oauth2_provider\\urls.py'> (None:oauth2_provider) ^o/>], [<RegexURLResolver <module 'market_service_apps.auths_api.urls' from 'D:\\pydev\\lp\\marketsoft\\market_serve\\market_service_apps\\auths_api\\urls.py'> (None:None) ^api/auths/>], [<RegexURLResolver <module 'market_service_apps.catalogo_api.urls' from 'D:\\pydev\\lp\\marketsoft\\market_serve\\market_service_apps\\catalogo_api\\urls.py'> (None:None) ^api/catalogo/>]], 'path': 'favicon.ico'}

During handling of the above exception, another exception occurred:

Traceback (most recent call last):
  File "D:\pydev\lp\marketsoft\ve_market\lib\site-packages\django\template\base.py", line 885, in _resolve_lookup
    current = current[bit]
TypeError: 'RegexURLResolver' object is not subscriptable

During handling of the above exception, another exception occurred:

Traceback (most recent call last):
  File "D:\pydev\lp\marketsoft\ve_market\lib\site-packages\django\template\base.py", line 893, in _resolve_lookup
    current = getattr(current, bit)
AttributeError: 'RegexURLResolver' object has no attribute 'name'

During handling of the above exception, another exception occurred:

Traceback (most recent call last):
  File "D:\pydev\lp\marketsoft\ve_market\lib\site-packages\django\template\base.py", line 900, in _resolve_lookup
    current = current[int(bit)]
ValueError: invalid literal for int() with base 10: 'name'

During handling of the above exception, another exception occurred:

Traceback (most recent call last):
  File "D:\pydev\lp\marketsoft\ve_market\lib\site-packages\django\template\base.py", line 907, in _resolve_lookup
    (bit, current))  # missing attribute
django.template.base.VariableDoesNotExist: Failed lookup for key [name] in "<RegexURLResolver <module 'rest_framework.urls' from 'D:\\\\pydev\\\\lp\\\\marketsoft\\\\ve_market\\\\lib\\\\site-packages\\\\rest_framework\\\\urls.py'> (rest_framework:rest_framework) ^api-auth/>"
[2016-11-09 15:10:19] DEBUG [django.template:929] Exception while resolving variable 'name' in template 'unknown'.
Traceback (most recent call last):
  File "D:\pydev\lp\marketsoft\ve_market\lib\site-packages\django\core\handlers\exception.py", line 39, in inner
    response = get_response(request)
  File "D:\pydev\lp\marketsoft\ve_market\lib\site-packages\django\core\handlers\base.py", line 249, in _legacy_get_response
    response = self._get_response(request)
  File "D:\pydev\lp\marketsoft\ve_market\lib\site-packages\django\core\handlers\base.py", line 172, in _get_response
    resolver_match = resolver.resolve(request.path_info)
  File "D:\pydev\lp\marketsoft\ve_market\lib\site-packages\django\urls\resolvers.py", line 300, in resolve
    raise Resolver404({'tried': tried, 'path': new_path})
django.urls.exceptions.Resolver404: {'tried': [[<RegexURLResolver <RegexURLPattern list> (admin:admin) ^admin/>], [<RegexURLResolver <module 'django.contrib.admindocs.urls' from 'D:\\pydev\\lp\\marketsoft\\ve_market\\lib\\site-packages\\django\\contrib\\admindocs\\urls.py'> (None:None) ^admin/doc/>], [<RegexURLResolver <module 'rest_framework.urls' from 'D:\\pydev\\lp\\marketsoft\\ve_market\\lib\\site-packages\\rest_framework\\urls.py'> (rest_framework:rest_framework) ^api-auth/>], [<RegexURLResolver <module 'oauth2_provider.urls' from 'D:\\pydev\\lp\\marketsoft\\ve_market\\lib\\site-packages\\oauth2_provider\\urls.py'> (None:oauth2_provider) ^o/>], [<RegexURLResolver <module 'market_service_apps.auths_api.urls' from 'D:\\pydev\\lp\\marketsoft\\market_serve\\market_service_apps\\auths_api\\urls.py'> (None:None) ^api/auths/>], [<RegexURLResolver <module 'market_service_apps.catalogo_api.urls' from 'D:\\pydev\\lp\\marketsoft\\market_serve\\market_service_apps\\catalogo_api\\urls.py'> (None:None) ^api/catalogo/>]], 'path': 'favicon.ico'}

During handling of the above exception, another exception occurred:

Traceback (most recent call last):
  File "D:\pydev\lp\marketsoft\ve_market\lib\site-packages\django\template\base.py", line 885, in _resolve_lookup
    current = current[bit]
TypeError: 'RegexURLResolver' object is not subscriptable

During handling of the above exception, another exception occurred:

Traceback (most recent call last):
  File "D:\pydev\lp\marketsoft\ve_market\lib\site-packages\django\template\base.py", line 893, in _resolve_lookup
    current = getattr(current, bit)
AttributeError: 'RegexURLResolver' object has no attribute 'name'

During handling of the above exception, another exception occurred:

Traceback (most recent call last):
  File "D:\pydev\lp\marketsoft\ve_market\lib\site-packages\django\template\base.py", line 900, in _resolve_lookup
    current = current[int(bit)]
ValueError: invalid literal for int() with base 10: 'name'

During handling of the above exception, another exception occurred:

Traceback (most recent call last):
  File "D:\pydev\lp\marketsoft\ve_market\lib\site-packages\django\template\base.py", line 907, in _resolve_lookup
    (bit, current))  # missing attribute
django.template.base.VariableDoesNotExist: Failed lookup for key [name] in "<RegexURLResolver <module 'oauth2_provider.urls' from 'D:\\\\pydev\\\\lp\\\\marketsoft\\\\ve_market\\\\lib\\\\site-packages\\\\oauth2_provider\\\\urls.py'> (None:oauth2_provider) ^o/>"
[2016-11-09 15:10:19] DEBUG [django.template:929] Exception while resolving variable 'name' in template 'unknown'.
Traceback (most recent call last):
  File "D:\pydev\lp\marketsoft\ve_market\lib\site-packages\django\core\handlers\exception.py", line 39, in inner
    response = get_response(request)
  File "D:\pydev\lp\marketsoft\ve_market\lib\site-packages\django\core\handlers\base.py", line 249, in _legacy_get_response
    response = self._get_response(request)
  File "D:\pydev\lp\marketsoft\ve_market\lib\site-packages\django\core\handlers\base.py", line 172, in _get_response
    resolver_match = resolver.resolve(request.path_info)
  File "D:\pydev\lp\marketsoft\ve_market\lib\site-packages\django\urls\resolvers.py", line 300, in resolve
    raise Resolver404({'tried': tried, 'path': new_path})
django.urls.exceptions.Resolver404: {'tried': [[<RegexURLResolver <RegexURLPattern list> (admin:admin) ^admin/>], [<RegexURLResolver <module 'django.contrib.admindocs.urls' from 'D:\\pydev\\lp\\marketsoft\\ve_market\\lib\\site-packages\\django\\contrib\\admindocs\\urls.py'> (None:None) ^admin/doc/>], [<RegexURLResolver <module 'rest_framework.urls' from 'D:\\pydev\\lp\\marketsoft\\ve_market\\lib\\site-packages\\rest_framework\\urls.py'> (rest_framework:rest_framework) ^api-auth/>], [<RegexURLResolver <module 'oauth2_provider.urls' from 'D:\\pydev\\lp\\marketsoft\\ve_market\\lib\\site-packages\\oauth2_provider\\urls.py'> (None:oauth2_provider) ^o/>], [<RegexURLResolver <module 'market_service_apps.auths_api.urls' from 'D:\\pydev\\lp\\marketsoft\\market_serve\\market_service_apps\\auths_api\\urls.py'> (None:None) ^api/auths/>], [<RegexURLResolver <module 'market_service_apps.catalogo_api.urls' from 'D:\\pydev\\lp\\marketsoft\\market_serve\\market_service_apps\\catalogo_api\\urls.py'> (None:None) ^api/catalogo/>]], 'path': 'favicon.ico'}

During handling of the above exception, another exception occurred:

Traceback (most recent call last):
  File "D:\pydev\lp\marketsoft\ve_market\lib\site-packages\django\template\base.py", line 885, in _resolve_lookup
    current = current[bit]
TypeError: 'RegexURLResolver' object is not subscriptable

During handling of the above exception, another exception occurred:

Traceback (most recent call last):
  File "D:\pydev\lp\marketsoft\ve_market\lib\site-packages\django\template\base.py", line 893, in _resolve_lookup
    current = getattr(current, bit)
AttributeError: 'RegexURLResolver' object has no attribute 'name'

During handling of the above exception, another exception occurred:

Traceback (most recent call last):
  File "D:\pydev\lp\marketsoft\ve_market\lib\site-packages\django\template\base.py", line 900, in _resolve_lookup
    current = current[int(bit)]
ValueError: invalid literal for int() with base 10: 'name'

During handling of the above exception, another exception occurred:

Traceback (most recent call last):
  File "D:\pydev\lp\marketsoft\ve_market\lib\site-packages\django\template\base.py", line 907, in _resolve_lookup
    (bit, current))  # missing attribute
django.template.base.VariableDoesNotExist: Failed lookup for key [name] in "<RegexURLResolver <module 'market_service_apps.auths_api.urls' from 'D:\\\\pydev\\\\lp\\\\marketsoft\\\\market_serve\\\\market_service_apps\\\\auths_api\\\\urls.py'> (None:None) ^api/auths/>"
[2016-11-09 15:10:19] DEBUG [django.template:929] Exception while resolving variable 'name' in template 'unknown'.
Traceback (most recent call last):
  File "D:\pydev\lp\marketsoft\ve_market\lib\site-packages\django\core\handlers\exception.py", line 39, in inner
    response = get_response(request)
  File "D:\pydev\lp\marketsoft\ve_market\lib\site-packages\django\core\handlers\base.py", line 249, in _legacy_get_response
    response = self._get_response(request)
  File "D:\pydev\lp\marketsoft\ve_market\lib\site-packages\django\core\handlers\base.py", line 172, in _get_response
    resolver_match = resolver.resolve(request.path_info)
  File "D:\pydev\lp\marketsoft\ve_market\lib\site-packages\django\urls\resolvers.py", line 300, in resolve
    raise Resolver404({'tried': tried, 'path': new_path})
django.urls.exceptions.Resolver404: {'tried': [[<RegexURLResolver <RegexURLPattern list> (admin:admin) ^admin/>], [<RegexURLResolver <module 'django.contrib.admindocs.urls' from 'D:\\pydev\\lp\\marketsoft\\ve_market\\lib\\site-packages\\django\\contrib\\admindocs\\urls.py'> (None:None) ^admin/doc/>], [<RegexURLResolver <module 'rest_framework.urls' from 'D:\\pydev\\lp\\marketsoft\\ve_market\\lib\\site-packages\\rest_framework\\urls.py'> (rest_framework:rest_framework) ^api-auth/>], [<RegexURLResolver <module 'oauth2_provider.urls' from 'D:\\pydev\\lp\\marketsoft\\ve_market\\lib\\site-packages\\oauth2_provider\\urls.py'> (None:oauth2_provider) ^o/>], [<RegexURLResolver <module 'market_service_apps.auths_api.urls' from 'D:\\pydev\\lp\\marketsoft\\market_serve\\market_service_apps\\auths_api\\urls.py'> (None:None) ^api/auths/>], [<RegexURLResolver <module 'market_service_apps.catalogo_api.urls' from 'D:\\pydev\\lp\\marketsoft\\market_serve\\market_service_apps\\catalogo_api\\urls.py'> (None:None) ^api/catalogo/>]], 'path': 'favicon.ico'}

During handling of the above exception, another exception occurred:

Traceback (most recent call last):
  File "D:\pydev\lp\marketsoft\ve_market\lib\site-packages\django\template\base.py", line 885, in _resolve_lookup
    current = current[bit]
TypeError: 'RegexURLResolver' object is not subscriptable

During handling of the above exception, another exception occurred:

Traceback (most recent call last):
  File "D:\pydev\lp\marketsoft\ve_market\lib\site-packages\django\template\base.py", line 893, in _resolve_lookup
    current = getattr(current, bit)
AttributeError: 'RegexURLResolver' object has no attribute 'name'

During handling of the above exception, another exception occurred:

Traceback (most recent call last):
  File "D:\pydev\lp\marketsoft\ve_market\lib\site-packages\django\template\base.py", line 900, in _resolve_lookup
    current = current[int(bit)]
ValueError: invalid literal for int() with base 10: 'name'

During handling of the above exception, another exception occurred:

Traceback (most recent call last):
  File "D:\pydev\lp\marketsoft\ve_market\lib\site-packages\django\template\base.py", line 907, in _resolve_lookup
    (bit, current))  # missing attribute
django.template.base.VariableDoesNotExist: Failed lookup for key [name] in "<RegexURLResolver <module 'market_service_apps.catalogo_api.urls' from 'D:\\\\pydev\\\\lp\\\\marketsoft\\\\market_serve\\\\market_service_apps\\\\catalogo_api\\\\urls.py'> (None:None) ^api/catalogo/>"
[2016-11-09 15:10:19] WARNING [django.request:152] Not Found: /favicon.ico
[2016-11-09 15:10:19] WARNING [django.server:131] "GET /favicon.ico HTTP/1.1" 404 2490
[2016-11-09 15:10:28] DEBUG [django.db.backends:90] (0.002) SELECT "auths_menu"."router_json" FROM "auths_menu" ORDER BY "auths_menu"."pos" ASC; args=()
[2016-11-09 15:10:28] INFO [django.server:131] "GET /api/auths/routers/ HTTP/1.1" 200 2
[2016-11-09 15:10:35] DEBUG [django.db.backends:90] (0.001) SELECT "oauth2_provider_application"."id", "oauth2_provider_application"."client_id", "oauth2_provider_application"."user_id", "oauth2_provider_application"."redirect_uris", "oauth2_provider_application"."client_type", "oauth2_provider_application"."authorization_grant_type", "oauth2_provider_application"."client_secret", "oauth2_provider_application"."name", "oauth2_provider_application"."skip_authorization" FROM "oauth2_provider_application" WHERE "oauth2_provider_application"."client_id" = 'Nd33HkotycCIWVTPQEuLPz7VyAw05ioaGJJy0gJb'; args=('Nd33HkotycCIWVTPQEuLPz7VyAw05ioaGJJy0gJb',)
[2016-11-09 15:10:35] DEBUG [django.db.backends:90] (0.001) SELECT "auths_user"."password", "auths_user"."last_login", "auths_user"."is_superuser", "auths_user"."username", "auths_user"."first_name", "auths_user"."last_name", "auths_user"."email", "auths_user"."is_staff", "auths_user"."is_active", "auths_user"."date_joined", "auths_user"."id", "auths_user"."last_hierarchy_id", "auths_user"."last_module_id", "auths_user"."person_id", "auths_user"."updated_at", "auths_user"."registered_by" FROM "auths_user" WHERE "auths_user"."username" = 'admin'; args=('admin',)
[2016-11-09 15:10:35] DEBUG [django.db.backends:90] (0.000) BEGIN; args=None
[2016-11-09 15:10:35] DEBUG [django.db.backends:90] (0.002) INSERT INTO "oauth2_provider_accesstoken" ("user_id", "token", "application_id", "expires", "scope") VALUES ('25e7efce92ee410c84e90b3c8ba9e969', 'v6boU3GGygtj222XT92hdz9QbFyS2D', 1, '2016-11-10 06:10:35.670093', 'write read'); args=['25e7efce92ee410c84e90b3c8ba9e969', 'v6boU3GGygtj222XT92hdz9QbFyS2D', 1, '2016-11-10 06:10:35.670093', 'write read']
[2016-11-09 15:10:35] DEBUG [django.db.backends:90] (0.000) BEGIN; args=None
[2016-11-09 15:10:35] DEBUG [django.db.backends:90] (0.003) INSERT INTO "oauth2_provider_refreshtoken" ("user_id", "token", "application_id", "access_token_id") VALUES ('25e7efce92ee410c84e90b3c8ba9e969', 'KHZ0rMVUAPLdC3oNCAa711ViKKysPD', 1, 4); args=['25e7efce92ee410c84e90b3c8ba9e969', 'KHZ0rMVUAPLdC3oNCAa711ViKKysPD', 1, 4]
[2016-11-09 15:10:35] INFO [django.server:131] "POST /o/token/ HTTP/1.1" 200 169
[2016-11-09 15:10:39] INFO [django.server:131] "OPTIONS /api/auths/localuserinfo/ HTTP/1.1" 200 0
[2016-11-09 15:10:39] DEBUG [django.db.backends:90] (0.002) SELECT "oauth2_provider_accesstoken"."id", "oauth2_provider_accesstoken"."user_id", "oauth2_provider_accesstoken"."token", "oauth2_provider_accesstoken"."application_id", "oauth2_provider_accesstoken"."expires", "oauth2_provider_accesstoken"."scope", "auths_user"."password", "auths_user"."last_login", "auths_user"."is_superuser", "auths_user"."username", "auths_user"."first_name", "auths_user"."last_name", "auths_user"."email", "auths_user"."is_staff", "auths_user"."is_active", "auths_user"."date_joined", "auths_user"."id", "auths_user"."last_hierarchy_id", "auths_user"."last_module_id", "auths_user"."person_id", "auths_user"."updated_at", "auths_user"."registered_by", "oauth2_provider_application"."id", "oauth2_provider_application"."client_id", "oauth2_provider_application"."user_id", "oauth2_provider_application"."redirect_uris", "oauth2_provider_application"."client_type", "oauth2_provider_application"."authorization_grant_type", "oauth2_provider_application"."client_secret", "oauth2_provider_application"."name", "oauth2_provider_application"."skip_authorization" FROM "oauth2_provider_accesstoken" LEFT OUTER JOIN "auths_user" ON ("oauth2_provider_accesstoken"."user_id" = "auths_user"."id") INNER JOIN "oauth2_provider_application" ON ("oauth2_provider_accesstoken"."application_id" = "oauth2_provider_application"."id") WHERE "oauth2_provider_accesstoken"."token" = 'v6boU3GGygtj222XT92hdz9QbFyS2D'; args=('v6boU3GGygtj222XT92hdz9QbFyS2D',)
[2016-11-09 15:10:39] DEBUG [django.db.backends:90] (0.000) SELECT "oauth2_provider_accesstoken"."id", "oauth2_provider_accesstoken"."user_id", "oauth2_provider_accesstoken"."token", "oauth2_provider_accesstoken"."application_id", "oauth2_provider_accesstoken"."expires", "oauth2_provider_accesstoken"."scope", "auths_user"."password", "auths_user"."last_login", "auths_user"."is_superuser", "auths_user"."username", "auths_user"."first_name", "auths_user"."last_name", "auths_user"."email", "auths_user"."is_staff", "auths_user"."is_active", "auths_user"."date_joined", "auths_user"."id", "auths_user"."last_hierarchy_id", "auths_user"."last_module_id", "auths_user"."person_id", "auths_user"."updated_at", "auths_user"."registered_by", "oauth2_provider_application"."id", "oauth2_provider_application"."client_id", "oauth2_provider_application"."user_id", "oauth2_provider_application"."redirect_uris", "oauth2_provider_application"."client_type", "oauth2_provider_application"."authorization_grant_type", "oauth2_provider_application"."client_secret", "oauth2_provider_application"."name", "oauth2_provider_application"."skip_authorization" FROM "oauth2_provider_accesstoken" LEFT OUTER JOIN "auths_user" ON ("oauth2_provider_accesstoken"."user_id" = "auths_user"."id") INNER JOIN "oauth2_provider_application" ON ("oauth2_provider_accesstoken"."application_id" = "oauth2_provider_application"."id") WHERE "oauth2_provider_accesstoken"."token" = 'v6boU3GGygtj222XT92hdz9QbFyS2D'; args=('v6boU3GGygtj222XT92hdz9QbFyS2D',)
[2016-11-09 15:10:39] DEBUG [django.db.backends:90] (0.002) SELECT "auth_group"."id", "auth_group"."name" FROM "auth_group" INNER JOIN "auths_user_groups" ON ("auth_group"."id" = "auths_user_groups"."group_id") WHERE "auths_user_groups"."user_id" = '25e7efce92ee410c84e90b3c8ba9e969'; args=('25e7efce92ee410c84e90b3c8ba9e969',)
[2016-11-09 15:10:39] INFO [django.server:131] "OPTIONS /api/auths/usermenu/ HTTP/1.1" 200 0
[2016-11-09 15:10:39] DEBUG [django.db.backends:90] (0.000) SELECT "auth_permission"."id", "auth_permission"."name", "auth_permission"."content_type_id", "auth_permission"."codename" FROM "auth_permission" INNER JOIN "auths_user_user_permissions" ON ("auth_permission"."id" = "auths_user_user_permissions"."permission_id") INNER JOIN "django_content_type" ON ("auth_permission"."content_type_id" = "django_content_type"."id") WHERE "auths_user_user_permissions"."user_id" = '25e7efce92ee410c84e90b3c8ba9e969' ORDER BY "django_content_type"."app_label" ASC, "django_content_type"."model" ASC, "auth_permission"."codename" ASC; args=('25e7efce92ee410c84e90b3c8ba9e969',)
[2016-11-09 15:10:39] INFO [django.server:131] "GET /api/auths/localuserinfo/ HTTP/1.1" 200 405
[2016-11-09 15:10:39] DEBUG [django.db.backends:90] (0.001) SELECT "oauth2_provider_accesstoken"."id", "oauth2_provider_accesstoken"."user_id", "oauth2_provider_accesstoken"."token", "oauth2_provider_accesstoken"."application_id", "oauth2_provider_accesstoken"."expires", "oauth2_provider_accesstoken"."scope", "auths_user"."password", "auths_user"."last_login", "auths_user"."is_superuser", "auths_user"."username", "auths_user"."first_name", "auths_user"."last_name", "auths_user"."email", "auths_user"."is_staff", "auths_user"."is_active", "auths_user"."date_joined", "auths_user"."id", "auths_user"."last_hierarchy_id", "auths_user"."last_module_id", "auths_user"."person_id", "auths_user"."updated_at", "auths_user"."registered_by", "oauth2_provider_application"."id", "oauth2_provider_application"."client_id", "oauth2_provider_application"."user_id", "oauth2_provider_application"."redirect_uris", "oauth2_provider_application"."client_type", "oauth2_provider_application"."authorization_grant_type", "oauth2_provider_application"."client_secret", "oauth2_provider_application"."name", "oauth2_provider_application"."skip_authorization" FROM "oauth2_provider_accesstoken" LEFT OUTER JOIN "auths_user" ON ("oauth2_provider_accesstoken"."user_id" = "auths_user"."id") INNER JOIN "oauth2_provider_application" ON ("oauth2_provider_accesstoken"."application_id" = "oauth2_provider_application"."id") WHERE "oauth2_provider_accesstoken"."token" = 'v6boU3GGygtj222XT92hdz9QbFyS2D'; args=('v6boU3GGygtj222XT92hdz9QbFyS2D',)
[2016-11-09 15:10:39] DEBUG [django.db.backends:90] (0.000) SELECT "oauth2_provider_accesstoken"."id", "oauth2_provider_accesstoken"."user_id", "oauth2_provider_accesstoken"."token", "oauth2_provider_accesstoken"."application_id", "oauth2_provider_accesstoken"."expires", "oauth2_provider_accesstoken"."scope", "auths_user"."password", "auths_user"."last_login", "auths_user"."is_superuser", "auths_user"."username", "auths_user"."first_name", "auths_user"."last_name", "auths_user"."email", "auths_user"."is_staff", "auths_user"."is_active", "auths_user"."date_joined", "auths_user"."id", "auths_user"."last_hierarchy_id", "auths_user"."last_module_id", "auths_user"."person_id", "auths_user"."updated_at", "auths_user"."registered_by", "oauth2_provider_application"."id", "oauth2_provider_application"."client_id", "oauth2_provider_application"."user_id", "oauth2_provider_application"."redirect_uris", "oauth2_provider_application"."client_type", "oauth2_provider_application"."authorization_grant_type", "oauth2_provider_application"."client_secret", "oauth2_provider_application"."name", "oauth2_provider_application"."skip_authorization" FROM "oauth2_provider_accesstoken" LEFT OUTER JOIN "auths_user" ON ("oauth2_provider_accesstoken"."user_id" = "auths_user"."id") INNER JOIN "oauth2_provider_application" ON ("oauth2_provider_accesstoken"."application_id" = "oauth2_provider_application"."id") WHERE "oauth2_provider_accesstoken"."token" = 'v6boU3GGygtj222XT92hdz9QbFyS2D'; args=('v6boU3GGygtj222XT92hdz9QbFyS2D',)
[2016-11-09 15:10:39] DEBUG [django.db.backends:90] (0.000) SELECT "auths_menu"."id" FROM "auths_menu" WHERE ("auths_menu"."id" IS NOT NULL AND "auths_menu"."module" = 'BACKEND' AND "auths_menu"."is_active" = 1) ORDER BY "auths_menu"."pos" ASC; args=('BACKEND', True)
[2016-11-09 15:10:39] DEBUG [django.db.backends:90] (0.001) SELECT (1) AS "a" FROM "django_session" WHERE "django_session"."session_key" = '4tgkhu6hwezn8cs7bltz9cetgaa6aqrq' LIMIT 1; args=('4tgkhu6hwezn8cs7bltz9cetgaa6aqrq',)
[2016-11-09 15:10:39] DEBUG [django.db.backends:90] (0.000) BEGIN; args=None
[2016-11-09 15:10:39] DEBUG [django.db.backends:90] (0.002) INSERT INTO "django_session" ("session_key", "session_data", "expire_date") SELECT '4tgkhu6hwezn8cs7bltz9cetgaa6aqrq', 'Y2U1MDdhOTVhY2Y1M2EzOGYyOTc1YmE0OTQ4NTlmMWJkODNmMmEzMjp7Il9zZXNzaW9uX2V4cGlyeSI6MzB9', '2016-11-09 20:11:09.466018'; args=('4tgkhu6hwezn8cs7bltz9cetgaa6aqrq', 'Y2U1MDdhOTVhY2Y1M2EzOGYyOTc1YmE0OTQ4NTlmMWJkODNmMmEzMjp7Il9zZXNzaW9uX2V4cGlyeSI6MzB9', '2016-11-09 20:11:09.466018')
[2016-11-09 15:10:39] INFO [django.server:131] "GET /api/auths/usermenu/ HTTP/1.1" 200 11
[2016-11-09 15:10:42] DEBUG [django.db.backends:90] (0.002) SELECT "django_session"."session_key", "django_session"."session_data", "django_session"."expire_date" FROM "django_session" WHERE ("django_session"."expire_date" > '2016-11-09 20:10:42.106952' AND "django_session"."session_key" = 'a7bftsy33vhbnqje2uo51dn3jhe8srq7'); args=('2016-11-09 20:10:42.106952', 'a7bftsy33vhbnqje2uo51dn3jhe8srq7')
[2016-11-09 15:10:42] INFO [django.server:131] "GET /admin/ HTTP/1.1" 302 0
[2016-11-09 15:10:42] DEBUG [django.template:929] Exception while resolving variable 'is_popup' in template 'admin/login.html'.
Traceback (most recent call last):
  File "D:\pydev\lp\marketsoft\ve_market\lib\site-packages\django\template\base.py", line 885, in _resolve_lookup
    current = current[bit]
  File "D:\pydev\lp\marketsoft\ve_market\lib\site-packages\django\template\context.py", line 75, in __getitem__
    raise KeyError(key)
KeyError: 'is_popup'

During handling of the above exception, another exception occurred:

Traceback (most recent call last):
  File "D:\pydev\lp\marketsoft\ve_market\lib\site-packages\django\template\base.py", line 891, in _resolve_lookup
    if isinstance(current, BaseContext) and getattr(type(current), bit):
AttributeError: type object 'RequestContext' has no attribute 'is_popup'

During handling of the above exception, another exception occurred:

Traceback (most recent call last):
  File "D:\pydev\lp\marketsoft\ve_market\lib\site-packages\django\template\base.py", line 900, in _resolve_lookup
    current = current[int(bit)]
ValueError: invalid literal for int() with base 10: 'is_popup'

During handling of the above exception, another exception occurred:

Traceback (most recent call last):
  File "D:\pydev\lp\marketsoft\ve_market\lib\site-packages\django\template\base.py", line 907, in _resolve_lookup
    (bit, current))  # missing attribute
django.template.base.VariableDoesNotExist: Failed lookup for key [is_popup] in "[{'False': False, 'None': None, 'True': True}, {'perms': <django.contrib.auth.context_processors.PermWrapper object at 0x01371090>, 'user': <SimpleLazyObject: <django.contrib.auth.models.AnonymousUser object at 0x00E56230>>, 'messages': <django.contrib.messages.storage.fallback.FallbackStorage object at 0x00E56CD0>, 'DEFAULT_MESSAGE_LEVELS': {'WARNING': 30, 'INFO': 20, 'ERROR': 40, 'DEBUG': 10, 'SUCCESS': 25}, 'csrf_token': <SimpleLazyObject: <function csrf.<locals>._get_val at 0x00E76D20>>, 'request': <WSGIRequest: GET '/admin/login/?next=/admin/'>}, {}, {'username': '', 'next': '/admin/', 'LANGUAGE_CODE': 'en-us', 'site': <django.contrib.sites.requests.RequestSite object at 0x00E56F70>, 'site_header': <django.utils.functional.lazy.<locals>.__proxy__ object at 0x03E0BCB0>, 'site_name': 'localhost:9000', 'site_title': <django.utils.functional.lazy.<locals>.__proxy__ object at 0x03E0BC50>, 'form': <AdminAuthenticationForm bound=False, valid=Unknown, fields=(username;password)>, 'LANGUAGE_BIDI': False, 'has_permission': False, 'app_path': '/admin/login/?next=/admin/', 'title': 'Log in', 'available_apps': [], 'site_url': '/'}]"
[2016-11-09 15:10:42] DEBUG [django.template:929] Exception while resolving variable 'is_popup' in template 'admin/login.html'.
Traceback (most recent call last):
  File "D:\pydev\lp\marketsoft\ve_market\lib\site-packages\django\template\base.py", line 885, in _resolve_lookup
    current = current[bit]
  File "D:\pydev\lp\marketsoft\ve_market\lib\site-packages\django\template\context.py", line 75, in __getitem__
    raise KeyError(key)
KeyError: 'is_popup'

During handling of the above exception, another exception occurred:

Traceback (most recent call last):
  File "D:\pydev\lp\marketsoft\ve_market\lib\site-packages\django\template\base.py", line 891, in _resolve_lookup
    if isinstance(current, BaseContext) and getattr(type(current), bit):
AttributeError: type object 'RequestContext' has no attribute 'is_popup'

During handling of the above exception, another exception occurred:

Traceback (most recent call last):
  File "D:\pydev\lp\marketsoft\ve_market\lib\site-packages\django\template\base.py", line 900, in _resolve_lookup
    current = current[int(bit)]
ValueError: invalid literal for int() with base 10: 'is_popup'

During handling of the above exception, another exception occurred:

Traceback (most recent call last):
  File "D:\pydev\lp\marketsoft\ve_market\lib\site-packages\django\template\base.py", line 907, in _resolve_lookup
    (bit, current))  # missing attribute
django.template.base.VariableDoesNotExist: Failed lookup for key [is_popup] in "[{'False': False, 'None': None, 'True': True}, {'perms': <django.contrib.auth.context_processors.PermWrapper object at 0x01371090>, 'user': <SimpleLazyObject: <django.contrib.auth.models.AnonymousUser object at 0x00E56230>>, 'messages': <django.contrib.messages.storage.fallback.FallbackStorage object at 0x00E56CD0>, 'DEFAULT_MESSAGE_LEVELS': {'WARNING': 30, 'INFO': 20, 'ERROR': 40, 'DEBUG': 10, 'SUCCESS': 25}, 'csrf_token': <SimpleLazyObject: <function csrf.<locals>._get_val at 0x00E76D20>>, 'request': <WSGIRequest: GET '/admin/login/?next=/admin/'>}, {}, {'username': '', 'next': '/admin/', 'LANGUAGE_CODE': 'en-us', 'site': <django.contrib.sites.requests.RequestSite object at 0x00E56F70>, 'site_header': <django.utils.functional.lazy.<locals>.__proxy__ object at 0x03E0BCB0>, 'site_name': 'localhost:9000', 'site_title': <django.utils.functional.lazy.<locals>.__proxy__ object at 0x03E0BC50>, 'form': <AdminAuthenticationForm bound=False, valid=Unknown, fields=(username;password)>, 'LANGUAGE_BIDI': False, 'has_permission': False, 'app_path': '/admin/login/?next=/admin/', 'title': 'Log in', 'available_apps': [], 'site_url': '/'}]"
[2016-11-09 15:10:42] INFO [django.server:131] "GET /admin/login/?next=/admin/ HTTP/1.1" 200 1658
[2016-11-09 15:10:42] INFO [django.server:131] "GET /static/admin/css/base.css HTTP/1.1" 304 0
[2016-11-09 15:10:42] INFO [django.server:131] "GET /static/admin/css/login.css HTTP/1.1" 304 0
[2016-11-09 15:10:42] INFO [django.server:131] "GET /static/admin/css/fonts.css HTTP/1.1" 304 0
[2016-11-09 15:10:43] INFO [django.server:131] "GET /static/admin/fonts/Roboto-Regular-webfont.woff HTTP/1.1" 200 80304
[2016-11-09 15:10:43] INFO [django.server:131] "GET /static/admin/fonts/Roboto-Light-webfont.woff HTTP/1.1" 200 81348
[2016-11-09 15:10:47] DEBUG [django.db.backends:90] (0.002) SELECT "auths_user"."password", "auths_user"."last_login", "auths_user"."is_superuser", "auths_user"."username", "auths_user"."first_name", "auths_user"."last_name", "auths_user"."email", "auths_user"."is_staff", "auths_user"."is_active", "auths_user"."date_joined", "auths_user"."id", "auths_user"."last_hierarchy_id", "auths_user"."last_module_id", "auths_user"."person_id", "auths_user"."updated_at", "auths_user"."registered_by" FROM "auths_user" WHERE "auths_user"."username" = 'admin'; args=('admin',)
[2016-11-09 15:10:47] DEBUG [django.db.backends:90] (0.000) SELECT (1) AS "a" FROM "django_session" WHERE "django_session"."session_key" = '4g513lvyqdjg2ebhta9jniml3iwymfwr' LIMIT 1; args=('4g513lvyqdjg2ebhta9jniml3iwymfwr',)
[2016-11-09 15:10:47] DEBUG [django.db.backends:90] (0.000) BEGIN; args=None
[2016-11-09 15:10:47] DEBUG [django.db.backends:90] (0.054) INSERT INTO "django_session" ("session_key", "session_data", "expire_date") SELECT '4g513lvyqdjg2ebhta9jniml3iwymfwr', 'ZDkwMGVmZTE5NTAzOWJmMjIyMDgzNWY4YmI1YjQyODcwOGRmYzhiNDp7fQ==', '2016-11-23 20:10:47.922610'; args=('4g513lvyqdjg2ebhta9jniml3iwymfwr', 'ZDkwMGVmZTE5NTAzOWJmMjIyMDgzNWY4YmI1YjQyODcwOGRmYzhiNDp7fQ==', '2016-11-23 20:10:47.922610')
[2016-11-09 15:10:48] DEBUG [django.db.backends:90] (0.000) BEGIN; args=None
[2016-11-09 15:10:48] DEBUG [django.db.backends:90] (0.002) UPDATE "auths_user" SET "last_login" = '2016-11-09 20:10:48.102412' WHERE "auths_user"."id" = '25e7efce92ee410c84e90b3c8ba9e969'; args=('2016-11-09 20:10:48.102412', '25e7efce92ee410c84e90b3c8ba9e969')
[2016-11-09 15:10:48] DEBUG [django.db.backends:90] (0.000) BEGIN; args=None
[2016-11-09 15:10:48] DEBUG [django.db.backends:90] (0.001) UPDATE "django_session" SET "session_data" = 'NTRmMmY3NzMyM2Q5M2ZkOGI4MjI0NDRjY2MyYzMyMGRiMTI1Yzk5MDp7Il9hdXRoX3VzZXJfaGFzaCI6IjdiMjhmODQ0ZDk2MzNjNmQ3ZGVmMjg2ZjRiM2FkYTNiOGVmNTBkOTgiLCJfYXV0aF91c2VyX2JhY2tlbmQiOiJkamFuZ28uY29udHJpYi5hdXRoLmJhY2tlbmRzLk1vZGVsQmFja2VuZCIsIl9hdXRoX3VzZXJfaWQiOiIyNWU3ZWZjZS05MmVlLTQxMGMtODRlOS0wYjNjOGJhOWU5NjkifQ==', "expire_date" = '2016-11-23 20:10:48.182977' WHERE "django_session"."session_key" = '4g513lvyqdjg2ebhta9jniml3iwymfwr'; args=('NTRmMmY3NzMyM2Q5M2ZkOGI4MjI0NDRjY2MyYzMyMGRiMTI1Yzk5MDp7Il9hdXRoX3VzZXJfaGFzaCI6IjdiMjhmODQ0ZDk2MzNjNmQ3ZGVmMjg2ZjRiM2FkYTNiOGVmNTBkOTgiLCJfYXV0aF91c2VyX2JhY2tlbmQiOiJkamFuZ28uY29udHJpYi5hdXRoLmJhY2tlbmRzLk1vZGVsQmFja2VuZCIsIl9hdXRoX3VzZXJfaWQiOiIyNWU3ZWZjZS05MmVlLTQxMGMtODRlOS0wYjNjOGJhOWU5NjkifQ==', '2016-11-23 20:10:48.182977', '4g513lvyqdjg2ebhta9jniml3iwymfwr')
[2016-11-09 15:10:48] INFO [django.server:131] "POST /admin/login/?next=/admin/ HTTP/1.1" 302 0
[2016-11-09 15:10:48] DEBUG [django.db.backends:90] (0.005) SELECT "django_session"."session_key", "django_session"."session_data", "django_session"."expire_date" FROM "django_session" WHERE ("django_session"."expire_date" > '2016-11-09 20:10:48.298980' AND "django_session"."session_key" = '4g513lvyqdjg2ebhta9jniml3iwymfwr'); args=('2016-11-09 20:10:48.298980', '4g513lvyqdjg2ebhta9jniml3iwymfwr')
[2016-11-09 15:10:48] DEBUG [django.db.backends:90] (0.001) SELECT "auths_user"."password", "auths_user"."last_login", "auths_user"."is_superuser", "auths_user"."username", "auths_user"."first_name", "auths_user"."last_name", "auths_user"."email", "auths_user"."is_staff", "auths_user"."is_active", "auths_user"."date_joined", "auths_user"."id", "auths_user"."last_hierarchy_id", "auths_user"."last_module_id", "auths_user"."person_id", "auths_user"."updated_at", "auths_user"."registered_by" FROM "auths_user" WHERE "auths_user"."id" = '25e7efce92ee410c84e90b3c8ba9e969'; args=('25e7efce92ee410c84e90b3c8ba9e969',)
[2016-11-09 15:10:48] DEBUG [django.template:929] Exception while resolving variable 'is_popup' in template 'admin/index.html'.
Traceback (most recent call last):
  File "D:\pydev\lp\marketsoft\ve_market\lib\site-packages\django\template\base.py", line 885, in _resolve_lookup
    current = current[bit]
  File "D:\pydev\lp\marketsoft\ve_market\lib\site-packages\django\template\context.py", line 75, in __getitem__
    raise KeyError(key)
KeyError: 'is_popup'

During handling of the above exception, another exception occurred:

Traceback (most recent call last):
  File "D:\pydev\lp\marketsoft\ve_market\lib\site-packages\django\template\base.py", line 891, in _resolve_lookup
    if isinstance(current, BaseContext) and getattr(type(current), bit):
AttributeError: type object 'RequestContext' has no attribute 'is_popup'

During handling of the above exception, another exception occurred:

Traceback (most recent call last):
  File "D:\pydev\lp\marketsoft\ve_market\lib\site-packages\django\template\base.py", line 900, in _resolve_lookup
    current = current[int(bit)]
ValueError: invalid literal for int() with base 10: 'is_popup'

During handling of the above exception, another exception occurred:

Traceback (most recent call last):
  File "D:\pydev\lp\marketsoft\ve_market\lib\site-packages\django\template\base.py", line 907, in _resolve_lookup
    (bit, current))  # missing attribute
django.template.base.VariableDoesNotExist: Failed lookup for key [is_popup] in "[{'False': False, 'None': None, 'True': True}, {'perms': <django.contrib.auth.context_processors.PermWrapper object at 0x00E67650>, 'user': <SimpleLazyObject: <User: admin>>, 'messages': <django.contrib.messages.storage.fallback.FallbackStorage object at 0x0136E2B0>, 'DEFAULT_MESSAGE_LEVELS': {'WARNING': 30, 'INFO': 20, 'ERROR': 40, 'DEBUG': 10, 'SUCCESS': 25}, 'csrf_token': <SimpleLazyObject: <function csrf.<locals>._get_val at 0x00E6EA50>>, 'request': <WSGIRequest: GET '/admin/'>}, {}, {'available_apps': [{'app_label': 'auth', 'has_module_perms': True, 'models': [{'perms': {'change': True, 'delete': True, 'add': True}, 'add_url': '/admin/auth/group/add/', 'admin_url': '/admin/auth/group/', 'name': <django.utils.functional.lazy.<locals>.__proxy__ object at 0x0137EFB0>, 'object_name': 'Group'}, {'perms': {'change': True, 'delete': True, 'add': True}, 'add_url': '/admin/auth/permission/add/', 'admin_url': '/admin/auth/permission/', 'name': <django.utils.functional.lazy.<locals>.__proxy__ object at 0x0137EE50>, 'object_name': 'Permission'}], 'app_url': '/admin/auth/', 'name': <django.utils.functional.lazy.<locals>.__proxy__ object at 0x03E1F730>}, {'app_label': 'auths', 'has_module_perms': True, 'models': [{'perms': {'change': True, 'delete': True, 'add': True}, 'add_url': '/admin/auths/hierarchytype/add/', 'admin_url': '/admin/auths/hierarchytype/', 'name': <django.utils.functional.lazy.<locals>.__proxy__ object at 0x0137E8D0>, 'object_name': 'HierarchyType'}, {'perms': {'change': True, 'delete': True, 'add': True}, 'add_url': '/admin/auths/hierarchy/add/', 'admin_url': '/admin/auths/hierarchy/', 'name': <django.utils.functional.lazy.<locals>.__proxy__ object at 0x0137EED0>, 'object_name': 'Hierarchy'}, {'perms': {'change': True, 'delete': True, 'add': True}, 'add_url': '/admin/auths/menu/add/', 'admin_url': '/admin/auths/menu/', 'name': <django.utils.functional.lazy.<locals>.__proxy__ object at 0x0137EE10>, 'object_name': 'Menu'}, {'perms': {'change': True, 'delete': True, 'add': True}, 'add_url': '/admin/auths/person/add/', 'admin_url': '/admin/auths/person/', 'name': <django.utils.functional.lazy.<locals>.__proxy__ object at 0x0137E9B0>, 'object_name': 'Person'}, {'perms': {'change': True, 'delete': True, 'add': True}, 'add_url': '/admin/auths/userhierarchygroup/add/', 'admin_url': '/admin/auths/userhierarchygroup/', 'name': <django.utils.functional.lazy.<locals>.__proxy__ object at 0x0137E210>, 'object_name': 'UserHierarchyGroup'}, {'perms': {'change': True, 'delete': True, 'add': True}, 'add_url': '/admin/auths/userhierarchypermission/add/', 'admin_url': '/admin/auths/userhierarchypermission/', 'name': <django.utils.functional.lazy.<locals>.__proxy__ object at 0x0137E9D0>, 'object_name': 'UserHierarchyPermission'}, {'perms': {'change': True, 'delete': True, 'add': True}, 'add_url': '/admin/auths/user/add/', 'admin_url': '/admin/auths/user/', 'name': <django.utils.functional.lazy.<locals>.__proxy__ object at 0x0137EE30>, 'object_name': 'User'}], 'app_url': '/admin/auths/', 'name': 'Auths'}, {'app_label': 'catalogo', 'has_module_perms': True, 'models': [{'perms': {'change': True, 'delete': True, 'add': True}, 'add_url': '/admin/catalogo/cliente/add/', 'admin_url': '/admin/catalogo/cliente/', 'name': 'Clientes', 'object_name': 'Cliente'}, {'perms': {'change': True, 'delete': True, 'add': True}, 'add_url': '/admin/catalogo/distribuidor/add/', 'admin_url': '/admin/catalogo/distribuidor/', 'name': <django.utils.functional.lazy.<locals>.__proxy__ object at 0x0137EEF0>, 'object_name': 'Distribuidor'}, {'perms': {'change': True, 'delete': True, 'add': True}, 'add_url': '/admin/catalogo/producto/add/', 'admin_url': '/admin/catalogo/producto/', 'name': <django.utils.functional.lazy.<locals>.__proxy__ object at 0x0137EF10>, 'object_name': 'Producto'}], 'app_url': '/admin/catalogo/', 'name': 'Catalogo'}, {'app_label': 'contenttypes', 'has_module_perms': True, 'models': [{'perms': {'change': True, 'delete': True, 'add': True}, 'add_url': '/admin/contenttypes/contenttype/add/', 'admin_url': '/admin/contenttypes/contenttype/', 'name': <django.utils.functional.lazy.<locals>.__proxy__ object at 0x0137EC50>, 'object_name': 'ContentType'}], 'app_url': '/admin/contenttypes/', 'name': <django.utils.functional.lazy.<locals>.__proxy__ object at 0x03E1F870>}, {'app_label': 'oauth2_provider', 'has_module_perms': True, 'models': [{'perms': {'change': True, 'delete': True, 'add': True}, 'add_url': '/admin/oauth2_provider/accesstoken/add/', 'admin_url': '/admin/oauth2_provider/accesstoken/', 'name': <django.utils.functional.lazy.<locals>.__proxy__ object at 0x0137EF70>, 'object_name': 'AccessToken'}, {'perms': {'change': True, 'delete': True, 'add': True}, 'add_url': '/admin/oauth2_provider/application/add/', 'admin_url': '/admin/oauth2_provider/application/', 'name': <django.utils.functional.lazy.<locals>.__proxy__ object at 0x0137EF50>, 'object_name': 'Application'}, {'perms': {'change': True, 'delete': True, 'add': True}, 'add_url': '/admin/oauth2_provider/grant/add/', 'admin_url': '/admin/oauth2_provider/grant/', 'name': <django.utils.functional.lazy.<locals>.__proxy__ object at 0x0137EAF0>, 'object_name': 'Grant'}, {'perms': {'change': True, 'delete': True, 'add': True}, 'add_url': '/admin/oauth2_provider/refreshtoken/add/', 'admin_url': '/admin/oauth2_provider/refreshtoken/', 'name': <django.utils.functional.lazy.<locals>.__proxy__ object at 0x0137E7B0>, 'object_name': 'RefreshToken'}], 'app_url': '/admin/oauth2_provider/', 'name': 'Django OAuth Toolkit'}], 'LANGUAGE_CODE': 'en-us', 'site_url': '/', 'site_title': <django.utils.functional.lazy.<locals>.__proxy__ object at 0x03E0BC50>, 'title': <django.utils.functional.lazy.<locals>.__proxy__ object at 0x03E0BD10>, 'site_header': <django.utils.functional.lazy.<locals>.__proxy__ object at 0x03E0BCB0>, 'has_permission': True, 'LANGUAGE_BIDI': False, 'app_list': [{'app_label': 'auth', 'has_module_perms': True, 'models': [{'perms': {'change': True, 'delete': True, 'add': True}, 'add_url': '/admin/auth/group/add/', 'admin_url': '/admin/auth/group/', 'name': <django.utils.functional.lazy.<locals>.__proxy__ object at 0x0136E2F0>, 'object_name': 'Group'}, {'perms': {'change': True, 'delete': True, 'add': True}, 'add_url': '/admin/auth/permission/add/', 'admin_url': '/admin/auth/permission/', 'name': <django.utils.functional.lazy.<locals>.__proxy__ object at 0x0136E530>, 'object_name': 'Permission'}], 'app_url': '/admin/auth/', 'name': <django.utils.functional.lazy.<locals>.__proxy__ object at 0x03E1F730>}, {'app_label': 'auths', 'has_module_perms': True, 'models': [{'perms': {'change': True, 'delete': True, 'add': True}, 'add_url': '/admin/auths/hierarchytype/add/', 'admin_url': '/admin/auths/hierarchytype/', 'name': <django.utils.functional.lazy.<locals>.__proxy__ object at 0x0136E730>, 'object_name': 'HierarchyType'}, {'perms': {'change': True, 'delete': True, 'add': True}, 'add_url': '/admin/auths/hierarchy/add/', 'admin_url': '/admin/auths/hierarchy/', 'name': <django.utils.functional.lazy.<locals>.__proxy__ object at 0x0136E250>, 'object_name': 'Hierarchy'}, {'perms': {'change': True, 'delete': True, 'add': True}, 'add_url': '/admin/auths/menu/add/', 'admin_url': '/admin/auths/menu/', 'name': <django.utils.functional.lazy.<locals>.__proxy__ object at 0x0136E350>, 'object_name': 'Menu'}, {'perms': {'change': True, 'delete': True, 'add': True}, 'add_url': '/admin/auths/person/add/', 'admin_url': '/admin/auths/person/', 'name': <django.utils.functional.lazy.<locals>.__proxy__ object at 0x0136E5D0>, 'object_name': 'Person'}, {'perms': {'change': True, 'delete': True, 'add': True}, 'add_url': '/admin/auths/userhierarchygroup/add/', 'admin_url': '/admin/auths/userhierarchygroup/', 'name': <django.utils.functional.lazy.<locals>.__proxy__ object at 0x0136E690>, 'object_name': 'UserHierarchyGroup'}, {'perms': {'change': True, 'delete': True, 'add': True}, 'add_url': '/admin/auths/userhierarchypermission/add/', 'admin_url': '/admin/auths/userhierarchypermission/', 'name': <django.utils.functional.lazy.<locals>.__proxy__ object at 0x0136E790>, 'object_name': 'UserHierarchyPermission'}, {'perms': {'change': True, 'delete': True, 'add': True}, 'add_url': '/admin/auths/user/add/', 'admin_url': '/admin/auths/user/', 'name': <django.utils.functional.lazy.<locals>.__proxy__ object at 0x0136E710>, 'object_name': 'User'}], 'app_url': '/admin/auths/', 'name': 'Auths'}, {'app_label': 'catalogo', 'has_module_perms': True, 'models': [{'perms': {'change': True, 'delete': True, 'add': True}, 'add_url': '/admin/catalogo/cliente/add/', 'admin_url': '/admin/catalogo/cliente/', 'name': 'Clientes', 'object_name': 'Cliente'}, {'perms': {'change': True, 'delete': True, 'add': True}, 'add_url': '/admin/catalogo/distribuidor/add/', 'admin_url': '/admin/catalogo/distribuidor/', 'name': <django.utils.functional.lazy.<locals>.__proxy__ object at 0x0136E5F0>, 'object_name': 'Distribuidor'}, {'perms': {'change': True, 'delete': True, 'add': True}, 'add_url': '/admin/catalogo/producto/add/', 'admin_url': '/admin/catalogo/producto/', 'name': <django.utils.functional.lazy.<locals>.__proxy__ object at 0x0136E850>, 'object_name': 'Producto'}], 'app_url': '/admin/catalogo/', 'name': 'Catalogo'}, {'app_label': 'contenttypes', 'has_module_perms': True, 'models': [{'perms': {'change': True, 'delete': True, 'add': True}, 'add_url': '/admin/contenttypes/contenttype/add/', 'admin_url': '/admin/contenttypes/contenttype/', 'name': <django.utils.functional.lazy.<locals>.__proxy__ object at 0x0136E650>, 'object_name': 'ContentType'}], 'app_url': '/admin/contenttypes/', 'name': <django.utils.functional.lazy.<locals>.__proxy__ object at 0x03E1F870>}, {'app_label': 'oauth2_provider', 'has_module_perms': True, 'models': [{'perms': {'change': True, 'delete': True, 'add': True}, 'add_url': '/admin/oauth2_provider/accesstoken/add/', 'admin_url': '/admin/oauth2_provider/accesstoken/', 'name': <django.utils.functional.lazy.<locals>.__proxy__ object at 0x0136E770>, 'object_name': 'AccessToken'}, {'perms': {'change': True, 'delete': True, 'add': True}, 'add_url': '/admin/oauth2_provider/application/add/', 'admin_url': '/admin/oauth2_provider/application/', 'name': <django.utils.functional.lazy.<locals>.__proxy__ object at 0x0136E7D0>, 'object_name': 'Application'}, {'perms': {'change': True, 'delete': True, 'add': True}, 'add_url': '/admin/oauth2_provider/grant/add/', 'admin_url': '/admin/oauth2_provider/grant/', 'name': <django.utils.functional.lazy.<locals>.__proxy__ object at 0x0136E6D0>, 'object_name': 'Grant'}, {'perms': {'change': True, 'delete': True, 'add': True}, 'add_url': '/admin/oauth2_provider/refreshtoken/add/', 'admin_url': '/admin/oauth2_provider/refreshtoken/', 'name': <django.utils.functional.lazy.<locals>.__proxy__ object at 0x0136E6F0>, 'object_name': 'RefreshToken'}], 'app_url': '/admin/oauth2_provider/', 'name': 'Django OAuth Toolkit'}]}]"
[2016-11-09 15:10:48] DEBUG [django.template:929] Exception while resolving variable 'is_popup' in template 'admin/index.html'.
Traceback (most recent call last):
  File "D:\pydev\lp\marketsoft\ve_market\lib\site-packages\django\template\base.py", line 885, in _resolve_lookup
    current = current[bit]
  File "D:\pydev\lp\marketsoft\ve_market\lib\site-packages\django\template\context.py", line 75, in __getitem__
    raise KeyError(key)
KeyError: 'is_popup'

During handling of the above exception, another exception occurred:

Traceback (most recent call last):
  File "D:\pydev\lp\marketsoft\ve_market\lib\site-packages\django\template\base.py", line 891, in _resolve_lookup
    if isinstance(current, BaseContext) and getattr(type(current), bit):
AttributeError: type object 'RequestContext' has no attribute 'is_popup'

During handling of the above exception, another exception occurred:

Traceback (most recent call last):
  File "D:\pydev\lp\marketsoft\ve_market\lib\site-packages\django\template\base.py", line 900, in _resolve_lookup
    current = current[int(bit)]
ValueError: invalid literal for int() with base 10: 'is_popup'

During handling of the above exception, another exception occurred:

Traceback (most recent call last):
  File "D:\pydev\lp\marketsoft\ve_market\lib\site-packages\django\template\base.py", line 907, in _resolve_lookup
    (bit, current))  # missing attribute
django.template.base.VariableDoesNotExist: Failed lookup for key [is_popup] in "[{'False': False, 'None': None, 'True': True}, {'perms': <django.contrib.auth.context_processors.PermWrapper object at 0x00E67650>, 'user': <SimpleLazyObject: <User: admin>>, 'messages': <django.contrib.messages.storage.fallback.FallbackStorage object at 0x0136E2B0>, 'DEFAULT_MESSAGE_LEVELS': {'WARNING': 30, 'INFO': 20, 'ERROR': 40, 'DEBUG': 10, 'SUCCESS': 25}, 'csrf_token': <SimpleLazyObject: <function csrf.<locals>._get_val at 0x00E6EA50>>, 'request': <WSGIRequest: GET '/admin/'>}, {}, {'available_apps': [{'app_label': 'auth', 'has_module_perms': True, 'models': [{'perms': {'change': True, 'delete': True, 'add': True}, 'add_url': '/admin/auth/group/add/', 'admin_url': '/admin/auth/group/', 'name': <django.utils.functional.lazy.<locals>.__proxy__ object at 0x0137EFB0>, 'object_name': 'Group'}, {'perms': {'change': True, 'delete': True, 'add': True}, 'add_url': '/admin/auth/permission/add/', 'admin_url': '/admin/auth/permission/', 'name': <django.utils.functional.lazy.<locals>.__proxy__ object at 0x0137EE50>, 'object_name': 'Permission'}], 'app_url': '/admin/auth/', 'name': <django.utils.functional.lazy.<locals>.__proxy__ object at 0x03E1F730>}, {'app_label': 'auths', 'has_module_perms': True, 'models': [{'perms': {'change': True, 'delete': True, 'add': True}, 'add_url': '/admin/auths/hierarchytype/add/', 'admin_url': '/admin/auths/hierarchytype/', 'name': <django.utils.functional.lazy.<locals>.__proxy__ object at 0x0137E8D0>, 'object_name': 'HierarchyType'}, {'perms': {'change': True, 'delete': True, 'add': True}, 'add_url': '/admin/auths/hierarchy/add/', 'admin_url': '/admin/auths/hierarchy/', 'name': <django.utils.functional.lazy.<locals>.__proxy__ object at 0x0137EED0>, 'object_name': 'Hierarchy'}, {'perms': {'change': True, 'delete': True, 'add': True}, 'add_url': '/admin/auths/menu/add/', 'admin_url': '/admin/auths/menu/', 'name': <django.utils.functional.lazy.<locals>.__proxy__ object at 0x0137EE10>, 'object_name': 'Menu'}, {'perms': {'change': True, 'delete': True, 'add': True}, 'add_url': '/admin/auths/person/add/', 'admin_url': '/admin/auths/person/', 'name': <django.utils.functional.lazy.<locals>.__proxy__ object at 0x0137E9B0>, 'object_name': 'Person'}, {'perms': {'change': True, 'delete': True, 'add': True}, 'add_url': '/admin/auths/userhierarchygroup/add/', 'admin_url': '/admin/auths/userhierarchygroup/', 'name': <django.utils.functional.lazy.<locals>.__proxy__ object at 0x0137E210>, 'object_name': 'UserHierarchyGroup'}, {'perms': {'change': True, 'delete': True, 'add': True}, 'add_url': '/admin/auths/userhierarchypermission/add/', 'admin_url': '/admin/auths/userhierarchypermission/', 'name': <django.utils.functional.lazy.<locals>.__proxy__ object at 0x0137E9D0>, 'object_name': 'UserHierarchyPermission'}, {'perms': {'change': True, 'delete': True, 'add': True}, 'add_url': '/admin/auths/user/add/', 'admin_url': '/admin/auths/user/', 'name': <django.utils.functional.lazy.<locals>.__proxy__ object at 0x0137EE30>, 'object_name': 'User'}], 'app_url': '/admin/auths/', 'name': 'Auths'}, {'app_label': 'catalogo', 'has_module_perms': True, 'models': [{'perms': {'change': True, 'delete': True, 'add': True}, 'add_url': '/admin/catalogo/cliente/add/', 'admin_url': '/admin/catalogo/cliente/', 'name': 'Clientes', 'object_name': 'Cliente'}, {'perms': {'change': True, 'delete': True, 'add': True}, 'add_url': '/admin/catalogo/distribuidor/add/', 'admin_url': '/admin/catalogo/distribuidor/', 'name': <django.utils.functional.lazy.<locals>.__proxy__ object at 0x0137EEF0>, 'object_name': 'Distribuidor'}, {'perms': {'change': True, 'delete': True, 'add': True}, 'add_url': '/admin/catalogo/producto/add/', 'admin_url': '/admin/catalogo/producto/', 'name': <django.utils.functional.lazy.<locals>.__proxy__ object at 0x0137EF10>, 'object_name': 'Producto'}], 'app_url': '/admin/catalogo/', 'name': 'Catalogo'}, {'app_label': 'contenttypes', 'has_module_perms': True, 'models': [{'perms': {'change': True, 'delete': True, 'add': True}, 'add_url': '/admin/contenttypes/contenttype/add/', 'admin_url': '/admin/contenttypes/contenttype/', 'name': <django.utils.functional.lazy.<locals>.__proxy__ object at 0x0137EC50>, 'object_name': 'ContentType'}], 'app_url': '/admin/contenttypes/', 'name': <django.utils.functional.lazy.<locals>.__proxy__ object at 0x03E1F870>}, {'app_label': 'oauth2_provider', 'has_module_perms': True, 'models': [{'perms': {'change': True, 'delete': True, 'add': True}, 'add_url': '/admin/oauth2_provider/accesstoken/add/', 'admin_url': '/admin/oauth2_provider/accesstoken/', 'name': <django.utils.functional.lazy.<locals>.__proxy__ object at 0x0137EF70>, 'object_name': 'AccessToken'}, {'perms': {'change': True, 'delete': True, 'add': True}, 'add_url': '/admin/oauth2_provider/application/add/', 'admin_url': '/admin/oauth2_provider/application/', 'name': <django.utils.functional.lazy.<locals>.__proxy__ object at 0x0137EF50>, 'object_name': 'Application'}, {'perms': {'change': True, 'delete': True, 'add': True}, 'add_url': '/admin/oauth2_provider/grant/add/', 'admin_url': '/admin/oauth2_provider/grant/', 'name': <django.utils.functional.lazy.<locals>.__proxy__ object at 0x0137EAF0>, 'object_name': 'Grant'}, {'perms': {'change': True, 'delete': True, 'add': True}, 'add_url': '/admin/oauth2_provider/refreshtoken/add/', 'admin_url': '/admin/oauth2_provider/refreshtoken/', 'name': <django.utils.functional.lazy.<locals>.__proxy__ object at 0x0137E7B0>, 'object_name': 'RefreshToken'}], 'app_url': '/admin/oauth2_provider/', 'name': 'Django OAuth Toolkit'}], 'LANGUAGE_CODE': 'en-us', 'site_url': '/', 'site_title': <django.utils.functional.lazy.<locals>.__proxy__ object at 0x03E0BC50>, 'title': <django.utils.functional.lazy.<locals>.__proxy__ object at 0x03E0BD10>, 'site_header': <django.utils.functional.lazy.<locals>.__proxy__ object at 0x03E0BCB0>, 'has_permission': True, 'LANGUAGE_BIDI': False, 'app_list': [{'app_label': 'auth', 'has_module_perms': True, 'models': [{'perms': {'change': True, 'delete': True, 'add': True}, 'add_url': '/admin/auth/group/add/', 'admin_url': '/admin/auth/group/', 'name': <django.utils.functional.lazy.<locals>.__proxy__ object at 0x0136E2F0>, 'object_name': 'Group'}, {'perms': {'change': True, 'delete': True, 'add': True}, 'add_url': '/admin/auth/permission/add/', 'admin_url': '/admin/auth/permission/', 'name': <django.utils.functional.lazy.<locals>.__proxy__ object at 0x0136E530>, 'object_name': 'Permission'}], 'app_url': '/admin/auth/', 'name': <django.utils.functional.lazy.<locals>.__proxy__ object at 0x03E1F730>}, {'app_label': 'auths', 'has_module_perms': True, 'models': [{'perms': {'change': True, 'delete': True, 'add': True}, 'add_url': '/admin/auths/hierarchytype/add/', 'admin_url': '/admin/auths/hierarchytype/', 'name': <django.utils.functional.lazy.<locals>.__proxy__ object at 0x0136E730>, 'object_name': 'HierarchyType'}, {'perms': {'change': True, 'delete': True, 'add': True}, 'add_url': '/admin/auths/hierarchy/add/', 'admin_url': '/admin/auths/hierarchy/', 'name': <django.utils.functional.lazy.<locals>.__proxy__ object at 0x0136E250>, 'object_name': 'Hierarchy'}, {'perms': {'change': True, 'delete': True, 'add': True}, 'add_url': '/admin/auths/menu/add/', 'admin_url': '/admin/auths/menu/', 'name': <django.utils.functional.lazy.<locals>.__proxy__ object at 0x0136E350>, 'object_name': 'Menu'}, {'perms': {'change': True, 'delete': True, 'add': True}, 'add_url': '/admin/auths/person/add/', 'admin_url': '/admin/auths/person/', 'name': <django.utils.functional.lazy.<locals>.__proxy__ object at 0x0136E5D0>, 'object_name': 'Person'}, {'perms': {'change': True, 'delete': True, 'add': True}, 'add_url': '/admin/auths/userhierarchygroup/add/', 'admin_url': '/admin/auths/userhierarchygroup/', 'name': <django.utils.functional.lazy.<locals>.__proxy__ object at 0x0136E690>, 'object_name': 'UserHierarchyGroup'}, {'perms': {'change': True, 'delete': True, 'add': True}, 'add_url': '/admin/auths/userhierarchypermission/add/', 'admin_url': '/admin/auths/userhierarchypermission/', 'name': <django.utils.functional.lazy.<locals>.__proxy__ object at 0x0136E790>, 'object_name': 'UserHierarchyPermission'}, {'perms': {'change': True, 'delete': True, 'add': True}, 'add_url': '/admin/auths/user/add/', 'admin_url': '/admin/auths/user/', 'name': <django.utils.functional.lazy.<locals>.__proxy__ object at 0x0136E710>, 'object_name': 'User'}], 'app_url': '/admin/auths/', 'name': 'Auths'}, {'app_label': 'catalogo', 'has_module_perms': True, 'models': [{'perms': {'change': True, 'delete': True, 'add': True}, 'add_url': '/admin/catalogo/cliente/add/', 'admin_url': '/admin/catalogo/cliente/', 'name': 'Clientes', 'object_name': 'Cliente'}, {'perms': {'change': True, 'delete': True, 'add': True}, 'add_url': '/admin/catalogo/distribuidor/add/', 'admin_url': '/admin/catalogo/distribuidor/', 'name': <django.utils.functional.lazy.<locals>.__proxy__ object at 0x0136E5F0>, 'object_name': 'Distribuidor'}, {'perms': {'change': True, 'delete': True, 'add': True}, 'add_url': '/admin/catalogo/producto/add/', 'admin_url': '/admin/catalogo/producto/', 'name': <django.utils.functional.lazy.<locals>.__proxy__ object at 0x0136E850>, 'object_name': 'Producto'}], 'app_url': '/admin/catalogo/', 'name': 'Catalogo'}, {'app_label': 'contenttypes', 'has_module_perms': True, 'models': [{'perms': {'change': True, 'delete': True, 'add': True}, 'add_url': '/admin/contenttypes/contenttype/add/', 'admin_url': '/admin/contenttypes/contenttype/', 'name': <django.utils.functional.lazy.<locals>.__proxy__ object at 0x0136E650>, 'object_name': 'ContentType'}], 'app_url': '/admin/contenttypes/', 'name': <django.utils.functional.lazy.<locals>.__proxy__ object at 0x03E1F870>}, {'app_label': 'oauth2_provider', 'has_module_perms': True, 'models': [{'perms': {'change': True, 'delete': True, 'add': True}, 'add_url': '/admin/oauth2_provider/accesstoken/add/', 'admin_url': '/admin/oauth2_provider/accesstoken/', 'name': <django.utils.functional.lazy.<locals>.__proxy__ object at 0x0136E770>, 'object_name': 'AccessToken'}, {'perms': {'change': True, 'delete': True, 'add': True}, 'add_url': '/admin/oauth2_provider/application/add/', 'admin_url': '/admin/oauth2_provider/application/', 'name': <django.utils.functional.lazy.<locals>.__proxy__ object at 0x0136E7D0>, 'object_name': 'Application'}, {'perms': {'change': True, 'delete': True, 'add': True}, 'add_url': '/admin/oauth2_provider/grant/add/', 'admin_url': '/admin/oauth2_provider/grant/', 'name': <django.utils.functional.lazy.<locals>.__proxy__ object at 0x0136E6D0>, 'object_name': 'Grant'}, {'perms': {'change': True, 'delete': True, 'add': True}, 'add_url': '/admin/oauth2_provider/refreshtoken/add/', 'admin_url': '/admin/oauth2_provider/refreshtoken/', 'name': <django.utils.functional.lazy.<locals>.__proxy__ object at 0x0136E6F0>, 'object_name': 'RefreshToken'}], 'app_url': '/admin/oauth2_provider/', 'name': 'Django OAuth Toolkit'}]}]"
[2016-11-09 15:10:48] DEBUG [django.db.backends:90] (0.001) SELECT "django_admin_log"."id", "django_admin_log"."action_time", "django_admin_log"."user_id", "django_admin_log"."content_type_id", "django_admin_log"."object_id", "django_admin_log"."object_repr", "django_admin_log"."action_flag", "django_admin_log"."change_message", "auths_user"."password", "auths_user"."last_login", "auths_user"."is_superuser", "auths_user"."username", "auths_user"."first_name", "auths_user"."last_name", "auths_user"."email", "auths_user"."is_staff", "auths_user"."is_active", "auths_user"."date_joined", "auths_user"."id", "auths_user"."last_hierarchy_id", "auths_user"."last_module_id", "auths_user"."person_id", "auths_user"."updated_at", "auths_user"."registered_by", "django_content_type"."id", "django_content_type"."app_label", "django_content_type"."model" FROM "django_admin_log" INNER JOIN "auths_user" ON ("django_admin_log"."user_id" = "auths_user"."id") LEFT OUTER JOIN "django_content_type" ON ("django_admin_log"."content_type_id" = "django_content_type"."id") WHERE "django_admin_log"."user_id" = '25e7efce92ee410c84e90b3c8ba9e969' ORDER BY "django_admin_log"."action_time" DESC LIMIT 10; args=('25e7efce92ee410c84e90b3c8ba9e969',)
[2016-11-09 15:10:48] INFO [django.server:131] "GET /admin/ HTTP/1.1" 200 11063
[2016-11-09 15:10:48] INFO [django.server:131] "GET /static/admin/css/dashboard.css HTTP/1.1" 304 0
[2016-11-09 15:10:48] INFO [django.server:131] "GET /static/admin/img/icon-addlink.svg HTTP/1.1" 304 0
[2016-11-09 15:10:48] INFO [django.server:131] "GET /static/admin/img/icon-changelink.svg HTTP/1.1" 304 0
[2016-11-09 15:10:48] INFO [django.server:131] "GET /static/admin/fonts/Roboto-Bold-webfont.woff HTTP/1.1" 200 82564
[2016-11-09 15:10:58] DEBUG [django.db.backends:90] (0.001) SELECT "django_session"."session_key", "django_session"."session_data", "django_session"."expire_date" FROM "django_session" WHERE ("django_session"."expire_date" > '2016-11-09 20:10:58.198470' AND "django_session"."session_key" = '4g513lvyqdjg2ebhta9jniml3iwymfwr'); args=('2016-11-09 20:10:58.198470', '4g513lvyqdjg2ebhta9jniml3iwymfwr')
[2016-11-09 15:10:58] DEBUG [django.db.backends:90] (0.000) SELECT "auths_user"."password", "auths_user"."last_login", "auths_user"."is_superuser", "auths_user"."username", "auths_user"."first_name", "auths_user"."last_name", "auths_user"."email", "auths_user"."is_staff", "auths_user"."is_active", "auths_user"."date_joined", "auths_user"."id", "auths_user"."last_hierarchy_id", "auths_user"."last_module_id", "auths_user"."person_id", "auths_user"."updated_at", "auths_user"."registered_by" FROM "auths_user" WHERE "auths_user"."id" = '25e7efce92ee410c84e90b3c8ba9e969'; args=('25e7efce92ee410c84e90b3c8ba9e969',)
[2016-11-09 15:10:58] DEBUG [django.db.backends:90] (0.000) SELECT COUNT(*) AS "__count" FROM "catalogo_distribuidor"; args=()
[2016-11-09 15:10:58] DEBUG [django.db.backends:90] (0.000) SELECT COUNT(*) AS "__count" FROM "catalogo_distribuidor"; args=()
[2016-11-09 15:10:58] DEBUG [django.db.backends:90] (0.000) SELECT "catalogo_distribuidor"."id", "catalogo_distribuidor"."nombre", "catalogo_distribuidor"."ruc", "catalogo_distribuidor"."telefono", "catalogo_distribuidor"."direccion" FROM "catalogo_distribuidor" ORDER BY "catalogo_distribuidor"."id" DESC; args=()
[2016-11-09 15:10:58] DEBUG [django.template:929] Exception while resolving variable 'errors' in template 'admin/change_list.html'.
Traceback (most recent call last):
  File "D:\pydev\lp\marketsoft\ve_market\lib\site-packages\django\template\base.py", line 885, in _resolve_lookup
    current = current[bit]
TypeError: 'NoneType' object is not subscriptable

During handling of the above exception, another exception occurred:

Traceback (most recent call last):
  File "D:\pydev\lp\marketsoft\ve_market\lib\site-packages\django\template\base.py", line 893, in _resolve_lookup
    current = getattr(current, bit)
AttributeError: 'NoneType' object has no attribute 'errors'

During handling of the above exception, another exception occurred:

Traceback (most recent call last):
  File "D:\pydev\lp\marketsoft\ve_market\lib\site-packages\django\template\base.py", line 900, in _resolve_lookup
    current = current[int(bit)]
ValueError: invalid literal for int() with base 10: 'errors'

During handling of the above exception, another exception occurred:

Traceback (most recent call last):
  File "D:\pydev\lp\marketsoft\ve_market\lib\site-packages\django\template\base.py", line 907, in _resolve_lookup
    (bit, current))  # missing attribute
django.template.base.VariableDoesNotExist: Failed lookup for key [errors] in 'None'
[2016-11-09 15:10:58] DEBUG [django.template:929] Exception while resolving variable 'show' in template 'admin/change_list.html'.
Traceback (most recent call last):
  File "D:\pydev\lp\marketsoft\ve_market\lib\site-packages\django\template\base.py", line 885, in _resolve_lookup
    current = current[bit]
  File "D:\pydev\lp\marketsoft\ve_market\lib\site-packages\django\template\context.py", line 75, in __getitem__
    raise KeyError(key)
KeyError: 'show'

During handling of the above exception, another exception occurred:

Traceback (most recent call last):
  File "D:\pydev\lp\marketsoft\ve_market\lib\site-packages\django\template\base.py", line 891, in _resolve_lookup
    if isinstance(current, BaseContext) and getattr(type(current), bit):
AttributeError: type object 'RequestContext' has no attribute 'show'

During handling of the above exception, another exception occurred:

Traceback (most recent call last):
  File "D:\pydev\lp\marketsoft\ve_market\lib\site-packages\django\template\base.py", line 900, in _resolve_lookup
    current = current[int(bit)]
ValueError: invalid literal for int() with base 10: 'show'

During handling of the above exception, another exception occurred:

Traceback (most recent call last):
  File "D:\pydev\lp\marketsoft\ve_market\lib\site-packages\django\template\base.py", line 907, in _resolve_lookup
    (bit, current))  # missing attribute
django.template.base.VariableDoesNotExist: Failed lookup for key [show] in "[{'False': False, 'None': None, 'True': True, 'csrf_token': <SimpleLazyObject: <function csrf.<locals>._get_val at 0x01394CD8>>}]"
[2016-11-09 15:10:58] DEBUG [django.template:929] Exception while resolving variable 'is_multipart' in template 'admin/change_list.html'.
Traceback (most recent call last):
  File "D:\pydev\lp\marketsoft\ve_market\lib\site-packages\django\template\base.py", line 885, in _resolve_lookup
    current = current[bit]
TypeError: 'NoneType' object is not subscriptable

During handling of the above exception, another exception occurred:

Traceback (most recent call last):
  File "D:\pydev\lp\marketsoft\ve_market\lib\site-packages\django\template\base.py", line 893, in _resolve_lookup
    current = getattr(current, bit)
AttributeError: 'NoneType' object has no attribute 'is_multipart'

During handling of the above exception, another exception occurred:

Traceback (most recent call last):
  File "D:\pydev\lp\marketsoft\ve_market\lib\site-packages\django\template\base.py", line 900, in _resolve_lookup
    current = current[int(bit)]
ValueError: invalid literal for int() with base 10: 'is_multipart'

During handling of the above exception, another exception occurred:

Traceback (most recent call last):
  File "D:\pydev\lp\marketsoft\ve_market\lib\site-packages\django\template\base.py", line 907, in _resolve_lookup
    (bit, current))  # missing attribute
django.template.base.VariableDoesNotExist: Failed lookup for key [is_multipart] in 'None'
[2016-11-09 15:10:58] INFO [django.server:131] "GET /admin/catalogo/distribuidor/ HTTP/1.1" 200 3508
[2016-11-09 15:10:58] INFO [django.server:131] "GET /static/admin/css/changelists.css HTTP/1.1" 304 0
[2016-11-09 15:10:58] DEBUG [django.db.backends:90] (0.001) SELECT "django_session"."session_key", "django_session"."session_data", "django_session"."expire_date" FROM "django_session" WHERE ("django_session"."expire_date" > '2016-11-09 20:10:58.574767' AND "django_session"."session_key" = '4g513lvyqdjg2ebhta9jniml3iwymfwr'); args=('2016-11-09 20:10:58.574767', '4g513lvyqdjg2ebhta9jniml3iwymfwr')
[2016-11-09 15:10:58] DEBUG [django.db.backends:90] (0.000) SELECT "auths_user"."password", "auths_user"."last_login", "auths_user"."is_superuser", "auths_user"."username", "auths_user"."first_name", "auths_user"."last_name", "auths_user"."email", "auths_user"."is_staff", "auths_user"."is_active", "auths_user"."date_joined", "auths_user"."id", "auths_user"."last_hierarchy_id", "auths_user"."last_module_id", "auths_user"."person_id", "auths_user"."updated_at", "auths_user"."registered_by" FROM "auths_user" WHERE "auths_user"."id" = '25e7efce92ee410c84e90b3c8ba9e969'; args=('25e7efce92ee410c84e90b3c8ba9e969',)
[2016-11-09 15:10:58] INFO [django.server:131] "GET /admin/jsi18n/ HTTP/1.1" 200 3189
[2016-11-09 15:10:58] INFO [django.server:131] "GET /static/admin/js/core.js HTTP/1.1" 304 0
[2016-11-09 15:10:58] INFO [django.server:131] "GET /static/admin/js/vendor/jquery/jquery.js HTTP/1.1" 304 0
[2016-11-09 15:10:58] INFO [django.server:131] "GET /static/admin/js/jquery.init.js HTTP/1.1" 304 0
[2016-11-09 15:10:58] INFO [django.server:131] "GET /static/admin/js/admin/RelatedObjectLookups.js HTTP/1.1" 304 0
[2016-11-09 15:10:58] INFO [django.server:131] "GET /static/admin/js/actions.js HTTP/1.1" 304 0
[2016-11-09 15:10:58] INFO [django.server:131] "GET /static/admin/js/urlify.js HTTP/1.1" 304 0
[2016-11-09 15:10:58] INFO [django.server:131] "GET /static/admin/js/prepopulate.js HTTP/1.1" 304 0
[2016-11-09 15:10:58] INFO [django.server:131] "GET /static/admin/js/vendor/xregexp/xregexp.js HTTP/1.1" 304 0
[2016-11-09 15:10:59] INFO [django.server:131] "GET /static/admin/img/search.svg HTTP/1.1" 200 458
[2016-11-09 15:10:59] INFO [django.server:131] "GET /static/admin/img/tooltag-add.svg HTTP/1.1" 304 0
[2016-11-09 15:11:03] DEBUG [django.db.backends:90] (0.001) SELECT "django_session"."session_key", "django_session"."session_data", "django_session"."expire_date" FROM "django_session" WHERE ("django_session"."expire_date" > '2016-11-09 20:11:03.878536' AND "django_session"."session_key" = '4g513lvyqdjg2ebhta9jniml3iwymfwr'); args=('2016-11-09 20:11:03.878536', '4g513lvyqdjg2ebhta9jniml3iwymfwr')
[2016-11-09 15:11:03] DEBUG [django.db.backends:90] (0.000) SELECT "auths_user"."password", "auths_user"."last_login", "auths_user"."is_superuser", "auths_user"."username", "auths_user"."first_name", "auths_user"."last_name", "auths_user"."email", "auths_user"."is_staff", "auths_user"."is_active", "auths_user"."date_joined", "auths_user"."id", "auths_user"."last_hierarchy_id", "auths_user"."last_module_id", "auths_user"."person_id", "auths_user"."updated_at", "auths_user"."registered_by" FROM "auths_user" WHERE "auths_user"."id" = '25e7efce92ee410c84e90b3c8ba9e969'; args=('25e7efce92ee410c84e90b3c8ba9e969',)
[2016-11-09 15:11:03] DEBUG [django.db.backends:90] (0.000) BEGIN; args=None
[2016-11-09 15:11:03] DEBUG [django.db.backends:90] (0.000) SELECT "django_content_type"."id", "django_content_type"."app_label", "django_content_type"."model" FROM "django_content_type" WHERE ("django_content_type"."app_label" = 'catalogo' AND "django_content_type"."model" = 'distribuidor'); args=('catalogo', 'distribuidor')
[2016-11-09 15:11:04] INFO [django.server:131] "GET /admin/catalogo/distribuidor/add/ HTTP/1.1" 200 5409
[2016-11-09 15:11:04] DEBUG [django.db.backends:90] (0.002) SELECT "django_session"."session_key", "django_session"."session_data", "django_session"."expire_date" FROM "django_session" WHERE ("django_session"."expire_date" > '2016-11-09 20:11:04.114119' AND "django_session"."session_key" = '4g513lvyqdjg2ebhta9jniml3iwymfwr'); args=('2016-11-09 20:11:04.114119', '4g513lvyqdjg2ebhta9jniml3iwymfwr')
[2016-11-09 15:11:04] DEBUG [django.db.backends:90] (0.000) SELECT "auths_user"."password", "auths_user"."last_login", "auths_user"."is_superuser", "auths_user"."username", "auths_user"."first_name", "auths_user"."last_name", "auths_user"."email", "auths_user"."is_staff", "auths_user"."is_active", "auths_user"."date_joined", "auths_user"."id", "auths_user"."last_hierarchy_id", "auths_user"."last_module_id", "auths_user"."person_id", "auths_user"."updated_at", "auths_user"."registered_by" FROM "auths_user" WHERE "auths_user"."id" = '25e7efce92ee410c84e90b3c8ba9e969'; args=('25e7efce92ee410c84e90b3c8ba9e969',)
[2016-11-09 15:11:04] INFO [django.server:131] "GET /admin/jsi18n/ HTTP/1.1" 200 3189
[2016-11-09 15:11:04] INFO [django.server:131] "GET /static/admin/css/forms.css HTTP/1.1" 200 7750
[2016-11-09 15:11:04] INFO [django.server:131] "GET /static/admin/css/widgets.css HTTP/1.1" 200 10340
[2016-11-09 15:11:04] INFO [django.server:131] "GET /static/admin/js/change_form.js HTTP/1.1" 304 0
[2016-11-09 15:11:04] INFO [django.server:131] "GET /static/admin/js/prepopulate_init.js HTTP/1.1" 304 0
[2016-11-09 15:11:15] INFO [django.server:131] "OPTIONS /api/catalogo/cliente/ HTTP/1.1" 200 0
[2016-11-09 15:11:15] DEBUG [django.db.backends:90] (0.001) SELECT "oauth2_provider_accesstoken"."id", "oauth2_provider_accesstoken"."user_id", "oauth2_provider_accesstoken"."token", "oauth2_provider_accesstoken"."application_id", "oauth2_provider_accesstoken"."expires", "oauth2_provider_accesstoken"."scope", "auths_user"."password", "auths_user"."last_login", "auths_user"."is_superuser", "auths_user"."username", "auths_user"."first_name", "auths_user"."last_name", "auths_user"."email", "auths_user"."is_staff", "auths_user"."is_active", "auths_user"."date_joined", "auths_user"."id", "auths_user"."last_hierarchy_id", "auths_user"."last_module_id", "auths_user"."person_id", "auths_user"."updated_at", "auths_user"."registered_by", "oauth2_provider_application"."id", "oauth2_provider_application"."client_id", "oauth2_provider_application"."user_id", "oauth2_provider_application"."redirect_uris", "oauth2_provider_application"."client_type", "oauth2_provider_application"."authorization_grant_type", "oauth2_provider_application"."client_secret", "oauth2_provider_application"."name", "oauth2_provider_application"."skip_authorization" FROM "oauth2_provider_accesstoken" LEFT OUTER JOIN "auths_user" ON ("oauth2_provider_accesstoken"."user_id" = "auths_user"."id") INNER JOIN "oauth2_provider_application" ON ("oauth2_provider_accesstoken"."application_id" = "oauth2_provider_application"."id") WHERE "oauth2_provider_accesstoken"."token" = 'v6boU3GGygtj222XT92hdz9QbFyS2D'; args=('v6boU3GGygtj222XT92hdz9QbFyS2D',)
[2016-11-09 15:11:15] DEBUG [django.db.backends:90] (0.001) SELECT "oauth2_provider_accesstoken"."id", "oauth2_provider_accesstoken"."user_id", "oauth2_provider_accesstoken"."token", "oauth2_provider_accesstoken"."application_id", "oauth2_provider_accesstoken"."expires", "oauth2_provider_accesstoken"."scope", "auths_user"."password", "auths_user"."last_login", "auths_user"."is_superuser", "auths_user"."username", "auths_user"."first_name", "auths_user"."last_name", "auths_user"."email", "auths_user"."is_staff", "auths_user"."is_active", "auths_user"."date_joined", "auths_user"."id", "auths_user"."last_hierarchy_id", "auths_user"."last_module_id", "auths_user"."person_id", "auths_user"."updated_at", "auths_user"."registered_by", "oauth2_provider_application"."id", "oauth2_provider_application"."client_id", "oauth2_provider_application"."user_id", "oauth2_provider_application"."redirect_uris", "oauth2_provider_application"."client_type", "oauth2_provider_application"."authorization_grant_type", "oauth2_provider_application"."client_secret", "oauth2_provider_application"."name", "oauth2_provider_application"."skip_authorization" FROM "oauth2_provider_accesstoken" LEFT OUTER JOIN "auths_user" ON ("oauth2_provider_accesstoken"."user_id" = "auths_user"."id") INNER JOIN "oauth2_provider_application" ON ("oauth2_provider_accesstoken"."application_id" = "oauth2_provider_application"."id") WHERE "oauth2_provider_accesstoken"."token" = 'v6boU3GGygtj222XT92hdz9QbFyS2D'; args=('v6boU3GGygtj222XT92hdz9QbFyS2D',)
[2016-11-09 15:11:15] DEBUG [django.db.backends:90] (0.001) SELECT COUNT(*) AS "__count" FROM "catalogo_cliente"; args=()
[2016-11-09 15:11:15] DEBUG [django.db.backends:90] (0.000) SELECT "catalogo_cliente"."id", "catalogo_cliente"."nombre", "catalogo_cliente"."apellidos", "catalogo_cliente"."dni", "catalogo_cliente"."direccion", "catalogo_cliente"."fecha_nac", "catalogo_cliente"."created_at", "catalogo_cliente"."updated_at" FROM "catalogo_cliente" LIMIT 1; args=()
[2016-11-09 15:11:15] ERROR [django.request:124] Internal Server Error: /api/catalogo/cliente/
Traceback (most recent call last):
  File "D:\pydev\lp\marketsoft\ve_market\lib\site-packages\django\core\handlers\exception.py", line 39, in inner
    response = get_response(request)
  File "D:\pydev\lp\marketsoft\ve_market\lib\site-packages\django\core\handlers\base.py", line 249, in _legacy_get_response
    response = self._get_response(request)
  File "D:\pydev\lp\marketsoft\ve_market\lib\site-packages\django\core\handlers\base.py", line 187, in _get_response
    response = self.process_exception_by_middleware(e, request)
  File "D:\pydev\lp\marketsoft\ve_market\lib\site-packages\django\core\handlers\base.py", line 185, in _get_response
    response = wrapped_callback(request, *callback_args, **callback_kwargs)
  File "D:\pydev\lp\marketsoft\ve_market\lib\site-packages\django\views\decorators\csrf.py", line 58, in wrapped_view
    return view_func(*args, **kwargs)
  File "D:\pydev\lp\marketsoft\ve_market\lib\site-packages\rest_framework\viewsets.py", line 83, in view
    return self.dispatch(request, *args, **kwargs)
  File "D:\pydev\lp\marketsoft\ve_market\lib\site-packages\rest_framework\views.py", line 477, in dispatch
    response = self.handle_exception(exc)
  File "D:\pydev\lp\marketsoft\ve_market\lib\site-packages\rest_framework\views.py", line 437, in handle_exception
    self.raise_uncaught_exception(exc)
  File "D:\pydev\lp\marketsoft\ve_market\lib\site-packages\rest_framework\views.py", line 474, in dispatch
    response = handler(request, *args, **kwargs)
  File "D:\pydev\lp\marketsoft\ve_market\lib\site-packages\rest_framework\mixins.py", line 45, in list
    return self.get_paginated_response(serializer.data)
  File "D:\pydev\lp\marketsoft\ve_market\lib\site-packages\rest_framework\serializers.py", line 725, in data
    ret = super(ListSerializer, self).data
  File "D:\pydev\lp\marketsoft\ve_market\lib\site-packages\rest_framework\serializers.py", line 262, in data
    self._data = self.to_representation(self.instance)
  File "D:\pydev\lp\marketsoft\ve_market\lib\site-packages\rest_framework\serializers.py", line 643, in to_representation
    self.child.to_representation(item) for item in iterable
  File "D:\pydev\lp\marketsoft\ve_market\lib\site-packages\rest_framework\serializers.py", line 643, in <listcomp>
    self.child.to_representation(item) for item in iterable
  File "D:\pydev\lp\marketsoft\ve_market\lib\site-packages\rest_framework\serializers.py", line 479, in to_representation
    fields = self._readable_fields
  File "D:\pydev\lp\marketsoft\ve_market\lib\site-packages\django\utils\functional.py", line 35, in __get__
    res = instance.__dict__[self.name] = self.func(instance)
  File "D:\pydev\lp\marketsoft\ve_market\lib\site-packages\rest_framework\serializers.py", line 373, in _readable_fields
    field for field in self.fields.values()
  File "D:\pydev\lp\marketsoft\ve_market\lib\site-packages\rest_framework\serializers.py", line 359, in fields
    for key, value in self.get_fields().items():
  File "D:\pydev\lp\marketsoft\ve_market\lib\site-packages\rest_framework\serializers.py", line 980, in get_fields
    field_names = self.get_field_names(declared_fields, info)
  File "D:\pydev\lp\marketsoft\ve_market\lib\site-packages\rest_framework\serializers.py", line 1053, in get_field_names
    serializer_class=self.__class__.__name__
AssertionError: ("Creating a ModelSerializer without either the 'fields' attribute or the 'exclude' attribute has been deprecated since 3.3.0, and is now disallowed. Add an explicit fields = '__all__' to the ClienteSerializer serializer.",)
[2016-11-09 15:11:16] DEBUG [django.db.backends:90] (0.000) SELECT "catalogo_cliente"."id", "catalogo_cliente"."nombre", "catalogo_cliente"."apellidos", "catalogo_cliente"."dni", "catalogo_cliente"."direccion", "catalogo_cliente"."fecha_nac", "catalogo_cliente"."created_at", "catalogo_cliente"."updated_at" FROM "catalogo_cliente" LIMIT 21; args=()
[2016-11-09 15:11:16] ERROR [django.server:131] "GET /api/catalogo/cliente/ HTTP/1.1" 500 20519
