[2016-11-13 23:37:51] DEBUG [django.db.backends:90] (0.002) 
            SELECT name, type FROM sqlite_master
            WHERE type in ('table', 'view') AND NOT name='sqlite_sequence'
            ORDER BY name; args=None
[2016-11-13 23:37:51] DEBUG [django.db.backends:90] (0.001) SELECT "django_migrations"."app", "django_migrations"."name" FROM "django_migrations"; args=()
[2016-11-13 23:42:36] DEBUG [django.db.backends:90] (0.002) 
            SELECT name, type FROM sqlite_master
            WHERE type in ('table', 'view') AND NOT name='sqlite_sequence'
            ORDER BY name; args=None
[2016-11-13 23:42:36] DEBUG [django.db.backends:90] (0.000) SELECT "django_migrations"."app", "django_migrations"."name" FROM "django_migrations"; args=()
[2016-11-13 23:43:02] DEBUG [django.db.backends:90] (0.001) 
            SELECT name, type FROM sqlite_master
            WHERE type in ('table', 'view') AND NOT name='sqlite_sequence'
            ORDER BY name; args=None
[2016-11-13 23:43:02] DEBUG [django.db.backends:90] (0.000) SELECT "django_migrations"."app", "django_migrations"."name" FROM "django_migrations"; args=()
[2016-11-13 23:43:17] DEBUG [django.db.backends:90] (0.001) 
            SELECT name, type FROM sqlite_master
            WHERE type in ('table', 'view') AND NOT name='sqlite_sequence'
            ORDER BY name; args=None
[2016-11-13 23:43:17] DEBUG [django.db.backends:90] (0.000) SELECT "django_migrations"."app", "django_migrations"."name" FROM "django_migrations"; args=()
[2016-11-13 23:43:17] DEBUG [django.db.backends:90] (0.000) 
            SELECT name, type FROM sqlite_master
            WHERE type in ('table', 'view') AND NOT name='sqlite_sequence'
            ORDER BY name; args=None
[2016-11-13 23:43:17] DEBUG [django.db.backends:90] (0.000) SELECT "django_migrations"."app", "django_migrations"."name" FROM "django_migrations"; args=()
[2016-11-13 23:43:17] DEBUG [django.db.backends:90] (0.000) 
            SELECT name, type FROM sqlite_master
            WHERE type in ('table', 'view') AND NOT name='sqlite_sequence'
            ORDER BY name; args=None
[2016-11-13 23:43:17] DEBUG [django.db.backends:90] (0.000) SELECT "django_migrations"."app", "django_migrations"."name" FROM "django_migrations"; args=()
[2016-11-13 23:43:17] DEBUG [django.db.backends:90] (0.001) SELECT "django_content_type"."id", "django_content_type"."app_label", "django_content_type"."model" FROM "django_content_type" WHERE ("django_content_type"."app_label" = 'admin' AND "django_content_type"."model" = 'logentry'); args=('admin', 'logentry')
[2016-11-13 23:43:17] DEBUG [django.db.backends:90] (0.000) SELECT "auth_permission"."content_type_id", "auth_permission"."codename" FROM "auth_permission" INNER JOIN "django_content_type" ON ("auth_permission"."content_type_id" = "django_content_type"."id") WHERE "auth_permission"."content_type_id" IN (1) ORDER BY "django_content_type"."app_label" ASC, "django_content_type"."model" ASC, "auth_permission"."codename" ASC; args=(1,)
[2016-11-13 23:43:17] DEBUG [django.db.backends:90] (0.000) SELECT "django_content_type"."id", "django_content_type"."app_label", "django_content_type"."model" FROM "django_content_type" WHERE "django_content_type"."app_label" = 'admin'; args=('admin',)
[2016-11-13 23:43:17] DEBUG [django.db.backends:90] (0.000) SELECT "django_content_type"."id", "django_content_type"."app_label", "django_content_type"."model" FROM "django_content_type" WHERE ("django_content_type"."app_label" = 'auth' AND "django_content_type"."model" = 'permission'); args=('auth', 'permission')
[2016-11-13 23:43:17] DEBUG [django.db.backends:90] (0.000) SELECT "django_content_type"."id", "django_content_type"."app_label", "django_content_type"."model" FROM "django_content_type" WHERE ("django_content_type"."app_label" = 'auth' AND "django_content_type"."model" = 'group'); args=('auth', 'group')
[2016-11-13 23:43:17] DEBUG [django.db.backends:90] (0.000) SELECT "auth_permission"."content_type_id", "auth_permission"."codename" FROM "auth_permission" INNER JOIN "django_content_type" ON ("auth_permission"."content_type_id" = "django_content_type"."id") WHERE "auth_permission"."content_type_id" IN (2, 3) ORDER BY "django_content_type"."app_label" ASC, "django_content_type"."model" ASC, "auth_permission"."codename" ASC; args=(2, 3)
[2016-11-13 23:43:17] DEBUG [django.db.backends:90] (0.000) SELECT "django_content_type"."id", "django_content_type"."app_label", "django_content_type"."model" FROM "django_content_type" WHERE "django_content_type"."app_label" = 'auth'; args=('auth',)
[2016-11-13 23:43:17] DEBUG [django.db.backends:90] (0.000) SELECT "django_content_type"."id", "django_content_type"."app_label", "django_content_type"."model" FROM "django_content_type" WHERE ("django_content_type"."app_label" = 'contenttypes' AND "django_content_type"."model" = 'contenttype'); args=('contenttypes', 'contenttype')
[2016-11-13 23:43:17] DEBUG [django.db.backends:90] (0.000) SELECT "auth_permission"."content_type_id", "auth_permission"."codename" FROM "auth_permission" INNER JOIN "django_content_type" ON ("auth_permission"."content_type_id" = "django_content_type"."id") WHERE "auth_permission"."content_type_id" IN (4) ORDER BY "django_content_type"."app_label" ASC, "django_content_type"."model" ASC, "auth_permission"."codename" ASC; args=(4,)
[2016-11-13 23:43:17] DEBUG [django.db.backends:90] (0.000) SELECT "django_content_type"."id", "django_content_type"."app_label", "django_content_type"."model" FROM "django_content_type" WHERE "django_content_type"."app_label" = 'contenttypes'; args=('contenttypes',)
[2016-11-13 23:43:17] DEBUG [django.db.backends:90] (0.000) SELECT "django_content_type"."id", "django_content_type"."app_label", "django_content_type"."model" FROM "django_content_type" WHERE ("django_content_type"."app_label" = 'sessions' AND "django_content_type"."model" = 'session'); args=('sessions', 'session')
[2016-11-13 23:43:17] DEBUG [django.db.backends:90] (0.000) SELECT "auth_permission"."content_type_id", "auth_permission"."codename" FROM "auth_permission" INNER JOIN "django_content_type" ON ("auth_permission"."content_type_id" = "django_content_type"."id") WHERE "auth_permission"."content_type_id" IN (5) ORDER BY "django_content_type"."app_label" ASC, "django_content_type"."model" ASC, "auth_permission"."codename" ASC; args=(5,)
[2016-11-13 23:43:17] DEBUG [django.db.backends:90] (0.000) SELECT "django_content_type"."id", "django_content_type"."app_label", "django_content_type"."model" FROM "django_content_type" WHERE "django_content_type"."app_label" = 'sessions'; args=('sessions',)
[2016-11-13 23:43:17] DEBUG [django.db.backends:90] (0.000) SELECT "django_content_type"."id", "django_content_type"."app_label", "django_content_type"."model" FROM "django_content_type" WHERE ("django_content_type"."app_label" = 'corsheaders' AND "django_content_type"."model" = 'corsmodel'); args=('corsheaders', 'corsmodel')
[2016-11-13 23:43:17] DEBUG [django.db.backends:90] (0.001) SELECT "auth_permission"."content_type_id", "auth_permission"."codename" FROM "auth_permission" INNER JOIN "django_content_type" ON ("auth_permission"."content_type_id" = "django_content_type"."id") WHERE "auth_permission"."content_type_id" IN (6) ORDER BY "django_content_type"."app_label" ASC, "django_content_type"."model" ASC, "auth_permission"."codename" ASC; args=(6,)
[2016-11-13 23:43:17] DEBUG [django.db.backends:90] (0.000) SELECT "django_content_type"."id", "django_content_type"."app_label", "django_content_type"."model" FROM "django_content_type" WHERE "django_content_type"."app_label" = 'corsheaders'; args=('corsheaders',)
[2016-11-13 23:43:17] DEBUG [django.db.backends:90] (0.000) SELECT "django_content_type"."id", "django_content_type"."app_label", "django_content_type"."model" FROM "django_content_type" WHERE ("django_content_type"."app_label" = 'oauth2_provider' AND "django_content_type"."model" = 'grant'); args=('oauth2_provider', 'grant')
[2016-11-13 23:43:17] DEBUG [django.db.backends:90] (0.000) SELECT "django_content_type"."id", "django_content_type"."app_label", "django_content_type"."model" FROM "django_content_type" WHERE ("django_content_type"."app_label" = 'oauth2_provider' AND "django_content_type"."model" = 'accesstoken'); args=('oauth2_provider', 'accesstoken')
[2016-11-13 23:43:17] DEBUG [django.db.backends:90] (0.000) SELECT "django_content_type"."id", "django_content_type"."app_label", "django_content_type"."model" FROM "django_content_type" WHERE ("django_content_type"."app_label" = 'oauth2_provider' AND "django_content_type"."model" = 'refreshtoken'); args=('oauth2_provider', 'refreshtoken')
[2016-11-13 23:43:17] DEBUG [django.db.backends:90] (0.001) SELECT "django_content_type"."id", "django_content_type"."app_label", "django_content_type"."model" FROM "django_content_type" WHERE ("django_content_type"."app_label" = 'oauth2_provider' AND "django_content_type"."model" = 'application'); args=('oauth2_provider', 'application')
[2016-11-13 23:43:17] DEBUG [django.db.backends:90] (0.000) SELECT "auth_permission"."content_type_id", "auth_permission"."codename" FROM "auth_permission" INNER JOIN "django_content_type" ON ("auth_permission"."content_type_id" = "django_content_type"."id") WHERE "auth_permission"."content_type_id" IN (8, 9, 10, 7) ORDER BY "django_content_type"."app_label" ASC, "django_content_type"."model" ASC, "auth_permission"."codename" ASC; args=(8, 9, 10, 7)
[2016-11-13 23:43:17] DEBUG [django.db.backends:90] (0.000) SELECT "django_content_type"."id", "django_content_type"."app_label", "django_content_type"."model" FROM "django_content_type" WHERE "django_content_type"."app_label" = 'oauth2_provider'; args=('oauth2_provider',)
[2016-11-13 23:43:17] DEBUG [django.db.backends:90] (0.000) SELECT "django_content_type"."id", "django_content_type"."app_label", "django_content_type"."model" FROM "django_content_type" WHERE ("django_content_type"."app_label" = 'auths' AND "django_content_type"."model" = 'hierarchytype'); args=('auths', 'hierarchytype')
[2016-11-13 23:43:17] DEBUG [django.db.backends:90] (0.000) SELECT "django_content_type"."id", "django_content_type"."app_label", "django_content_type"."model" FROM "django_content_type" WHERE ("django_content_type"."app_label" = 'auths' AND "django_content_type"."model" = 'menu'); args=('auths', 'menu')
[2016-11-13 23:43:17] DEBUG [django.db.backends:90] (0.000) SELECT "django_content_type"."id", "django_content_type"."app_label", "django_content_type"."model" FROM "django_content_type" WHERE ("django_content_type"."app_label" = 'auths' AND "django_content_type"."model" = 'userhierarchygroup'); args=('auths', 'userhierarchygroup')
[2016-11-13 23:43:17] DEBUG [django.db.backends:90] (0.000) SELECT "django_content_type"."id", "django_content_type"."app_label", "django_content_type"."model" FROM "django_content_type" WHERE ("django_content_type"."app_label" = 'auths' AND "django_content_type"."model" = 'person'); args=('auths', 'person')
[2016-11-13 23:43:17] DEBUG [django.db.backends:90] (0.000) SELECT "django_content_type"."id", "django_content_type"."app_label", "django_content_type"."model" FROM "django_content_type" WHERE ("django_content_type"."app_label" = 'auths' AND "django_content_type"."model" = 'hierarchy'); args=('auths', 'hierarchy')
[2016-11-13 23:43:17] DEBUG [django.db.backends:90] (0.000) SELECT "django_content_type"."id", "django_content_type"."app_label", "django_content_type"."model" FROM "django_content_type" WHERE ("django_content_type"."app_label" = 'auths' AND "django_content_type"."model" = 'user'); args=('auths', 'user')
[2016-11-13 23:43:17] DEBUG [django.db.backends:90] (0.000) SELECT "django_content_type"."id", "django_content_type"."app_label", "django_content_type"."model" FROM "django_content_type" WHERE ("django_content_type"."app_label" = 'auths' AND "django_content_type"."model" = 'userhierarchypermission'); args=('auths', 'userhierarchypermission')
[2016-11-13 23:43:17] DEBUG [django.db.backends:90] (0.000) SELECT "auth_permission"."content_type_id", "auth_permission"."codename" FROM "auth_permission" INNER JOIN "django_content_type" ON ("auth_permission"."content_type_id" = "django_content_type"."id") WHERE "auth_permission"."content_type_id" IN (11, 12, 13, 14, 15, 16, 17) ORDER BY "django_content_type"."app_label" ASC, "django_content_type"."model" ASC, "auth_permission"."codename" ASC; args=(11, 12, 13, 14, 15, 16, 17)
[2016-11-13 23:43:17] DEBUG [django.db.backends:90] (0.000) SELECT "django_content_type"."id", "django_content_type"."app_label", "django_content_type"."model" FROM "django_content_type" WHERE "django_content_type"."app_label" = 'auths'; args=('auths',)
[2016-11-13 23:43:17] DEBUG [django.db.backends:90] (0.000) SELECT "django_content_type"."id", "django_content_type"."app_label", "django_content_type"."model" FROM "django_content_type" WHERE ("django_content_type"."app_label" = 'registro' AND "django_content_type"."model" = 'distribuidor'); args=('registro', 'distribuidor')
[2016-11-13 23:43:17] DEBUG [django.db.backends:90] (0.000) SELECT "django_content_type"."id", "django_content_type"."app_label", "django_content_type"."model" FROM "django_content_type" WHERE ("django_content_type"."app_label" = 'registro' AND "django_content_type"."model" = 'producto'); args=('registro', 'producto')
[2016-11-13 23:43:17] DEBUG [django.db.backends:90] (0.000) SELECT "django_content_type"."id", "django_content_type"."app_label", "django_content_type"."model" FROM "django_content_type" WHERE ("django_content_type"."app_label" = 'registro' AND "django_content_type"."model" = 'detallecompra'); args=('registro', 'detallecompra')
[2016-11-13 23:43:17] DEBUG [django.db.backends:90] (0.000) SELECT "django_content_type"."id", "django_content_type"."app_label", "django_content_type"."model" FROM "django_content_type" WHERE ("django_content_type"."app_label" = 'registro' AND "django_content_type"."model" = 'marca'); args=('registro', 'marca')
[2016-11-13 23:43:17] DEBUG [django.db.backends:90] (0.000) SELECT "django_content_type"."id", "django_content_type"."app_label", "django_content_type"."model" FROM "django_content_type" WHERE ("django_content_type"."app_label" = 'registro' AND "django_content_type"."model" = 'cabecera'); args=('registro', 'cabecera')
[2016-11-13 23:43:17] DEBUG [django.db.backends:90] (0.000) SELECT "django_content_type"."id", "django_content_type"."app_label", "django_content_type"."model" FROM "django_content_type" WHERE ("django_content_type"."app_label" = 'registro' AND "django_content_type"."model" = 'cliente'); args=('registro', 'cliente')
[2016-11-13 23:43:17] DEBUG [django.db.backends:90] (0.000) SELECT "auth_permission"."content_type_id", "auth_permission"."codename" FROM "auth_permission" INNER JOIN "django_content_type" ON ("auth_permission"."content_type_id" = "django_content_type"."id") WHERE "auth_permission"."content_type_id" IN (18, 19, 20, 21, 22, 23) ORDER BY "django_content_type"."app_label" ASC, "django_content_type"."model" ASC, "auth_permission"."codename" ASC; args=(18, 19, 20, 21, 22, 23)
[2016-11-13 23:43:17] DEBUG [django.db.backends:90] (0.000) SELECT "django_content_type"."id", "django_content_type"."app_label", "django_content_type"."model" FROM "django_content_type" WHERE "django_content_type"."app_label" = 'registro'; args=('registro',)
[2016-11-13 23:43:26] DEBUG [django.db.backends:90] (0.001) 
            SELECT name, type FROM sqlite_master
            WHERE type in ('table', 'view') AND NOT name='sqlite_sequence'
            ORDER BY name; args=None
[2016-11-13 23:43:26] DEBUG [django.db.backends:90] (0.001) SELECT "django_migrations"."app", "django_migrations"."name" FROM "django_migrations"; args=()
[2016-11-13 23:44:10] DEBUG [django.template:929] Exception while resolving variable 'name' in template 'unknown'.
Traceback (most recent call last):
  File "D:\pydev\lp\marketsoft\ve_market\lib\site-packages\django\core\handlers\exception.py", line 39, in inner
    response = get_response(request)
  File "D:\pydev\lp\marketsoft\ve_market\lib\site-packages\django\core\handlers\base.py", line 249, in _legacy_get_response
    response = self._get_response(request)
  File "D:\pydev\lp\marketsoft\ve_market\lib\site-packages\django\core\handlers\base.py", line 172, in _get_response
    resolver_match = resolver.resolve(request.path_info)
  File "D:\pydev\lp\marketsoft\ve_market\lib\site-packages\django\urls\resolvers.py", line 300, in resolve
    raise Resolver404({'tried': tried, 'path': new_path})
django.urls.exceptions.Resolver404: {'tried': [[<RegexURLResolver <RegexURLPattern list> (admin:admin) ^admin/>], [<RegexURLResolver <module 'django.contrib.admindocs.urls' from 'D:\\pydev\\lp\\marketsoft\\ve_market\\lib\\site-packages\\django\\contrib\\admindocs\\urls.py'> (None:None) ^admin/doc/>], [<RegexURLResolver <module 'rest_framework.urls' from 'D:\\pydev\\lp\\marketsoft\\ve_market\\lib\\site-packages\\rest_framework\\urls.py'> (rest_framework:rest_framework) ^api-auth/>], [<RegexURLResolver <module 'oauth2_provider.urls' from 'D:\\pydev\\lp\\marketsoft\\ve_market\\lib\\site-packages\\oauth2_provider\\urls.py'> (None:oauth2_provider) ^o/>], [<RegexURLResolver <module 'market_service_apps.auths_api.urls' from 'D:\\pydev\\lp\\marketsoft\\market_serve\\market_service_apps\\auths_api\\urls.py'> (None:None) ^api/auths/>], [<RegexURLResolver <module 'market_service_apps.registro_api.urls' from 'D:\\pydev\\lp\\marketsoft\\market_serve\\market_service_apps\\registro_api\\urls.py'> (None:None) ^api/registro/>]], 'path': ''}

During handling of the above exception, another exception occurred:

Traceback (most recent call last):
  File "D:\pydev\lp\marketsoft\ve_market\lib\site-packages\django\template\base.py", line 885, in _resolve_lookup
    current = current[bit]
TypeError: 'RegexURLResolver' object is not subscriptable

During handling of the above exception, another exception occurred:

Traceback (most recent call last):
  File "D:\pydev\lp\marketsoft\ve_market\lib\site-packages\django\template\base.py", line 893, in _resolve_lookup
    current = getattr(current, bit)
AttributeError: 'RegexURLResolver' object has no attribute 'name'

During handling of the above exception, another exception occurred:

Traceback (most recent call last):
  File "D:\pydev\lp\marketsoft\ve_market\lib\site-packages\django\template\base.py", line 900, in _resolve_lookup
    current = current[int(bit)]
ValueError: invalid literal for int() with base 10: 'name'

During handling of the above exception, another exception occurred:

Traceback (most recent call last):
  File "D:\pydev\lp\marketsoft\ve_market\lib\site-packages\django\template\base.py", line 907, in _resolve_lookup
    (bit, current))  # missing attribute
django.template.base.VariableDoesNotExist: Failed lookup for key [name] in '<RegexURLResolver <RegexURLPattern list> (admin:admin) ^admin/>'
[2016-11-13 23:44:10] DEBUG [django.template:929] Exception while resolving variable 'name' in template 'unknown'.
Traceback (most recent call last):
  File "D:\pydev\lp\marketsoft\ve_market\lib\site-packages\django\core\handlers\exception.py", line 39, in inner
    response = get_response(request)
  File "D:\pydev\lp\marketsoft\ve_market\lib\site-packages\django\core\handlers\base.py", line 249, in _legacy_get_response
    response = self._get_response(request)
  File "D:\pydev\lp\marketsoft\ve_market\lib\site-packages\django\core\handlers\base.py", line 172, in _get_response
    resolver_match = resolver.resolve(request.path_info)
  File "D:\pydev\lp\marketsoft\ve_market\lib\site-packages\django\urls\resolvers.py", line 300, in resolve
    raise Resolver404({'tried': tried, 'path': new_path})
django.urls.exceptions.Resolver404: {'tried': [[<RegexURLResolver <RegexURLPattern list> (admin:admin) ^admin/>], [<RegexURLResolver <module 'django.contrib.admindocs.urls' from 'D:\\pydev\\lp\\marketsoft\\ve_market\\lib\\site-packages\\django\\contrib\\admindocs\\urls.py'> (None:None) ^admin/doc/>], [<RegexURLResolver <module 'rest_framework.urls' from 'D:\\pydev\\lp\\marketsoft\\ve_market\\lib\\site-packages\\rest_framework\\urls.py'> (rest_framework:rest_framework) ^api-auth/>], [<RegexURLResolver <module 'oauth2_provider.urls' from 'D:\\pydev\\lp\\marketsoft\\ve_market\\lib\\site-packages\\oauth2_provider\\urls.py'> (None:oauth2_provider) ^o/>], [<RegexURLResolver <module 'market_service_apps.auths_api.urls' from 'D:\\pydev\\lp\\marketsoft\\market_serve\\market_service_apps\\auths_api\\urls.py'> (None:None) ^api/auths/>], [<RegexURLResolver <module 'market_service_apps.registro_api.urls' from 'D:\\pydev\\lp\\marketsoft\\market_serve\\market_service_apps\\registro_api\\urls.py'> (None:None) ^api/registro/>]], 'path': ''}

During handling of the above exception, another exception occurred:

Traceback (most recent call last):
  File "D:\pydev\lp\marketsoft\ve_market\lib\site-packages\django\template\base.py", line 885, in _resolve_lookup
    current = current[bit]
TypeError: 'RegexURLResolver' object is not subscriptable

During handling of the above exception, another exception occurred:

Traceback (most recent call last):
  File "D:\pydev\lp\marketsoft\ve_market\lib\site-packages\django\template\base.py", line 893, in _resolve_lookup
    current = getattr(current, bit)
AttributeError: 'RegexURLResolver' object has no attribute 'name'

During handling of the above exception, another exception occurred:

Traceback (most recent call last):
  File "D:\pydev\lp\marketsoft\ve_market\lib\site-packages\django\template\base.py", line 900, in _resolve_lookup
    current = current[int(bit)]
ValueError: invalid literal for int() with base 10: 'name'

During handling of the above exception, another exception occurred:

Traceback (most recent call last):
  File "D:\pydev\lp\marketsoft\ve_market\lib\site-packages\django\template\base.py", line 907, in _resolve_lookup
    (bit, current))  # missing attribute
django.template.base.VariableDoesNotExist: Failed lookup for key [name] in "<RegexURLResolver <module 'django.contrib.admindocs.urls' from 'D:\\\\pydev\\\\lp\\\\marketsoft\\\\ve_market\\\\lib\\\\site-packages\\\\django\\\\contrib\\\\admindocs\\\\urls.py'> (None:None) ^admin/doc/>"
[2016-11-13 23:44:10] DEBUG [django.template:929] Exception while resolving variable 'name' in template 'unknown'.
Traceback (most recent call last):
  File "D:\pydev\lp\marketsoft\ve_market\lib\site-packages\django\core\handlers\exception.py", line 39, in inner
    response = get_response(request)
  File "D:\pydev\lp\marketsoft\ve_market\lib\site-packages\django\core\handlers\base.py", line 249, in _legacy_get_response
    response = self._get_response(request)
  File "D:\pydev\lp\marketsoft\ve_market\lib\site-packages\django\core\handlers\base.py", line 172, in _get_response
    resolver_match = resolver.resolve(request.path_info)
  File "D:\pydev\lp\marketsoft\ve_market\lib\site-packages\django\urls\resolvers.py", line 300, in resolve
    raise Resolver404({'tried': tried, 'path': new_path})
django.urls.exceptions.Resolver404: {'tried': [[<RegexURLResolver <RegexURLPattern list> (admin:admin) ^admin/>], [<RegexURLResolver <module 'django.contrib.admindocs.urls' from 'D:\\pydev\\lp\\marketsoft\\ve_market\\lib\\site-packages\\django\\contrib\\admindocs\\urls.py'> (None:None) ^admin/doc/>], [<RegexURLResolver <module 'rest_framework.urls' from 'D:\\pydev\\lp\\marketsoft\\ve_market\\lib\\site-packages\\rest_framework\\urls.py'> (rest_framework:rest_framework) ^api-auth/>], [<RegexURLResolver <module 'oauth2_provider.urls' from 'D:\\pydev\\lp\\marketsoft\\ve_market\\lib\\site-packages\\oauth2_provider\\urls.py'> (None:oauth2_provider) ^o/>], [<RegexURLResolver <module 'market_service_apps.auths_api.urls' from 'D:\\pydev\\lp\\marketsoft\\market_serve\\market_service_apps\\auths_api\\urls.py'> (None:None) ^api/auths/>], [<RegexURLResolver <module 'market_service_apps.registro_api.urls' from 'D:\\pydev\\lp\\marketsoft\\market_serve\\market_service_apps\\registro_api\\urls.py'> (None:None) ^api/registro/>]], 'path': ''}

During handling of the above exception, another exception occurred:

Traceback (most recent call last):
  File "D:\pydev\lp\marketsoft\ve_market\lib\site-packages\django\template\base.py", line 885, in _resolve_lookup
    current = current[bit]
TypeError: 'RegexURLResolver' object is not subscriptable

During handling of the above exception, another exception occurred:

Traceback (most recent call last):
  File "D:\pydev\lp\marketsoft\ve_market\lib\site-packages\django\template\base.py", line 893, in _resolve_lookup
    current = getattr(current, bit)
AttributeError: 'RegexURLResolver' object has no attribute 'name'

During handling of the above exception, another exception occurred:

Traceback (most recent call last):
  File "D:\pydev\lp\marketsoft\ve_market\lib\site-packages\django\template\base.py", line 900, in _resolve_lookup
    current = current[int(bit)]
ValueError: invalid literal for int() with base 10: 'name'

During handling of the above exception, another exception occurred:

Traceback (most recent call last):
  File "D:\pydev\lp\marketsoft\ve_market\lib\site-packages\django\template\base.py", line 907, in _resolve_lookup
    (bit, current))  # missing attribute
django.template.base.VariableDoesNotExist: Failed lookup for key [name] in "<RegexURLResolver <module 'rest_framework.urls' from 'D:\\\\pydev\\\\lp\\\\marketsoft\\\\ve_market\\\\lib\\\\site-packages\\\\rest_framework\\\\urls.py'> (rest_framework:rest_framework) ^api-auth/>"
[2016-11-13 23:44:10] DEBUG [django.template:929] Exception while resolving variable 'name' in template 'unknown'.
Traceback (most recent call last):
  File "D:\pydev\lp\marketsoft\ve_market\lib\site-packages\django\core\handlers\exception.py", line 39, in inner
    response = get_response(request)
  File "D:\pydev\lp\marketsoft\ve_market\lib\site-packages\django\core\handlers\base.py", line 249, in _legacy_get_response
    response = self._get_response(request)
  File "D:\pydev\lp\marketsoft\ve_market\lib\site-packages\django\core\handlers\base.py", line 172, in _get_response
    resolver_match = resolver.resolve(request.path_info)
  File "D:\pydev\lp\marketsoft\ve_market\lib\site-packages\django\urls\resolvers.py", line 300, in resolve
    raise Resolver404({'tried': tried, 'path': new_path})
django.urls.exceptions.Resolver404: {'tried': [[<RegexURLResolver <RegexURLPattern list> (admin:admin) ^admin/>], [<RegexURLResolver <module 'django.contrib.admindocs.urls' from 'D:\\pydev\\lp\\marketsoft\\ve_market\\lib\\site-packages\\django\\contrib\\admindocs\\urls.py'> (None:None) ^admin/doc/>], [<RegexURLResolver <module 'rest_framework.urls' from 'D:\\pydev\\lp\\marketsoft\\ve_market\\lib\\site-packages\\rest_framework\\urls.py'> (rest_framework:rest_framework) ^api-auth/>], [<RegexURLResolver <module 'oauth2_provider.urls' from 'D:\\pydev\\lp\\marketsoft\\ve_market\\lib\\site-packages\\oauth2_provider\\urls.py'> (None:oauth2_provider) ^o/>], [<RegexURLResolver <module 'market_service_apps.auths_api.urls' from 'D:\\pydev\\lp\\marketsoft\\market_serve\\market_service_apps\\auths_api\\urls.py'> (None:None) ^api/auths/>], [<RegexURLResolver <module 'market_service_apps.registro_api.urls' from 'D:\\pydev\\lp\\marketsoft\\market_serve\\market_service_apps\\registro_api\\urls.py'> (None:None) ^api/registro/>]], 'path': ''}

During handling of the above exception, another exception occurred:

Traceback (most recent call last):
  File "D:\pydev\lp\marketsoft\ve_market\lib\site-packages\django\template\base.py", line 885, in _resolve_lookup
    current = current[bit]
TypeError: 'RegexURLResolver' object is not subscriptable

During handling of the above exception, another exception occurred:

Traceback (most recent call last):
  File "D:\pydev\lp\marketsoft\ve_market\lib\site-packages\django\template\base.py", line 893, in _resolve_lookup
    current = getattr(current, bit)
AttributeError: 'RegexURLResolver' object has no attribute 'name'

During handling of the above exception, another exception occurred:

Traceback (most recent call last):
  File "D:\pydev\lp\marketsoft\ve_market\lib\site-packages\django\template\base.py", line 900, in _resolve_lookup
    current = current[int(bit)]
ValueError: invalid literal for int() with base 10: 'name'

During handling of the above exception, another exception occurred:

Traceback (most recent call last):
  File "D:\pydev\lp\marketsoft\ve_market\lib\site-packages\django\template\base.py", line 907, in _resolve_lookup
    (bit, current))  # missing attribute
django.template.base.VariableDoesNotExist: Failed lookup for key [name] in "<RegexURLResolver <module 'oauth2_provider.urls' from 'D:\\\\pydev\\\\lp\\\\marketsoft\\\\ve_market\\\\lib\\\\site-packages\\\\oauth2_provider\\\\urls.py'> (None:oauth2_provider) ^o/>"
[2016-11-13 23:44:10] DEBUG [django.template:929] Exception while resolving variable 'name' in template 'unknown'.
Traceback (most recent call last):
  File "D:\pydev\lp\marketsoft\ve_market\lib\site-packages\django\core\handlers\exception.py", line 39, in inner
    response = get_response(request)
  File "D:\pydev\lp\marketsoft\ve_market\lib\site-packages\django\core\handlers\base.py", line 249, in _legacy_get_response
    response = self._get_response(request)
  File "D:\pydev\lp\marketsoft\ve_market\lib\site-packages\django\core\handlers\base.py", line 172, in _get_response
    resolver_match = resolver.resolve(request.path_info)
  File "D:\pydev\lp\marketsoft\ve_market\lib\site-packages\django\urls\resolvers.py", line 300, in resolve
    raise Resolver404({'tried': tried, 'path': new_path})
django.urls.exceptions.Resolver404: {'tried': [[<RegexURLResolver <RegexURLPattern list> (admin:admin) ^admin/>], [<RegexURLResolver <module 'django.contrib.admindocs.urls' from 'D:\\pydev\\lp\\marketsoft\\ve_market\\lib\\site-packages\\django\\contrib\\admindocs\\urls.py'> (None:None) ^admin/doc/>], [<RegexURLResolver <module 'rest_framework.urls' from 'D:\\pydev\\lp\\marketsoft\\ve_market\\lib\\site-packages\\rest_framework\\urls.py'> (rest_framework:rest_framework) ^api-auth/>], [<RegexURLResolver <module 'oauth2_provider.urls' from 'D:\\pydev\\lp\\marketsoft\\ve_market\\lib\\site-packages\\oauth2_provider\\urls.py'> (None:oauth2_provider) ^o/>], [<RegexURLResolver <module 'market_service_apps.auths_api.urls' from 'D:\\pydev\\lp\\marketsoft\\market_serve\\market_service_apps\\auths_api\\urls.py'> (None:None) ^api/auths/>], [<RegexURLResolver <module 'market_service_apps.registro_api.urls' from 'D:\\pydev\\lp\\marketsoft\\market_serve\\market_service_apps\\registro_api\\urls.py'> (None:None) ^api/registro/>]], 'path': ''}

During handling of the above exception, another exception occurred:

Traceback (most recent call last):
  File "D:\pydev\lp\marketsoft\ve_market\lib\site-packages\django\template\base.py", line 885, in _resolve_lookup
    current = current[bit]
TypeError: 'RegexURLResolver' object is not subscriptable

During handling of the above exception, another exception occurred:

Traceback (most recent call last):
  File "D:\pydev\lp\marketsoft\ve_market\lib\site-packages\django\template\base.py", line 893, in _resolve_lookup
    current = getattr(current, bit)
AttributeError: 'RegexURLResolver' object has no attribute 'name'

During handling of the above exception, another exception occurred:

Traceback (most recent call last):
  File "D:\pydev\lp\marketsoft\ve_market\lib\site-packages\django\template\base.py", line 900, in _resolve_lookup
    current = current[int(bit)]
ValueError: invalid literal for int() with base 10: 'name'

During handling of the above exception, another exception occurred:

Traceback (most recent call last):
  File "D:\pydev\lp\marketsoft\ve_market\lib\site-packages\django\template\base.py", line 907, in _resolve_lookup
    (bit, current))  # missing attribute
django.template.base.VariableDoesNotExist: Failed lookup for key [name] in "<RegexURLResolver <module 'market_service_apps.auths_api.urls' from 'D:\\\\pydev\\\\lp\\\\marketsoft\\\\market_serve\\\\market_service_apps\\\\auths_api\\\\urls.py'> (None:None) ^api/auths/>"
[2016-11-13 23:44:10] DEBUG [django.template:929] Exception while resolving variable 'name' in template 'unknown'.
Traceback (most recent call last):
  File "D:\pydev\lp\marketsoft\ve_market\lib\site-packages\django\core\handlers\exception.py", line 39, in inner
    response = get_response(request)
  File "D:\pydev\lp\marketsoft\ve_market\lib\site-packages\django\core\handlers\base.py", line 249, in _legacy_get_response
    response = self._get_response(request)
  File "D:\pydev\lp\marketsoft\ve_market\lib\site-packages\django\core\handlers\base.py", line 172, in _get_response
    resolver_match = resolver.resolve(request.path_info)
  File "D:\pydev\lp\marketsoft\ve_market\lib\site-packages\django\urls\resolvers.py", line 300, in resolve
    raise Resolver404({'tried': tried, 'path': new_path})
django.urls.exceptions.Resolver404: {'tried': [[<RegexURLResolver <RegexURLPattern list> (admin:admin) ^admin/>], [<RegexURLResolver <module 'django.contrib.admindocs.urls' from 'D:\\pydev\\lp\\marketsoft\\ve_market\\lib\\site-packages\\django\\contrib\\admindocs\\urls.py'> (None:None) ^admin/doc/>], [<RegexURLResolver <module 'rest_framework.urls' from 'D:\\pydev\\lp\\marketsoft\\ve_market\\lib\\site-packages\\rest_framework\\urls.py'> (rest_framework:rest_framework) ^api-auth/>], [<RegexURLResolver <module 'oauth2_provider.urls' from 'D:\\pydev\\lp\\marketsoft\\ve_market\\lib\\site-packages\\oauth2_provider\\urls.py'> (None:oauth2_provider) ^o/>], [<RegexURLResolver <module 'market_service_apps.auths_api.urls' from 'D:\\pydev\\lp\\marketsoft\\market_serve\\market_service_apps\\auths_api\\urls.py'> (None:None) ^api/auths/>], [<RegexURLResolver <module 'market_service_apps.registro_api.urls' from 'D:\\pydev\\lp\\marketsoft\\market_serve\\market_service_apps\\registro_api\\urls.py'> (None:None) ^api/registro/>]], 'path': ''}

During handling of the above exception, another exception occurred:

Traceback (most recent call last):
  File "D:\pydev\lp\marketsoft\ve_market\lib\site-packages\django\template\base.py", line 885, in _resolve_lookup
    current = current[bit]
TypeError: 'RegexURLResolver' object is not subscriptable

During handling of the above exception, another exception occurred:

Traceback (most recent call last):
  File "D:\pydev\lp\marketsoft\ve_market\lib\site-packages\django\template\base.py", line 893, in _resolve_lookup
    current = getattr(current, bit)
AttributeError: 'RegexURLResolver' object has no attribute 'name'

During handling of the above exception, another exception occurred:

Traceback (most recent call last):
  File "D:\pydev\lp\marketsoft\ve_market\lib\site-packages\django\template\base.py", line 900, in _resolve_lookup
    current = current[int(bit)]
ValueError: invalid literal for int() with base 10: 'name'

During handling of the above exception, another exception occurred:

Traceback (most recent call last):
  File "D:\pydev\lp\marketsoft\ve_market\lib\site-packages\django\template\base.py", line 907, in _resolve_lookup
    (bit, current))  # missing attribute
django.template.base.VariableDoesNotExist: Failed lookup for key [name] in "<RegexURLResolver <module 'market_service_apps.registro_api.urls' from 'D:\\\\pydev\\\\lp\\\\marketsoft\\\\market_serve\\\\market_service_apps\\\\registro_api\\\\urls.py'> (None:None) ^api/registro/>"
[2016-11-13 23:44:10] WARNING [django.request:152] Not Found: /
[2016-11-13 23:44:10] WARNING [django.server:131] "GET / HTTP/1.1" 404 2457
[2016-11-13 23:44:10] DEBUG [django.template:929] Exception while resolving variable 'name' in template 'unknown'.
Traceback (most recent call last):
  File "D:\pydev\lp\marketsoft\ve_market\lib\site-packages\django\core\handlers\exception.py", line 39, in inner
    response = get_response(request)
  File "D:\pydev\lp\marketsoft\ve_market\lib\site-packages\django\core\handlers\base.py", line 249, in _legacy_get_response
    response = self._get_response(request)
  File "D:\pydev\lp\marketsoft\ve_market\lib\site-packages\django\core\handlers\base.py", line 172, in _get_response
    resolver_match = resolver.resolve(request.path_info)
  File "D:\pydev\lp\marketsoft\ve_market\lib\site-packages\django\urls\resolvers.py", line 300, in resolve
    raise Resolver404({'tried': tried, 'path': new_path})
django.urls.exceptions.Resolver404: {'tried': [[<RegexURLResolver <RegexURLPattern list> (admin:admin) ^admin/>], [<RegexURLResolver <module 'django.contrib.admindocs.urls' from 'D:\\pydev\\lp\\marketsoft\\ve_market\\lib\\site-packages\\django\\contrib\\admindocs\\urls.py'> (None:None) ^admin/doc/>], [<RegexURLResolver <module 'rest_framework.urls' from 'D:\\pydev\\lp\\marketsoft\\ve_market\\lib\\site-packages\\rest_framework\\urls.py'> (rest_framework:rest_framework) ^api-auth/>], [<RegexURLResolver <module 'oauth2_provider.urls' from 'D:\\pydev\\lp\\marketsoft\\ve_market\\lib\\site-packages\\oauth2_provider\\urls.py'> (None:oauth2_provider) ^o/>], [<RegexURLResolver <module 'market_service_apps.auths_api.urls' from 'D:\\pydev\\lp\\marketsoft\\market_serve\\market_service_apps\\auths_api\\urls.py'> (None:None) ^api/auths/>], [<RegexURLResolver <module 'market_service_apps.registro_api.urls' from 'D:\\pydev\\lp\\marketsoft\\market_serve\\market_service_apps\\registro_api\\urls.py'> (None:None) ^api/registro/>]], 'path': 'favicon.ico'}

During handling of the above exception, another exception occurred:

Traceback (most recent call last):
  File "D:\pydev\lp\marketsoft\ve_market\lib\site-packages\django\template\base.py", line 885, in _resolve_lookup
    current = current[bit]
TypeError: 'RegexURLResolver' object is not subscriptable

During handling of the above exception, another exception occurred:

Traceback (most recent call last):
  File "D:\pydev\lp\marketsoft\ve_market\lib\site-packages\django\template\base.py", line 893, in _resolve_lookup
    current = getattr(current, bit)
AttributeError: 'RegexURLResolver' object has no attribute 'name'

During handling of the above exception, another exception occurred:

Traceback (most recent call last):
  File "D:\pydev\lp\marketsoft\ve_market\lib\site-packages\django\template\base.py", line 900, in _resolve_lookup
    current = current[int(bit)]
ValueError: invalid literal for int() with base 10: 'name'

During handling of the above exception, another exception occurred:

Traceback (most recent call last):
  File "D:\pydev\lp\marketsoft\ve_market\lib\site-packages\django\template\base.py", line 907, in _resolve_lookup
    (bit, current))  # missing attribute
django.template.base.VariableDoesNotExist: Failed lookup for key [name] in '<RegexURLResolver <RegexURLPattern list> (admin:admin) ^admin/>'
[2016-11-13 23:44:10] DEBUG [django.template:929] Exception while resolving variable 'name' in template 'unknown'.
Traceback (most recent call last):
  File "D:\pydev\lp\marketsoft\ve_market\lib\site-packages\django\core\handlers\exception.py", line 39, in inner
    response = get_response(request)
  File "D:\pydev\lp\marketsoft\ve_market\lib\site-packages\django\core\handlers\base.py", line 249, in _legacy_get_response
    response = self._get_response(request)
  File "D:\pydev\lp\marketsoft\ve_market\lib\site-packages\django\core\handlers\base.py", line 172, in _get_response
    resolver_match = resolver.resolve(request.path_info)
  File "D:\pydev\lp\marketsoft\ve_market\lib\site-packages\django\urls\resolvers.py", line 300, in resolve
    raise Resolver404({'tried': tried, 'path': new_path})
django.urls.exceptions.Resolver404: {'tried': [[<RegexURLResolver <RegexURLPattern list> (admin:admin) ^admin/>], [<RegexURLResolver <module 'django.contrib.admindocs.urls' from 'D:\\pydev\\lp\\marketsoft\\ve_market\\lib\\site-packages\\django\\contrib\\admindocs\\urls.py'> (None:None) ^admin/doc/>], [<RegexURLResolver <module 'rest_framework.urls' from 'D:\\pydev\\lp\\marketsoft\\ve_market\\lib\\site-packages\\rest_framework\\urls.py'> (rest_framework:rest_framework) ^api-auth/>], [<RegexURLResolver <module 'oauth2_provider.urls' from 'D:\\pydev\\lp\\marketsoft\\ve_market\\lib\\site-packages\\oauth2_provider\\urls.py'> (None:oauth2_provider) ^o/>], [<RegexURLResolver <module 'market_service_apps.auths_api.urls' from 'D:\\pydev\\lp\\marketsoft\\market_serve\\market_service_apps\\auths_api\\urls.py'> (None:None) ^api/auths/>], [<RegexURLResolver <module 'market_service_apps.registro_api.urls' from 'D:\\pydev\\lp\\marketsoft\\market_serve\\market_service_apps\\registro_api\\urls.py'> (None:None) ^api/registro/>]], 'path': 'favicon.ico'}

During handling of the above exception, another exception occurred:

Traceback (most recent call last):
  File "D:\pydev\lp\marketsoft\ve_market\lib\site-packages\django\template\base.py", line 885, in _resolve_lookup
    current = current[bit]
TypeError: 'RegexURLResolver' object is not subscriptable

During handling of the above exception, another exception occurred:

Traceback (most recent call last):
  File "D:\pydev\lp\marketsoft\ve_market\lib\site-packages\django\template\base.py", line 893, in _resolve_lookup
    current = getattr(current, bit)
AttributeError: 'RegexURLResolver' object has no attribute 'name'

During handling of the above exception, another exception occurred:

Traceback (most recent call last):
  File "D:\pydev\lp\marketsoft\ve_market\lib\site-packages\django\template\base.py", line 900, in _resolve_lookup
    current = current[int(bit)]
ValueError: invalid literal for int() with base 10: 'name'

During handling of the above exception, another exception occurred:

Traceback (most recent call last):
  File "D:\pydev\lp\marketsoft\ve_market\lib\site-packages\django\template\base.py", line 907, in _resolve_lookup
    (bit, current))  # missing attribute
django.template.base.VariableDoesNotExist: Failed lookup for key [name] in "<RegexURLResolver <module 'django.contrib.admindocs.urls' from 'D:\\\\pydev\\\\lp\\\\marketsoft\\\\ve_market\\\\lib\\\\site-packages\\\\django\\\\contrib\\\\admindocs\\\\urls.py'> (None:None) ^admin/doc/>"
[2016-11-13 23:44:10] DEBUG [django.template:929] Exception while resolving variable 'name' in template 'unknown'.
Traceback (most recent call last):
  File "D:\pydev\lp\marketsoft\ve_market\lib\site-packages\django\core\handlers\exception.py", line 39, in inner
    response = get_response(request)
  File "D:\pydev\lp\marketsoft\ve_market\lib\site-packages\django\core\handlers\base.py", line 249, in _legacy_get_response
    response = self._get_response(request)
  File "D:\pydev\lp\marketsoft\ve_market\lib\site-packages\django\core\handlers\base.py", line 172, in _get_response
    resolver_match = resolver.resolve(request.path_info)
  File "D:\pydev\lp\marketsoft\ve_market\lib\site-packages\django\urls\resolvers.py", line 300, in resolve
    raise Resolver404({'tried': tried, 'path': new_path})
django.urls.exceptions.Resolver404: {'tried': [[<RegexURLResolver <RegexURLPattern list> (admin:admin) ^admin/>], [<RegexURLResolver <module 'django.contrib.admindocs.urls' from 'D:\\pydev\\lp\\marketsoft\\ve_market\\lib\\site-packages\\django\\contrib\\admindocs\\urls.py'> (None:None) ^admin/doc/>], [<RegexURLResolver <module 'rest_framework.urls' from 'D:\\pydev\\lp\\marketsoft\\ve_market\\lib\\site-packages\\rest_framework\\urls.py'> (rest_framework:rest_framework) ^api-auth/>], [<RegexURLResolver <module 'oauth2_provider.urls' from 'D:\\pydev\\lp\\marketsoft\\ve_market\\lib\\site-packages\\oauth2_provider\\urls.py'> (None:oauth2_provider) ^o/>], [<RegexURLResolver <module 'market_service_apps.auths_api.urls' from 'D:\\pydev\\lp\\marketsoft\\market_serve\\market_service_apps\\auths_api\\urls.py'> (None:None) ^api/auths/>], [<RegexURLResolver <module 'market_service_apps.registro_api.urls' from 'D:\\pydev\\lp\\marketsoft\\market_serve\\market_service_apps\\registro_api\\urls.py'> (None:None) ^api/registro/>]], 'path': 'favicon.ico'}

During handling of the above exception, another exception occurred:

Traceback (most recent call last):
  File "D:\pydev\lp\marketsoft\ve_market\lib\site-packages\django\template\base.py", line 885, in _resolve_lookup
    current = current[bit]
TypeError: 'RegexURLResolver' object is not subscriptable

During handling of the above exception, another exception occurred:

Traceback (most recent call last):
  File "D:\pydev\lp\marketsoft\ve_market\lib\site-packages\django\template\base.py", line 893, in _resolve_lookup
    current = getattr(current, bit)
AttributeError: 'RegexURLResolver' object has no attribute 'name'

During handling of the above exception, another exception occurred:

Traceback (most recent call last):
  File "D:\pydev\lp\marketsoft\ve_market\lib\site-packages\django\template\base.py", line 900, in _resolve_lookup
    current = current[int(bit)]
ValueError: invalid literal for int() with base 10: 'name'

During handling of the above exception, another exception occurred:

Traceback (most recent call last):
  File "D:\pydev\lp\marketsoft\ve_market\lib\site-packages\django\template\base.py", line 907, in _resolve_lookup
    (bit, current))  # missing attribute
django.template.base.VariableDoesNotExist: Failed lookup for key [name] in "<RegexURLResolver <module 'rest_framework.urls' from 'D:\\\\pydev\\\\lp\\\\marketsoft\\\\ve_market\\\\lib\\\\site-packages\\\\rest_framework\\\\urls.py'> (rest_framework:rest_framework) ^api-auth/>"
[2016-11-13 23:44:10] DEBUG [django.template:929] Exception while resolving variable 'name' in template 'unknown'.
Traceback (most recent call last):
  File "D:\pydev\lp\marketsoft\ve_market\lib\site-packages\django\core\handlers\exception.py", line 39, in inner
    response = get_response(request)
  File "D:\pydev\lp\marketsoft\ve_market\lib\site-packages\django\core\handlers\base.py", line 249, in _legacy_get_response
    response = self._get_response(request)
  File "D:\pydev\lp\marketsoft\ve_market\lib\site-packages\django\core\handlers\base.py", line 172, in _get_response
    resolver_match = resolver.resolve(request.path_info)
  File "D:\pydev\lp\marketsoft\ve_market\lib\site-packages\django\urls\resolvers.py", line 300, in resolve
    raise Resolver404({'tried': tried, 'path': new_path})
django.urls.exceptions.Resolver404: {'tried': [[<RegexURLResolver <RegexURLPattern list> (admin:admin) ^admin/>], [<RegexURLResolver <module 'django.contrib.admindocs.urls' from 'D:\\pydev\\lp\\marketsoft\\ve_market\\lib\\site-packages\\django\\contrib\\admindocs\\urls.py'> (None:None) ^admin/doc/>], [<RegexURLResolver <module 'rest_framework.urls' from 'D:\\pydev\\lp\\marketsoft\\ve_market\\lib\\site-packages\\rest_framework\\urls.py'> (rest_framework:rest_framework) ^api-auth/>], [<RegexURLResolver <module 'oauth2_provider.urls' from 'D:\\pydev\\lp\\marketsoft\\ve_market\\lib\\site-packages\\oauth2_provider\\urls.py'> (None:oauth2_provider) ^o/>], [<RegexURLResolver <module 'market_service_apps.auths_api.urls' from 'D:\\pydev\\lp\\marketsoft\\market_serve\\market_service_apps\\auths_api\\urls.py'> (None:None) ^api/auths/>], [<RegexURLResolver <module 'market_service_apps.registro_api.urls' from 'D:\\pydev\\lp\\marketsoft\\market_serve\\market_service_apps\\registro_api\\urls.py'> (None:None) ^api/registro/>]], 'path': 'favicon.ico'}

During handling of the above exception, another exception occurred:

Traceback (most recent call last):
  File "D:\pydev\lp\marketsoft\ve_market\lib\site-packages\django\template\base.py", line 885, in _resolve_lookup
    current = current[bit]
TypeError: 'RegexURLResolver' object is not subscriptable

During handling of the above exception, another exception occurred:

Traceback (most recent call last):
  File "D:\pydev\lp\marketsoft\ve_market\lib\site-packages\django\template\base.py", line 893, in _resolve_lookup
    current = getattr(current, bit)
AttributeError: 'RegexURLResolver' object has no attribute 'name'

During handling of the above exception, another exception occurred:

Traceback (most recent call last):
  File "D:\pydev\lp\marketsoft\ve_market\lib\site-packages\django\template\base.py", line 900, in _resolve_lookup
    current = current[int(bit)]
ValueError: invalid literal for int() with base 10: 'name'

During handling of the above exception, another exception occurred:

Traceback (most recent call last):
  File "D:\pydev\lp\marketsoft\ve_market\lib\site-packages\django\template\base.py", line 907, in _resolve_lookup
    (bit, current))  # missing attribute
django.template.base.VariableDoesNotExist: Failed lookup for key [name] in "<RegexURLResolver <module 'oauth2_provider.urls' from 'D:\\\\pydev\\\\lp\\\\marketsoft\\\\ve_market\\\\lib\\\\site-packages\\\\oauth2_provider\\\\urls.py'> (None:oauth2_provider) ^o/>"
[2016-11-13 23:44:10] DEBUG [django.template:929] Exception while resolving variable 'name' in template 'unknown'.
Traceback (most recent call last):
  File "D:\pydev\lp\marketsoft\ve_market\lib\site-packages\django\core\handlers\exception.py", line 39, in inner
    response = get_response(request)
  File "D:\pydev\lp\marketsoft\ve_market\lib\site-packages\django\core\handlers\base.py", line 249, in _legacy_get_response
    response = self._get_response(request)
  File "D:\pydev\lp\marketsoft\ve_market\lib\site-packages\django\core\handlers\base.py", line 172, in _get_response
    resolver_match = resolver.resolve(request.path_info)
  File "D:\pydev\lp\marketsoft\ve_market\lib\site-packages\django\urls\resolvers.py", line 300, in resolve
    raise Resolver404({'tried': tried, 'path': new_path})
django.urls.exceptions.Resolver404: {'tried': [[<RegexURLResolver <RegexURLPattern list> (admin:admin) ^admin/>], [<RegexURLResolver <module 'django.contrib.admindocs.urls' from 'D:\\pydev\\lp\\marketsoft\\ve_market\\lib\\site-packages\\django\\contrib\\admindocs\\urls.py'> (None:None) ^admin/doc/>], [<RegexURLResolver <module 'rest_framework.urls' from 'D:\\pydev\\lp\\marketsoft\\ve_market\\lib\\site-packages\\rest_framework\\urls.py'> (rest_framework:rest_framework) ^api-auth/>], [<RegexURLResolver <module 'oauth2_provider.urls' from 'D:\\pydev\\lp\\marketsoft\\ve_market\\lib\\site-packages\\oauth2_provider\\urls.py'> (None:oauth2_provider) ^o/>], [<RegexURLResolver <module 'market_service_apps.auths_api.urls' from 'D:\\pydev\\lp\\marketsoft\\market_serve\\market_service_apps\\auths_api\\urls.py'> (None:None) ^api/auths/>], [<RegexURLResolver <module 'market_service_apps.registro_api.urls' from 'D:\\pydev\\lp\\marketsoft\\market_serve\\market_service_apps\\registro_api\\urls.py'> (None:None) ^api/registro/>]], 'path': 'favicon.ico'}

During handling of the above exception, another exception occurred:

Traceback (most recent call last):
  File "D:\pydev\lp\marketsoft\ve_market\lib\site-packages\django\template\base.py", line 885, in _resolve_lookup
    current = current[bit]
TypeError: 'RegexURLResolver' object is not subscriptable

During handling of the above exception, another exception occurred:

Traceback (most recent call last):
  File "D:\pydev\lp\marketsoft\ve_market\lib\site-packages\django\template\base.py", line 893, in _resolve_lookup
    current = getattr(current, bit)
AttributeError: 'RegexURLResolver' object has no attribute 'name'

During handling of the above exception, another exception occurred:

Traceback (most recent call last):
  File "D:\pydev\lp\marketsoft\ve_market\lib\site-packages\django\template\base.py", line 900, in _resolve_lookup
    current = current[int(bit)]
ValueError: invalid literal for int() with base 10: 'name'

During handling of the above exception, another exception occurred:

Traceback (most recent call last):
  File "D:\pydev\lp\marketsoft\ve_market\lib\site-packages\django\template\base.py", line 907, in _resolve_lookup
    (bit, current))  # missing attribute
django.template.base.VariableDoesNotExist: Failed lookup for key [name] in "<RegexURLResolver <module 'market_service_apps.auths_api.urls' from 'D:\\\\pydev\\\\lp\\\\marketsoft\\\\market_serve\\\\market_service_apps\\\\auths_api\\\\urls.py'> (None:None) ^api/auths/>"
[2016-11-13 23:44:10] DEBUG [django.template:929] Exception while resolving variable 'name' in template 'unknown'.
Traceback (most recent call last):
  File "D:\pydev\lp\marketsoft\ve_market\lib\site-packages\django\core\handlers\exception.py", line 39, in inner
    response = get_response(request)
  File "D:\pydev\lp\marketsoft\ve_market\lib\site-packages\django\core\handlers\base.py", line 249, in _legacy_get_response
    response = self._get_response(request)
  File "D:\pydev\lp\marketsoft\ve_market\lib\site-packages\django\core\handlers\base.py", line 172, in _get_response
    resolver_match = resolver.resolve(request.path_info)
  File "D:\pydev\lp\marketsoft\ve_market\lib\site-packages\django\urls\resolvers.py", line 300, in resolve
    raise Resolver404({'tried': tried, 'path': new_path})
django.urls.exceptions.Resolver404: {'tried': [[<RegexURLResolver <RegexURLPattern list> (admin:admin) ^admin/>], [<RegexURLResolver <module 'django.contrib.admindocs.urls' from 'D:\\pydev\\lp\\marketsoft\\ve_market\\lib\\site-packages\\django\\contrib\\admindocs\\urls.py'> (None:None) ^admin/doc/>], [<RegexURLResolver <module 'rest_framework.urls' from 'D:\\pydev\\lp\\marketsoft\\ve_market\\lib\\site-packages\\rest_framework\\urls.py'> (rest_framework:rest_framework) ^api-auth/>], [<RegexURLResolver <module 'oauth2_provider.urls' from 'D:\\pydev\\lp\\marketsoft\\ve_market\\lib\\site-packages\\oauth2_provider\\urls.py'> (None:oauth2_provider) ^o/>], [<RegexURLResolver <module 'market_service_apps.auths_api.urls' from 'D:\\pydev\\lp\\marketsoft\\market_serve\\market_service_apps\\auths_api\\urls.py'> (None:None) ^api/auths/>], [<RegexURLResolver <module 'market_service_apps.registro_api.urls' from 'D:\\pydev\\lp\\marketsoft\\market_serve\\market_service_apps\\registro_api\\urls.py'> (None:None) ^api/registro/>]], 'path': 'favicon.ico'}

During handling of the above exception, another exception occurred:

Traceback (most recent call last):
  File "D:\pydev\lp\marketsoft\ve_market\lib\site-packages\django\template\base.py", line 885, in _resolve_lookup
    current = current[bit]
TypeError: 'RegexURLResolver' object is not subscriptable

During handling of the above exception, another exception occurred:

Traceback (most recent call last):
  File "D:\pydev\lp\marketsoft\ve_market\lib\site-packages\django\template\base.py", line 893, in _resolve_lookup
    current = getattr(current, bit)
AttributeError: 'RegexURLResolver' object has no attribute 'name'

During handling of the above exception, another exception occurred:

Traceback (most recent call last):
  File "D:\pydev\lp\marketsoft\ve_market\lib\site-packages\django\template\base.py", line 900, in _resolve_lookup
    current = current[int(bit)]
ValueError: invalid literal for int() with base 10: 'name'

During handling of the above exception, another exception occurred:

Traceback (most recent call last):
  File "D:\pydev\lp\marketsoft\ve_market\lib\site-packages\django\template\base.py", line 907, in _resolve_lookup
    (bit, current))  # missing attribute
django.template.base.VariableDoesNotExist: Failed lookup for key [name] in "<RegexURLResolver <module 'market_service_apps.registro_api.urls' from 'D:\\\\pydev\\\\lp\\\\marketsoft\\\\market_serve\\\\market_service_apps\\\\registro_api\\\\urls.py'> (None:None) ^api/registro/>"
[2016-11-13 23:44:10] WARNING [django.request:152] Not Found: /favicon.ico
[2016-11-13 23:44:10] WARNING [django.server:131] "GET /favicon.ico HTTP/1.1" 404 2490
[2016-11-13 23:44:13] DEBUG [django.db.backends:90] (0.002) SELECT "auths_menu"."router_json" FROM "auths_menu" ORDER BY "auths_menu"."pos" ASC; args=()
[2016-11-13 23:44:13] INFO [django.server:131] "GET /api/auths/routers/ HTTP/1.1" 200 2
[2016-11-13 23:44:23] DEBUG [django.db.backends:90] (0.001) SELECT "oauth2_provider_application"."id", "oauth2_provider_application"."client_id", "oauth2_provider_application"."user_id", "oauth2_provider_application"."redirect_uris", "oauth2_provider_application"."client_type", "oauth2_provider_application"."authorization_grant_type", "oauth2_provider_application"."client_secret", "oauth2_provider_application"."name", "oauth2_provider_application"."skip_authorization" FROM "oauth2_provider_application" WHERE "oauth2_provider_application"."client_id" = 'bt3DF5yKjdIawl6nGPiHl0C0V1NkDYSDSU9Eq8U3'; args=('bt3DF5yKjdIawl6nGPiHl0C0V1NkDYSDSU9Eq8U3',)
[2016-11-13 23:44:23] DEBUG [django.db.backends:90] (0.000) SELECT "auths_user"."password", "auths_user"."last_login", "auths_user"."is_superuser", "auths_user"."username", "auths_user"."first_name", "auths_user"."last_name", "auths_user"."email", "auths_user"."is_staff", "auths_user"."is_active", "auths_user"."date_joined", "auths_user"."id", "auths_user"."last_hierarchy_id", "auths_user"."last_module_id", "auths_user"."person_id", "auths_user"."updated_at", "auths_user"."registered_by" FROM "auths_user" WHERE "auths_user"."username" = 'admin'; args=('admin',)
[2016-11-13 23:44:23] DEBUG [django.db.backends:90] (0.000) BEGIN; args=None
[2016-11-13 23:44:23] DEBUG [django.db.backends:90] (0.002) INSERT INTO "oauth2_provider_accesstoken" ("user_id", "token", "application_id", "expires", "scope") VALUES ('9b1f3f3e83664b418357b0197f40ee24', '8pMmDmJa2KNSPMYKUll6FEFE1HOUFR', 1, '2016-11-14 14:44:23.248582', 'write read'); args=['9b1f3f3e83664b418357b0197f40ee24', '8pMmDmJa2KNSPMYKUll6FEFE1HOUFR', 1, '2016-11-14 14:44:23.248582', 'write read']
[2016-11-13 23:44:23] DEBUG [django.db.backends:90] (0.000) BEGIN; args=None
[2016-11-13 23:44:23] DEBUG [django.db.backends:90] (0.001) INSERT INTO "oauth2_provider_refreshtoken" ("user_id", "token", "application_id", "access_token_id") VALUES ('9b1f3f3e83664b418357b0197f40ee24', 'g4L43fAHC7A3uKlPY9Teo0a9s0E0rJ', 1, 2); args=['9b1f3f3e83664b418357b0197f40ee24', 'g4L43fAHC7A3uKlPY9Teo0a9s0E0rJ', 1, 2]
[2016-11-13 23:44:23] INFO [django.server:131] "POST /o/token/ HTTP/1.1" 200 169
[2016-11-13 23:44:25] INFO [django.server:131] "OPTIONS /api/auths/localuserinfo/ HTTP/1.1" 200 0
[2016-11-13 23:44:25] DEBUG [django.db.backends:90] (0.002) SELECT "oauth2_provider_accesstoken"."id", "oauth2_provider_accesstoken"."user_id", "oauth2_provider_accesstoken"."token", "oauth2_provider_accesstoken"."application_id", "oauth2_provider_accesstoken"."expires", "oauth2_provider_accesstoken"."scope", "auths_user"."password", "auths_user"."last_login", "auths_user"."is_superuser", "auths_user"."username", "auths_user"."first_name", "auths_user"."last_name", "auths_user"."email", "auths_user"."is_staff", "auths_user"."is_active", "auths_user"."date_joined", "auths_user"."id", "auths_user"."last_hierarchy_id", "auths_user"."last_module_id", "auths_user"."person_id", "auths_user"."updated_at", "auths_user"."registered_by", "oauth2_provider_application"."id", "oauth2_provider_application"."client_id", "oauth2_provider_application"."user_id", "oauth2_provider_application"."redirect_uris", "oauth2_provider_application"."client_type", "oauth2_provider_application"."authorization_grant_type", "oauth2_provider_application"."client_secret", "oauth2_provider_application"."name", "oauth2_provider_application"."skip_authorization" FROM "oauth2_provider_accesstoken" LEFT OUTER JOIN "auths_user" ON ("oauth2_provider_accesstoken"."user_id" = "auths_user"."id") INNER JOIN "oauth2_provider_application" ON ("oauth2_provider_accesstoken"."application_id" = "oauth2_provider_application"."id") WHERE "oauth2_provider_accesstoken"."token" = '8pMmDmJa2KNSPMYKUll6FEFE1HOUFR'; args=('8pMmDmJa2KNSPMYKUll6FEFE1HOUFR',)
[2016-11-13 23:44:25] DEBUG [django.db.backends:90] (0.001) SELECT "oauth2_provider_accesstoken"."id", "oauth2_provider_accesstoken"."user_id", "oauth2_provider_accesstoken"."token", "oauth2_provider_accesstoken"."application_id", "oauth2_provider_accesstoken"."expires", "oauth2_provider_accesstoken"."scope", "auths_user"."password", "auths_user"."last_login", "auths_user"."is_superuser", "auths_user"."username", "auths_user"."first_name", "auths_user"."last_name", "auths_user"."email", "auths_user"."is_staff", "auths_user"."is_active", "auths_user"."date_joined", "auths_user"."id", "auths_user"."last_hierarchy_id", "auths_user"."last_module_id", "auths_user"."person_id", "auths_user"."updated_at", "auths_user"."registered_by", "oauth2_provider_application"."id", "oauth2_provider_application"."client_id", "oauth2_provider_application"."user_id", "oauth2_provider_application"."redirect_uris", "oauth2_provider_application"."client_type", "oauth2_provider_application"."authorization_grant_type", "oauth2_provider_application"."client_secret", "oauth2_provider_application"."name", "oauth2_provider_application"."skip_authorization" FROM "oauth2_provider_accesstoken" LEFT OUTER JOIN "auths_user" ON ("oauth2_provider_accesstoken"."user_id" = "auths_user"."id") INNER JOIN "oauth2_provider_application" ON ("oauth2_provider_accesstoken"."application_id" = "oauth2_provider_application"."id") WHERE "oauth2_provider_accesstoken"."token" = '8pMmDmJa2KNSPMYKUll6FEFE1HOUFR'; args=('8pMmDmJa2KNSPMYKUll6FEFE1HOUFR',)
[2016-11-13 23:44:25] INFO [django.server:131] "OPTIONS /api/auths/usermenu/ HTTP/1.1" 200 0
[2016-11-13 23:44:25] DEBUG [django.db.backends:90] (0.002) SELECT "auth_group"."id", "auth_group"."name" FROM "auth_group" INNER JOIN "auths_user_groups" ON ("auth_group"."id" = "auths_user_groups"."group_id") WHERE "auths_user_groups"."user_id" = '9b1f3f3e83664b418357b0197f40ee24'; args=('9b1f3f3e83664b418357b0197f40ee24',)
[2016-11-13 23:44:25] DEBUG [django.db.backends:90] (0.000) SELECT "auth_permission"."id", "auth_permission"."name", "auth_permission"."content_type_id", "auth_permission"."codename" FROM "auth_permission" INNER JOIN "auths_user_user_permissions" ON ("auth_permission"."id" = "auths_user_user_permissions"."permission_id") INNER JOIN "django_content_type" ON ("auth_permission"."content_type_id" = "django_content_type"."id") WHERE "auths_user_user_permissions"."user_id" = '9b1f3f3e83664b418357b0197f40ee24' ORDER BY "django_content_type"."app_label" ASC, "django_content_type"."model" ASC, "auth_permission"."codename" ASC; args=('9b1f3f3e83664b418357b0197f40ee24',)
[2016-11-13 23:44:25] INFO [django.server:131] "GET /api/auths/localuserinfo/ HTTP/1.1" 200 405
[2016-11-13 23:44:25] DEBUG [django.db.backends:90] (0.002) SELECT "oauth2_provider_accesstoken"."id", "oauth2_provider_accesstoken"."user_id", "oauth2_provider_accesstoken"."token", "oauth2_provider_accesstoken"."application_id", "oauth2_provider_accesstoken"."expires", "oauth2_provider_accesstoken"."scope", "auths_user"."password", "auths_user"."last_login", "auths_user"."is_superuser", "auths_user"."username", "auths_user"."first_name", "auths_user"."last_name", "auths_user"."email", "auths_user"."is_staff", "auths_user"."is_active", "auths_user"."date_joined", "auths_user"."id", "auths_user"."last_hierarchy_id", "auths_user"."last_module_id", "auths_user"."person_id", "auths_user"."updated_at", "auths_user"."registered_by", "oauth2_provider_application"."id", "oauth2_provider_application"."client_id", "oauth2_provider_application"."user_id", "oauth2_provider_application"."redirect_uris", "oauth2_provider_application"."client_type", "oauth2_provider_application"."authorization_grant_type", "oauth2_provider_application"."client_secret", "oauth2_provider_application"."name", "oauth2_provider_application"."skip_authorization" FROM "oauth2_provider_accesstoken" LEFT OUTER JOIN "auths_user" ON ("oauth2_provider_accesstoken"."user_id" = "auths_user"."id") INNER JOIN "oauth2_provider_application" ON ("oauth2_provider_accesstoken"."application_id" = "oauth2_provider_application"."id") WHERE "oauth2_provider_accesstoken"."token" = '8pMmDmJa2KNSPMYKUll6FEFE1HOUFR'; args=('8pMmDmJa2KNSPMYKUll6FEFE1HOUFR',)
[2016-11-13 23:44:25] DEBUG [django.db.backends:90] (0.001) SELECT "oauth2_provider_accesstoken"."id", "oauth2_provider_accesstoken"."user_id", "oauth2_provider_accesstoken"."token", "oauth2_provider_accesstoken"."application_id", "oauth2_provider_accesstoken"."expires", "oauth2_provider_accesstoken"."scope", "auths_user"."password", "auths_user"."last_login", "auths_user"."is_superuser", "auths_user"."username", "auths_user"."first_name", "auths_user"."last_name", "auths_user"."email", "auths_user"."is_staff", "auths_user"."is_active", "auths_user"."date_joined", "auths_user"."id", "auths_user"."last_hierarchy_id", "auths_user"."last_module_id", "auths_user"."person_id", "auths_user"."updated_at", "auths_user"."registered_by", "oauth2_provider_application"."id", "oauth2_provider_application"."client_id", "oauth2_provider_application"."user_id", "oauth2_provider_application"."redirect_uris", "oauth2_provider_application"."client_type", "oauth2_provider_application"."authorization_grant_type", "oauth2_provider_application"."client_secret", "oauth2_provider_application"."name", "oauth2_provider_application"."skip_authorization" FROM "oauth2_provider_accesstoken" LEFT OUTER JOIN "auths_user" ON ("oauth2_provider_accesstoken"."user_id" = "auths_user"."id") INNER JOIN "oauth2_provider_application" ON ("oauth2_provider_accesstoken"."application_id" = "oauth2_provider_application"."id") WHERE "oauth2_provider_accesstoken"."token" = '8pMmDmJa2KNSPMYKUll6FEFE1HOUFR'; args=('8pMmDmJa2KNSPMYKUll6FEFE1HOUFR',)
[2016-11-13 23:44:25] DEBUG [django.db.backends:90] (0.000) SELECT "auths_menu"."id" FROM "auths_menu" WHERE ("auths_menu"."id" IS NOT NULL AND "auths_menu"."module" = 'BACKEND' AND "auths_menu"."is_active" = 1) ORDER BY "auths_menu"."pos" ASC; args=('BACKEND', True)
[2016-11-13 23:44:25] DEBUG [django.db.backends:90] (0.000) SELECT (1) AS "a" FROM "django_session" WHERE "django_session"."session_key" = 'eej1achzvbe1sqgx3ya3r6ykgt6x1qcn' LIMIT 1; args=('eej1achzvbe1sqgx3ya3r6ykgt6x1qcn',)
[2016-11-13 23:44:25] DEBUG [django.db.backends:90] (0.000) BEGIN; args=None
[2016-11-13 23:44:25] DEBUG [django.db.backends:90] (0.002) INSERT INTO "django_session" ("session_key", "session_data", "expire_date") SELECT 'eej1achzvbe1sqgx3ya3r6ykgt6x1qcn', 'Y2U1MDdhOTVhY2Y1M2EzOGYyOTc1YmE0OTQ4NTlmMWJkODNmMmEzMjp7Il9zZXNzaW9uX2V4cGlyeSI6MzB9', '2016-11-14 04:44:55.889145'; args=('eej1achzvbe1sqgx3ya3r6ykgt6x1qcn', 'Y2U1MDdhOTVhY2Y1M2EzOGYyOTc1YmE0OTQ4NTlmMWJkODNmMmEzMjp7Il9zZXNzaW9uX2V4cGlyeSI6MzB9', '2016-11-14 04:44:55.889145')
[2016-11-13 23:44:26] INFO [django.server:131] "GET /api/auths/usermenu/ HTTP/1.1" 200 11
[2016-11-14 00:26:31] DEBUG [django.db.backends:90] (0.002) SELECT "auths_menu"."router_json" FROM "auths_menu" ORDER BY "auths_menu"."pos" ASC; args=()
[2016-11-14 00:26:31] INFO [django.server:131] "GET /api/auths/routers/ HTTP/1.1" 200 2
[2016-11-14 00:26:39] DEBUG [django.db.backends:90] (0.001) SELECT "oauth2_provider_application"."id", "oauth2_provider_application"."client_id", "oauth2_provider_application"."user_id", "oauth2_provider_application"."redirect_uris", "oauth2_provider_application"."client_type", "oauth2_provider_application"."authorization_grant_type", "oauth2_provider_application"."client_secret", "oauth2_provider_application"."name", "oauth2_provider_application"."skip_authorization" FROM "oauth2_provider_application" WHERE "oauth2_provider_application"."client_id" = 'bt3DF5yKjdIawl6nGPiHl0C0V1NkDYSDSU9Eq8U3'; args=('bt3DF5yKjdIawl6nGPiHl0C0V1NkDYSDSU9Eq8U3',)
[2016-11-14 00:26:39] DEBUG [django.db.backends:90] (0.001) SELECT "auths_user"."password", "auths_user"."last_login", "auths_user"."is_superuser", "auths_user"."username", "auths_user"."first_name", "auths_user"."last_name", "auths_user"."email", "auths_user"."is_staff", "auths_user"."is_active", "auths_user"."date_joined", "auths_user"."id", "auths_user"."last_hierarchy_id", "auths_user"."last_module_id", "auths_user"."person_id", "auths_user"."updated_at", "auths_user"."registered_by" FROM "auths_user" WHERE "auths_user"."username" = 'admin'; args=('admin',)
[2016-11-14 00:26:39] DEBUG [django.db.backends:90] (0.000) BEGIN; args=None
[2016-11-14 00:26:39] DEBUG [django.db.backends:90] (0.001) INSERT INTO "oauth2_provider_accesstoken" ("user_id", "token", "application_id", "expires", "scope") VALUES ('9b1f3f3e83664b418357b0197f40ee24', 'I0zk0myYTCiszus2VAsm9QUNtz3xgV', 1, '2016-11-14 15:26:39.150540', 'write read'); args=['9b1f3f3e83664b418357b0197f40ee24', 'I0zk0myYTCiszus2VAsm9QUNtz3xgV', 1, '2016-11-14 15:26:39.150540', 'write read']
[2016-11-14 00:26:39] DEBUG [django.db.backends:90] (0.000) BEGIN; args=None
[2016-11-14 00:26:39] DEBUG [django.db.backends:90] (0.001) INSERT INTO "oauth2_provider_refreshtoken" ("user_id", "token", "application_id", "access_token_id") VALUES ('9b1f3f3e83664b418357b0197f40ee24', 'i9pnnGFFdOINFSsFCd0KqEdgJjnZgY', 1, 3); args=['9b1f3f3e83664b418357b0197f40ee24', 'i9pnnGFFdOINFSsFCd0KqEdgJjnZgY', 1, 3]
[2016-11-14 00:26:39] INFO [django.server:131] "POST /o/token/ HTTP/1.1" 200 169
[2016-11-14 00:26:40] DEBUG [django.db.backends:90] (0.006) SELECT "oauth2_provider_accesstoken"."id", "oauth2_provider_accesstoken"."user_id", "oauth2_provider_accesstoken"."token", "oauth2_provider_accesstoken"."application_id", "oauth2_provider_accesstoken"."expires", "oauth2_provider_accesstoken"."scope", "auths_user"."password", "auths_user"."last_login", "auths_user"."is_superuser", "auths_user"."username", "auths_user"."first_name", "auths_user"."last_name", "auths_user"."email", "auths_user"."is_staff", "auths_user"."is_active", "auths_user"."date_joined", "auths_user"."id", "auths_user"."last_hierarchy_id", "auths_user"."last_module_id", "auths_user"."person_id", "auths_user"."updated_at", "auths_user"."registered_by", "oauth2_provider_application"."id", "oauth2_provider_application"."client_id", "oauth2_provider_application"."user_id", "oauth2_provider_application"."redirect_uris", "oauth2_provider_application"."client_type", "oauth2_provider_application"."authorization_grant_type", "oauth2_provider_application"."client_secret", "oauth2_provider_application"."name", "oauth2_provider_application"."skip_authorization" FROM "oauth2_provider_accesstoken" LEFT OUTER JOIN "auths_user" ON ("oauth2_provider_accesstoken"."user_id" = "auths_user"."id") INNER JOIN "oauth2_provider_application" ON ("oauth2_provider_accesstoken"."application_id" = "oauth2_provider_application"."id") WHERE "oauth2_provider_accesstoken"."token" = 'I0zk0myYTCiszus2VAsm9QUNtz3xgV'; args=('I0zk0myYTCiszus2VAsm9QUNtz3xgV',)
[2016-11-14 00:26:40] DEBUG [django.db.backends:90] (0.000) SELECT "oauth2_provider_accesstoken"."id", "oauth2_provider_accesstoken"."user_id", "oauth2_provider_accesstoken"."token", "oauth2_provider_accesstoken"."application_id", "oauth2_provider_accesstoken"."expires", "oauth2_provider_accesstoken"."scope", "auths_user"."password", "auths_user"."last_login", "auths_user"."is_superuser", "auths_user"."username", "auths_user"."first_name", "auths_user"."last_name", "auths_user"."email", "auths_user"."is_staff", "auths_user"."is_active", "auths_user"."date_joined", "auths_user"."id", "auths_user"."last_hierarchy_id", "auths_user"."last_module_id", "auths_user"."person_id", "auths_user"."updated_at", "auths_user"."registered_by", "oauth2_provider_application"."id", "oauth2_provider_application"."client_id", "oauth2_provider_application"."user_id", "oauth2_provider_application"."redirect_uris", "oauth2_provider_application"."client_type", "oauth2_provider_application"."authorization_grant_type", "oauth2_provider_application"."client_secret", "oauth2_provider_application"."name", "oauth2_provider_application"."skip_authorization" FROM "oauth2_provider_accesstoken" LEFT OUTER JOIN "auths_user" ON ("oauth2_provider_accesstoken"."user_id" = "auths_user"."id") INNER JOIN "oauth2_provider_application" ON ("oauth2_provider_accesstoken"."application_id" = "oauth2_provider_application"."id") WHERE "oauth2_provider_accesstoken"."token" = 'I0zk0myYTCiszus2VAsm9QUNtz3xgV'; args=('I0zk0myYTCiszus2VAsm9QUNtz3xgV',)
[2016-11-14 00:26:40] DEBUG [django.db.backends:90] (0.006) SELECT "oauth2_provider_accesstoken"."id", "oauth2_provider_accesstoken"."user_id", "oauth2_provider_accesstoken"."token", "oauth2_provider_accesstoken"."application_id", "oauth2_provider_accesstoken"."expires", "oauth2_provider_accesstoken"."scope", "auths_user"."password", "auths_user"."last_login", "auths_user"."is_superuser", "auths_user"."username", "auths_user"."first_name", "auths_user"."last_name", "auths_user"."email", "auths_user"."is_staff", "auths_user"."is_active", "auths_user"."date_joined", "auths_user"."id", "auths_user"."last_hierarchy_id", "auths_user"."last_module_id", "auths_user"."person_id", "auths_user"."updated_at", "auths_user"."registered_by", "oauth2_provider_application"."id", "oauth2_provider_application"."client_id", "oauth2_provider_application"."user_id", "oauth2_provider_application"."redirect_uris", "oauth2_provider_application"."client_type", "oauth2_provider_application"."authorization_grant_type", "oauth2_provider_application"."client_secret", "oauth2_provider_application"."name", "oauth2_provider_application"."skip_authorization" FROM "oauth2_provider_accesstoken" LEFT OUTER JOIN "auths_user" ON ("oauth2_provider_accesstoken"."user_id" = "auths_user"."id") INNER JOIN "oauth2_provider_application" ON ("oauth2_provider_accesstoken"."application_id" = "oauth2_provider_application"."id") WHERE "oauth2_provider_accesstoken"."token" = 'I0zk0myYTCiszus2VAsm9QUNtz3xgV'; args=('I0zk0myYTCiszus2VAsm9QUNtz3xgV',)
[2016-11-14 00:26:40] DEBUG [django.db.backends:90] (0.001) SELECT "oauth2_provider_accesstoken"."id", "oauth2_provider_accesstoken"."user_id", "oauth2_provider_accesstoken"."token", "oauth2_provider_accesstoken"."application_id", "oauth2_provider_accesstoken"."expires", "oauth2_provider_accesstoken"."scope", "auths_user"."password", "auths_user"."last_login", "auths_user"."is_superuser", "auths_user"."username", "auths_user"."first_name", "auths_user"."last_name", "auths_user"."email", "auths_user"."is_staff", "auths_user"."is_active", "auths_user"."date_joined", "auths_user"."id", "auths_user"."last_hierarchy_id", "auths_user"."last_module_id", "auths_user"."person_id", "auths_user"."updated_at", "auths_user"."registered_by", "oauth2_provider_application"."id", "oauth2_provider_application"."client_id", "oauth2_provider_application"."user_id", "oauth2_provider_application"."redirect_uris", "oauth2_provider_application"."client_type", "oauth2_provider_application"."authorization_grant_type", "oauth2_provider_application"."client_secret", "oauth2_provider_application"."name", "oauth2_provider_application"."skip_authorization" FROM "oauth2_provider_accesstoken" LEFT OUTER JOIN "auths_user" ON ("oauth2_provider_accesstoken"."user_id" = "auths_user"."id") INNER JOIN "oauth2_provider_application" ON ("oauth2_provider_accesstoken"."application_id" = "oauth2_provider_application"."id") WHERE "oauth2_provider_accesstoken"."token" = 'I0zk0myYTCiszus2VAsm9QUNtz3xgV'; args=('I0zk0myYTCiszus2VAsm9QUNtz3xgV',)
[2016-11-14 00:26:40] DEBUG [django.db.backends:90] (0.002) SELECT "auth_group"."id", "auth_group"."name" FROM "auth_group" INNER JOIN "auths_user_groups" ON ("auth_group"."id" = "auths_user_groups"."group_id") WHERE "auths_user_groups"."user_id" = '9b1f3f3e83664b418357b0197f40ee24'; args=('9b1f3f3e83664b418357b0197f40ee24',)
[2016-11-14 00:26:40] DEBUG [django.db.backends:90] (0.001) SELECT "auths_menu"."id" FROM "auths_menu" WHERE ("auths_menu"."id" IS NOT NULL AND "auths_menu"."module" = 'BACKEND' AND "auths_menu"."is_active" = 1) ORDER BY "auths_menu"."pos" ASC; args=('BACKEND', True)
[2016-11-14 00:26:40] DEBUG [django.db.backends:90] (0.002) SELECT "auth_permission"."id", "auth_permission"."name", "auth_permission"."content_type_id", "auth_permission"."codename" FROM "auth_permission" INNER JOIN "auths_user_user_permissions" ON ("auth_permission"."id" = "auths_user_user_permissions"."permission_id") INNER JOIN "django_content_type" ON ("auth_permission"."content_type_id" = "django_content_type"."id") WHERE "auths_user_user_permissions"."user_id" = '9b1f3f3e83664b418357b0197f40ee24' ORDER BY "django_content_type"."app_label" ASC, "django_content_type"."model" ASC, "auth_permission"."codename" ASC; args=('9b1f3f3e83664b418357b0197f40ee24',)
[2016-11-14 00:26:40] DEBUG [django.db.backends:90] (0.003) SELECT (1) AS "a" FROM "django_session" WHERE "django_session"."session_key" = '0b33hrxn69gjcd139vb9rroy3oc9qby0' LIMIT 1; args=('0b33hrxn69gjcd139vb9rroy3oc9qby0',)
[2016-11-14 00:26:40] INFO [django.server:131] "GET /api/auths/localuserinfo/ HTTP/1.1" 200 405
[2016-11-14 00:26:40] DEBUG [django.db.backends:90] (0.001) BEGIN; args=None
[2016-11-14 00:26:41] DEBUG [django.db.backends:90] (0.066) INSERT INTO "django_session" ("session_key", "session_data", "expire_date") SELECT '0b33hrxn69gjcd139vb9rroy3oc9qby0', 'Y2U1MDdhOTVhY2Y1M2EzOGYyOTc1YmE0OTQ4NTlmMWJkODNmMmEzMjp7Il9zZXNzaW9uX2V4cGlyeSI6MzB9', '2016-11-14 05:27:10.932614'; args=('0b33hrxn69gjcd139vb9rroy3oc9qby0', 'Y2U1MDdhOTVhY2Y1M2EzOGYyOTc1YmE0OTQ4NTlmMWJkODNmMmEzMjp7Il9zZXNzaW9uX2V4cGlyeSI6MzB9', '2016-11-14 05:27:10.932614')
[2016-11-14 00:26:41] INFO [django.server:131] "GET /api/auths/usermenu/ HTTP/1.1" 200 11
